Workbook

Sheet تحليل الاداء
A1: م | B1: اسم السائق | C1: مواعيد الحضور | D1: 46133 | E1: 46133 | F1: عدد الرحلات | G1: عدد الفروع | H1: مواعيد الحضور | I1: 46134 | J1: 46134 | K1: عدد الرحلات | L1: عدد الفروع | M1: مواعيد الحضور | N1: 46135 | O1: 46135 | P1: عدد الرحلات | Q1: عدد الفروع | R1: مواعيد الحضور | S1: 46136 | T1: 46136 | U1: عدد الرحلات | V1: عدد الفروع | W1: مواعيد الحضور | X1: 46137 | Y1: 46137 | Z1: عدد الرحلات | AA1: عدد الفروع | AB1: مواعيد الحضور | AC1: 46138 | AD1: 46138 | AE1: عدد الرحلات | AF1: عدد الفروع | AG1: مواعيد الحضور | AH1: 46139 | AI1: 46139 | AJ1: عدد الرحلات | AK1: عدد الفروع | AM1: عدد الرحلات المجمع اسبوعى | AN1: عدد الفروع المجمع اسبوعى
A2: 2 | B2: عمرو محمد حسنى | C2: 0.25347222 | D2: التجمع1-التجمع5 | E2: سرياقوس | F2: 2 | G2: 3 | H2: 0.25 | I2: الشروق1-الشروق3 | J2: سرياقوس | K2: 2 | L2: 3 | M2: 0.25347222 | N2: شبرا-الدوران | O2: مسطرد | P2: 2 | Q2: 3 | R2: 0.25694444 | S2: العاشر | T2: الدقى - عرابى | U2: 2 | V2: 3 | W2: راحة | X2: راحة | Z2: 0 | AA2: 0 | AB2: 0.25 | AC2: الجسر | AD2: الجسر-النزهه | AE2: 2 | AF2: 3 | AG2: 0.25 | AH2: جاردنيا-مكرم | AI2: فيصل-الطوابق | AJ2: 2 | AK2: 4 | AM2: =AJ2+AE2+Z2+U2+P2+K2+F2 -> 12 | AN2: =AK2+AF2+AA2+V2+Q2+L2+G2 -> 19
A3: 3 | B3: محمد حسن حسان | C3: 0.23958333 | D3: جاردنيا-مكرم | E3: الجسر-النزهه | F3: 2 | G3: 4 | H3: 0.23958333 | I3: شبرا-الدوران | J3: بهتيم | K3: 2 | L3: 3 | M3: 0.25 | N3: الجسر | O3: السواح | P3: 2 | Q3: 2 | R3: 0.25 | S3: المرغنى - عباس | T3: فيصل | U3: 2 | V3: 3 | W3: راحة | X3: راحة | Z3: 0 | AA3: 0 | AB3: 0.24652778 | AC3: المعادى-العاشر | AD3: اكتوبر | AE3: 2 | AF3: 3 | AG3: 0.25 | AH3: فيصل | AI3: شبرا-الدوران بهتيم | AJ3: 3 | AK3: 4 | AM3: =AJ3+AE3+Z3+U3+P3+K3+F3 -> 13 | AN3: =AK3+AF3+AA3+V3+Q3+L3+G3 -> 19
A4: 7 | B4: احمد حسن | C4: سنوى | D4: سنوى | F4: 0 | G4: 0 | H4: سنوى | I4: سنوى | K4: 0 | L4: 0 | M4: سنوى | N4: سنوى | P4: 0 | Q4: 0 | R4: سنوى | S4: سنوى | U4: 0 | V4: 0 | W4: راحة | X4: راحة | Z4: 0 | AA4: 0 | AB4: 0.25347222 | AC4: الطوابق | AD4: ورشه كاوتش | AE4: 2 | AF4: 2 | AG4: 0.25694444 | AH4: عبور2 | AI4: سرياقوس | AJ4: 2 | AK4: 2 | AM4: =AJ4+AE4+Z4+U4+P4+K4+F4 -> 4 | AN4: =AK4+AF4+AA4+V4+Q4+L4+G4 -> 4
B5: عمرو عبد الرحمن | C5: غياب | D5: غياب | F5: 0 | G5: 0 | H5: 0.27083333 | I5: الشريف | J5: العاشر من رمضان | K5: 2 | L5: 2 | M5: 0.28472222 | N5: مأموريه(hr) | P5: 1 | Q5: 1 | R5: 0.27083333 | S5: الشريف | T5: ايس كريم ( 7 فروع ) | U5: 2 | V5: 8 | W5: راحة | X5: راحة | Z5: 0 | AA5: 0 | AB5: 0.27430556 | AC5: المطريه | AD5: الوسط-الشريف منفذ المصنع | AE5: 3 | AF5: 4 | AG5: غياب | AH5: غياب بدون اذن | AJ5: 0 | AK5: 0 | AM5: =AJ5+AE5+Z5+U5+P5+K5+F5 -> 8 | AN5: =AK5+AF5+AA5+V5+Q5+L5+G5 -> 15
B6: كريم محمود | C6: 0.27083333 | D6: مسطرد | E6: منفذ المصنع بهتيم | F6: 3 | G6: 3 | H6: 0.27083333 | I6: مسطرد | J6: عبور2 | K6: 2 | L6: 2 | M6: 0.27430556 | N6: الكوربه | O6: اكتوبر | P6: 2 | Q6: 2 | R6: 0.27777778 | S6: المطرية | T6: الشيراتون - جاردينيا | U6: 2 | V6: 3 | W6: راحة | X6: راحة | Z6: 0 | AA6: 0 | AB6: 0.27083333 | AC6: المرغنى | AD6: ايس كريم(5فروع) | AE6: 2 | AF6: 6 | AG6: 0.27430556 | AH6: الكوربه | AI6: ايس كريم(5فروع) | AJ6: 2 | AK6: 6 | AM6: =AJ6+AE6+Z6+U6+P6+K6+F6 -> 13 | AN6: =AK6+AF6+AA6+V6+Q6+L6+G6 -> 22
A7: 8 | B7: على حمدى | C7: سنوى | D7: سنوى | F7: 0 | G7: 0 | H7: سنوى | I7: سنوى | K7: 0 | L7: 0 | M7: سنوى | N7: سنوى | P7: 0 | Q7: 0 | R7: سنوى | S7: سنوى | U7: 0 | V7: 0 | W7: سنوى | X7: سنوى | Z7: 0 | AA7: 0 | AB7: راحة | AC7: راحة | AE7: 0 | AF7: 0 | AG7: 0.27083333 | AH7: المعادى2 | AI7: العاشر من رمضان | AJ7: 2 | AK7: 2 | AM7: =AJ7+AE7+Z7+U7+P7+K7+F7 -> 2 | AN7: =AK7+AF7+AA7+V7+Q7+L7+G7 -> 2
A8: 10 | B8: رضا معروف | C8: 0.26388889 | D8: الطوابق | E8: عبور2 | F8: 2 | G8: 2 | H8: 0.25 | I8: منتزه-وايلى | J8: الطوابق | K8: 2 | L8: 2 | M8: 0.26388889 | N8: عرابى | O8: العاشر سرياقوس | P8: 3 | Q8: 3 | R8: 0.26388889 | S8: فيصل | T8: المعادى 1 - المعادى 2 | U8: 2 | V8: 3 | W8: 0.26388889 | X8: اكتوبر | Y8: الشروق 1 - الشروق 2 | Z8: 2 | AA8: 3 | AB8: راحة | AC8: راحة | AE8: 0 | AF8: 0 | AG8: سنوى | AH8: سنوى | AJ8: 0 | AK8: 0 | AM8: =AJ8+AE8+Z8+U8+P8+K8+F8 -> 11 | AN8: =AK8+AF8+AA8+V8+Q8+L8+G8 -> 13
A9: 11 | B9: وائل على | C9: 0.25 | D9: اسكندريه | F9: 1 | G9: 1 | H9: 0.25 | I9: التجمع1-التجمع5 | J9: مسطرد | K9: 2 | L9: 3 | M9: 0.25 | N9: الشروق1-الشروق3 | O9: النزهه | P9: 2 | Q9: 3 | R9: 0.22916667 | S9: شبرا - الدوران | T9: مكرم | U9: 2 | V9: 3 | W9: 0.25 | X9: الوايلى - المنتزه | Y9: الجسر-النزهه | Z9: 2 | AA9: 4 | AB9: راحة | AC9: راحة | AE9: 0 | AF9: 0 | AG9: 0.25347222 | AH9: التجمع1-التجمع5 | AI9: السواح-المطريه | AJ9: 2 | AK9: 4 | AM9: =AJ9+AE9+Z9+U9+P9+K9+F9 -> 11 | AN9: =AK9+AF9+AA9+V9+Q9+L9+G9 -> 18
A10: 41 | B10: اسامه مصطفى | C10: 0.24305556 | D10: فيصل | E10: الدقى-عرابى | F10: 2 | G10: 3 | H10: 0.24305556 | I10: فيصل | J10: شبرا-الدوران | K10: 2 | L10: 3 | M10: 0.25 | N10: اكتوبر | O10: عبور2 | P10: 2 | Q10: 2 | R10: 0.24652778 | S10: النزهة | T10: الطوابق | U10: 2 | V10: 2 | W10: 0.24305556 | X10: الدقى | Y10: شبرا - الدوران | Z10: 2 | AA10: 3 | AB10: راحة | AC10: راحة | AE10: 0 | AF10: 0 | AG10: 0.24305556 | AH10: النزهه | AI10: عباسيه-وايلى | AJ10: 2 | AK10: 3 | AM10: =AJ10+AE10+Z10+U10+P10+K10+F10 -> 12 | AN10: =AK10+AF10+AA10+V10+Q10+L10+G10 -> 16
B11: على عادل عبد الفتاح | C11: 0.25 | D11: عباس-المرغنى | E11: العثيم كارفور | F11: 2 | G11: 3 | H11: سنوى | I11: سنوى | K11: 0 | L11: 0 | M11: 0.23263889 | N11: العاشر | O11: عطل سياره مأموريه | P11: 2 | Q11: 2 | R11: 0.25 | S11: الجسر | T11: النزهة | U11: 2 | V11: 2 | W11: 0.24652778 | X11: مكرم - جاردينيا | Y11: العاشر-مكرم | Z11: 2 | AA11: 4 | AB11: راحة | AC11: راحة | AE11: 0 | AF11: 0 | AG11: سنوى | AH11: سنوى | AJ11: 0 | AK11: 0 | AM11: =AJ11+AE11+Z11+U11+P11+K11+F11 -> 8 | AN11: =AK11+AF11+AA11+V11+Q11+L11+G11 -> 11
A12: 13 | B12: رجب محمد مصطفى | C12: 0.24305556 | D12: الشروق1-الشروق3 | F12: 1 | G12: 2 | H12: 0.23958333 | I12: المعادى-العاشر | J12: السواح-المطريه | K12: 2 | L12: 4 | M12: 0.24305556 | N12: عباس-المرغنى | O12: الجسر | P12: 2 | Q12: 3 | R12: 0.24652778 | S12: التجمع 1 | T12: المطرية | U12: 2 | V12: 2 | W12: 0.24305556 | X12: فيصل | Y12: بهتيم مسطرد | Z12: 2 | AA12: 2 | AB12: 0.24305556 | AC12: التجمع 1 - التجمع 5 | AD12: السواح-المطريه | AE12: 2 | AF12: 4 | AG12: راحة | AH12: راحة | AJ12: 0 | AK12: 0 | AM12: =AJ12+AE12+Z12+U12+P12+K12+F12 -> 11 | AN12: =AK12+AF12+AA12+V12+Q12+L12+G12 -> 17
A13: 14 | B13: محمد صلاح | C13: 0.24305556 | D13: العاشر | E13: المعادى1-المعادى2 | F13: 2 | G13: 3 | H13: 0.23958333 | I13: العبور | J13: التجمع1-التجمع5 | K13: 2 | L13: 3 | M13: 0.25 | N13: الدقى | O13: المعادى1-المعادى2 | P13: 2 | Q13: 3 | R13: 0.24305556 | S13: العبور 2 | T13: العاشر | U13: 2 | V13: 2 | W13: 0.25 | X13: المعادى 1 | Y13: الطوابق | Z13: 2 | AA13: 2 | AB13: سنوى | AC13: سنوى | AE13: 0 | AF13: 0 | AG13: راحة | AH13: راحة | AJ13: 0 | AK13: 0 | AM13: =AJ13+AE13+Z13+U13+P13+K13+F13 -> 10 | AN13: =AK13+AF13+AA13+V13+Q13+L13+G13 -> 13
A14: 17 | B14: علاء مجدى | C14: 0.23958333 | D14: عرابى-الدقى | E14: فيصل-الطوابق | F14: 2 | G14: 4 | H14: 0.23958333 | I14: جاردنيا-مكرم | J14: الجسر | K14: 2 | L14: 3 | M14: 0.23958333 | N14: الوايلى - المنتزه | O14: فيصل-الطوابق | P14: 2 | Q14: 4 | R14: 0.25 | S14: الشروق 2 - الشروق 3 | T14: مسطرد | U14: 2 | V14: 3 | W14: 0.25 | X14: الجسر | Y14: السواح-المطريه | Z14: 2 | AA14: 3 | AB14: 0.24305556 | AC14: الشروق 1 - الشروق 3 | AD14: سرياقوس | AE14: 2 | AF14: 3 | AG14: راحة | AH14: راحة | AJ14: 0 | AK14: 0 | AM14: =AJ14+AE14+Z14+U14+P14+K14+F14 -> 12 | AN14: =AK14+AF14+AA14+V14+Q14+L14+G14 -> 20
A15: 18 | B15: مصطفى احمد | C15: 0.25 | D15: الجسر | E15: الكيلو4.5 | F15: 2 | G15: 2 | H15: 0.25 | I15: مرور(هيئه السلامه الغذاء) | K15: 1 | L15: 1 | M15: 0.25 | N15: جاردنيا-مكرم | O15: بهتيم | P15: 2 | Q15: 3 | R15: 0.25347222 | S15: الوايلى - المنتزه | T15: الجسر | U15: 2 | V15: 3 | W15: 0.25 | X15: شبرا - الدوران | Y15: العاشر من رمضان الكيلو4.5 | Z15: 3 | AA15: 4 | AB15: 0.25347222 | AC15: الوايلى - المنتزه | AD15: الترعه | AE15: 2 | AF15: 3 | AG15: راحة | AH15: راحة | AJ15: 0 | AK15: 0 | AM15: =AJ15+AE15+Z15+U15+P15+K15+F15 -> 12 | AN15: =AK15+AF15+AA15+V15+Q15+L15+G15 -> 16
B16: الشناوى سرور | C16: 0.25347222 | D16: المعادى2 | E16: الشروق1-الشروق3 | F16: 2 | G16: 3 | H16: 0.25 | I16: الوسط | J16: جاردنبا-الشيراتون | K16: 2 | L16: 3 | M16: 0.25347222 | N16: العاشر من رمضان | O16: الكوربه-منتزه | P16: 2 | Q16: 3 | R16: 0.25694444 | S16: المعادى 2 | T16: منفذ المصنع | U16: 2 | V16: 2 | W16: 0.25 | X16: الشريف | Y16: العاشر من رمضان | Z16: 2 | AA16: 2 | AB16: 0.25 | AC16: العاشر من رمضان | AD16: سرياقوس | AE16: 2 | AF16: 2 | AG16: راحة | AH16: راحة | AJ16: 0 | AK16: 0 | AM16: =AJ16+AE16+Z16+U16+P16+K16+F16 -> 12 | AN16: =AK16+AF16+AA16+V16+Q16+L16+G16 -> 15
A17: 19 | B17: احمد عواد | C17: راحة | D17: راحة | F17: 0 | G17: 0 | H17: 0.22222222 | I17: الشيراتون | J17: الشروق1-الشروق3 | K17: 2 | L17: 3 | M17: 0.22222222 | N17: المطريه | O17: الوسط-الشريف بهتيم | P17: 3 | Q17: 4 | R17: 0.23958333 | S17: الوسط | T17: مسطرد / العاشر من رمضان | U17: 3 | V17: 3 | W17: 0.23611111 | X17: المطرية | Y17: اكتوبر | Z17: 2 | AA17: 2 | AB17: 0.25 | AC17: عباسيه | AD17: العاشر من رمضان | AE17: 2 | AF17: 2 | AG17: 0.23958333 | AH17: الشريف | AI17: الكوربه-منتزه منفذ المصنع | AJ17: 3 | AK17: 4 | AM17: =AJ17+AE17+Z17+U17+P17+K17+F17 -> 15 | AN17: =AK17+AF17+AA17+V17+Q17+L17+G17 -> 18
A18: 20 | B18: محمد مراد | C18: راحة | D18: راحة | F18: 0 | G18: 0 | H18: 0.26388889 | I18: المعادى | J18: اكتوبر | K18: 2 | L18: 2 | M18: 0.25347222 | N18: المعادى2 | O18: مكرم | P18: 2 | Q18: 2 | R18: 0.26041667 | S18: التجمع 5 | T18: المنتزه - الكوربة | U18: 2 | V18: 3 | W18: 0.26041667 | X18: المرغنى | Y18: المنتزه - الكوربة | Z18: 2 | AA18: 3 | AB18: 0.28472222 | AC18: المعادى1 | AD18: الشروق 1 - الشروق 3 | AE18: 2 | AF18: 3 | AG18: 0.24305556 | AH18: العاشر من رمضان | AI18: المرغنى | AJ18: 2 | AK18: 2 | AM18: =AJ18+AE18+Z18+U18+P18+K18+F18 -> 12 | AN18: =AK18+AF18+AA18+V18+Q18+L18+G18 -> 15
A19: 22 | B19: خالد عبده | C19: راحة | D19: راحة | F19: 0 | G19: 0 | H19: 0.26388889 | I19: الدوران | K19: 1 | L19: 1 | M19: 0.26041667 | N19: الدوران | O19: المقطم | P19: 2 | Q19: 2 | R19: 0.25347222 | S19: العباسية | T19: الوسط / بهتيم | U19: 3 | V19: 3 | W19: 0.26736111 | X19: الشيراتون | Y19: منفذ المصنع | Z19: 2 | AA19: 2 | AB19: 0.25347222 | AC19: الشيراتون | AD19: مأموريه | AE19: 2 | AF19: 2 | AG19: غياب | AH19: غياب بدون اذن | AJ19: 0 | AK19: 0 | AM19: =AJ19+AE19+Z19+U19+P19+K19+F19 -> 10 | AN19: =AK19+AF19+AA19+V19+Q19+L19+G19 -> 10
A20: 23 | B20: سيد محمد العسال | C20: راحة | D20: راحة | F20: 0 | G20: 0 | H20: 0.25 | I20: عباس-المرغنى | J20: المعادى1-المعادى2 | K20: 2 | L20: 4 | M20: 0.26041667 | N20: التجمع1-التجمع5 | P20: 1 | Q20: 2 | R20: 0.26041667 | S20: مكرم - جاردينيا | T20: شبرا - الدوران | U20: 2 | V20: 4 | W20: 0.26388889 | X20: الشروق 2 - الشروق 3 | Y20: توكيل | Z20: 2 | AA20: 3 | AB20: 0.26041667 | AC20: الدوران | AD20: توكيل | AE20: 2 | AF20: 2 | AG20: 0.26736111 | AH20: الشيراتون | AI20: الجسر-النزهه | AJ20: 2 | AK20: 3 | AM20: =AJ20+AE20+Z20+U20+P20+K20+F20 -> 11 | AN20: =AK20+AF20+AA20+V20+Q20+L20+G20 -> 18
B21: صبري امام | C21: راحة | D21: راحة | F21: 0 | G21: 0 | H21: 0.25 | I21: العاشر من رمضان | J21: مسطرد | K21: 2 | L21: 2 | M21: 0.26388889 | N21: الوسط | O21: الشروق1-الشروق3 | P21: 2 | Q21: 3 | R21: 0.26041667 | S21: العاشر من رمضان | T21: بهتيم | U21: 2 | V21: 2 | W21: 0.26041667 | X21: المعادى 2 | Z21: 1 | AA21: 1 | AB21: 0.26736111 | AC21: الشريف | AD21: الشيراتون - جاردنيا الترعه | AE21: 3 | AF21: 4 | AG21: 0.27083333 | AH21: المرغنى | AI21: اكتوبر | AJ21: 2 | AK21: 2 | AM21: =AJ21+AE21+Z21+U21+P21+K21+F21 -> 12 | AN21: =AK21+AF21+AA21+V21+Q21+L21+G21 -> 14
A22: 24 | B22: سامح عبد السميع | C22: راحة | D22: راحة | F22: 0 | G22: 0 | H22: 0.25 | I22: مدينه بدر(امن الفروع) | K22: 1 | L22: 1 | M22: 0.25694444 | N22: المعادى | O22: العباسية - الوايلى | P22: 2 | Q22: 3 | R22: 0.26041667 | S22: المعادى 1 | T22: المرغنى - عباس | U22: 2 | V22: 3 | W22: 0.25 | X22: الكوربة | Y22: المرج(مصنع فكره) | Z22: 2 | AA22: 2 | AB22: 0.25694444 | AC22: مكرم - جاردينيا | AD22: مسطرد | AE22: 2 | AF22: 3 | AG22: 0.25347222 | AH22: عباس | AI22: عباس-المرغنى سرياقوس | AJ22: 3 | AK22: 4 | AM22: =AJ22+AE22+Z22+U22+P22+K22+F22 -> 12 | AN22: =AK22+AF22+AA22+V22+Q22+L22+G22 -> 16
A23: 25 | B23: جمعه السيد | C23: 0.23958333 | D23: الوسط | E23: الوسط-الشريف | F23: 2 | G23: 3 | H23: راحة | I23: راحة | K23: 0 | L23: 0 | M23: 0.24305556 | N23: العباسية | O23: العاشر من رمضان | P23: 2 | Q23: 2 | R23: 0.24652778 | S23: الكوربة | T23: اكتوبر | U23: 2 | V23: 2 | W23: 0.25 | X23: العاشر من رمضان | Z23: 1 | AA23: 1 | AB23: 0.23611111 | AC23: الوسط | AD23: مصر للطيران | AE23: 2 | AF23: 2 | AG23: 0.23958333 | AH23: الشيراتون | AI23: العبور2 | AJ23: 2 | AK23: 2 | AM23: =AJ23+AE23+Z23+U23+P23+K23+F23 -> 11 | AN23: =AK23+AF23+AA23+V23+Q23+L23+G23 -> 12
A24: 26 | B24: خالد صبرى | C24: 0.26388889 | D24: الدوران | E24: مدينه بدر | F24: 2 | G24: 2 | H24: راحة | I24: راحة | K24: 0 | L24: 0 | M24: سنوى | N24: سنوى | P24: 0 | Q24: 0 | R24: سنوى | S24: سنوى | U24: 0 | V24: 0 | W24: سنوى | X24: سنوى | Z24: 0 | AA24: 0 | AB24: سنوى | AC24: سنوى | AE24: 0 | AF24: 0 | AG24: سنوى | AH24: سنوى | AJ24: 0 | AK24: 0 | AM24: =AJ24+AE24+Z24+U24+P24+K24+F24 -> 2 | AN24: =AK24+AF24+AA24+V24+Q24+L24+G24 -> 2
A25: 27 | B25: محمود أبو طالب | C25: 0.25347222 | D25: العبور | E25: السواح-المطريه | F25: 2 | G25: 3 | H25: راحة | I25: راحة | K25: 0 | L25: 0 | M25: سنوى | N25: سنوى | P25: 0 | Q25: 0 | R25: سنوى | S25: سنوى | U25: 0 | V25: 0 | W25: سنوى | X25: سنوى | Z25: 0 | AA25: 0 | AB25: سنوى | AC25: سنوى | AE25: 0 | AF25: 0 | AG25: سنوى | AH25: سنوى | AJ25: 0 | AK25: 0 | AM25: =AJ25+AE25+Z25+U25+P25+K25+F25 -> 2 | AN25: =AK25+AF25+AA25+V25+Q25+L25+G25 -> 3
A26: 33 | B26: عبد الرحمن محمد | C26: 0.26041667 | D26: الشريف | E26: الكوربه-منتزه | F26: 2 | G26: 3 | H26: راحة | I26: راحة | K26: 0 | L26: 0 | M26: 0.26388889 | N26: الشيراتون | O26: الشيراتون - جاردينيا | P26: 2 | Q26: 3 | R26: 0.27777778 | S26: الشيراتون | T26: الشريف | U26: 2 | V26: 2 | W26: 0.26736111 | X26: عرابى | Y26: الوايلى - العباسية | Z26: 2 | AA26: 3 | AB26: 0.26041667 | AC26: عرابى | AD26: بهتيم | AE26: 2 | AF26: 2 | AG26: 0.26388889 | AH26: المعادى | AI26: الشروق1-الشروق3 | AJ26: 2 | AK26: 3 | AM26: =AJ26+AE26+Z26+U26+P26+K26+F26 -> 12 | AN26: =AK26+AF26+AA26+V26+Q26+L26+G26 -> 16
A27: 35 | B27: خالد محمد ابراهيم | C27: 0.25694444 | D27: المعادى2 | E27: عباسيه-وايلى | F27: 2 | G27: 3 | H27: راحة | I27: راحة | K27: 0 | L27: 0 | M27: 0.25694444 | N27: العبور | O27: عباس-المرغنى | P27: 2 | Q27: 3 | R27: عارضة | S27: حالة وفاة | U27: 0 | V27: 0 | W27: سنوى | X27: سنوى | Z27: 0 | AA27: 0 | AB27: 0.25347222 | AC27: العبور | AD27: التجمع 1 - التجمع 5 | AE27: 2 | AF27: 3 | AG27: 0.25694444 | AH27: الدقى | AI27: المعادى1-المعادى2 | AJ27: 2 | AK27: 3 | AM27: =AJ27+AE27+Z27+U27+P27+K27+F27 -> 8 | AN27: =AK27+AF27+AA27+V27+Q27+L27+G27 -> 12
B28: رامى حسن محمد | C28: 0.22916667 | D28: اكتوبر | E28: النزهه | F28: 2 | G28: 2 | H28: 0.22569444 | I28: النزهه | J28: عباس-المرغنى | K28: 2 | L28: 3 | M28: راحة | N28: راحة | P28: 0 | Q28: 0 | R28: 0.26041667 | S28: عرابى | T28: الشروق 1 - الشروق 2 | U28: 2 | V28: 3 | W28: 0.24305556 | X28: العبور | Y28: العبور | Z28: 2 | AA28: 2 | AB28: 0.24305556 | AC28: عباس | AD28: الدقى - عرابى | AE28: 2 | AF28: 3 | AG28: 0.23958333 | AH28: عرابى | AI28: التجمع1-التجمع5 | AJ28: 2 | AK28: 3 | AM28: =AJ28+AE28+Z28+U28+P28+K28+F28 -> 12 | AN28: =AK28+AF28+AA28+V28+Q28+L28+G28 -> 16
B29: احمد سعيد سالم | C29: 0.25347222 | D29: العاشر من رمضان | E29: عبور2 | F29: 2 | G29: 2 | H29: 0.25 | I29: اسماعليه | K29: 1 | L29: 1 | M29: راحة | N29: راحة | P29: 0 | Q29: 0 | R29: 0.27083333 | S29: السواح | T29: مصنع ابو محرم السواح | U29: 3 | V29: 3 | W29: سنوى | X29: عارضة | Z29: 0 | AA29: 0 | AB29: غياب | AC29: غياب بدون اذن | AE29: 0 | AF29: 0 | AG29: 0.25 | AH29: العاشر | AI29: الدقى-عرابى | AJ29: 2 | AK29: 3 | AM29: =AJ29+AE29+Z29+U29+P29+K29+F29 -> 8 | AN29: =AK29+AF29+AA29+V29+Q29+L29+G29 -> 9
B30: رامى عادل | C30: 0.25347222 | D30: منتزه-وايلى | E30: شبرا-الدوران | F30: 2 | G30: 4 | H30: سنوى | I30: سنوى | K30: 0 | L30: 0 | M30: راحة | N30: راحة | P30: 0 | Q30: 0 | R30: 0.25694444 | S30: الدقى | T30: التجمع 1 - التجمع 5 | U30: 2 | V30: 3 | W30: 0.25 | X30: التجمع 1 - التجمع 5 | Y30: فيصل | Z30: 2 | AA30: 3 | AB30: 0.26041667 | AC30: الدقى | AD30: شبرا - الدوران بهتيم | AE30: 3 | AF30: 4 | AG30: 0.25694444 | AH30: الشروق1-الشروق3 | AI30: سرياقوس | AJ30: 2 | AK30: 3 | AM30: =AJ30+AE30+Z30+U30+P30+K30+F30 -> 11 | AN30: =AK30+AF30+AA30+V30+Q30+L30+G30 -> 17
B31: محمد عباس | C31: 0.26041667 | D31: الكوربه | E31: اكتوبر | F31: 2 | G31: 2 | H31: 0.26041667 | I31: عباسيه | J31: عرابى-الدقى | K31: 2 | L31: 3 | M31: راحة | N31: راحة | P31: 0 | Q31: 0 | R31: 0.28472222 | S31: الدوران | T31: الكيلو 4.5 | U31: 2 | V31: 2 | W31: 0.27083333 | X31: العباسية | Y31: ابو محرم | Z31: 2 | AA31: 2 | AB31: 0.26388889 | AC31: مسطرد | AD31: الكوربه-المنتزه | AE31: 2 | AF31: 3 | AG31: 0.27083333 | AH31: عباسيه | AI31: ايس كريم(5فروع) | AJ31: 2 | AK31: 6 | AM31: =AJ31+AE31+Z31+U31+P31+K31+F31 -> 12 | AN31: =AK31+AF31+AA31+V31+Q31+L31+G31 -> 18
B32: عمرو المهدى | C32: 0.23958333 | D32: النزهه | E32: عباس-المرغنى بهتيم | F32: 3 | G32: 4 | H32: 0.24097222 | I32: اكتوبر | J32: عباسيه-وايلى | K32: 2 | L32: 3 | M32: 0.23263889 | N32: فيصل | O32: التجمع1-التجمع5 | P32: 2 | Q32: 3 | R32: 0.24652778 | S32: اكتوبر | T32: الوايلى - العباسية | U32: 2 | V32: 3 | W32: 0.23958333 | X32: عباس | Y32: المرغنى - عباس | Z32: 2 | AA32: 3 | AB32: 0.25 | AC32: اكتوبر | AD32: الوايلى - عباسيه | AE32: 2 | AF32: 3 | AG32: 0.23958333 | AH32: اكتوبر | AI32: بهتيم -الترعه | AJ32: 1 | AK32: 1 | AM32: =AJ32+AE32+Z32+U32+P32+K32+F32 -> 14 | AN32: =AK32+AF32+AA32+V32+Q32+L32+G32 -> 20
A33: 34 | B33: على الشحات | C33: 0.23611111 | D33: ابس كريم(3فروع) | E33: عبور2 | F33: 2 | G33: 4 | H33: 0.24305556 | I33: الطوابق | J33: النزهه | K33: 2 | L33: 2 | M33: 0.25 | N33: الطوابق | O33: المطريه | P33: 2 | Q33: 2 | R33: 0.25 | S33: الطوابق | T33: العبور | U33: 2 | V33: 2 | W33: 0.25 | X33: الطوابق | Y33: التجمع 1 - التجمع 5 | Z33: 2 | AA33: 3 | AB33: 0.24652778 | AC33: النزهه | AD33: المعادى 1 - المعادى 2 | AE33: 2 | AF33: 3 | AG33: 0.25 | AH33: منتزه-وايلى | AI33: بهتيم | AJ33: 2 | AK33: 3 | AM33: =AJ33+AE33+Z33+U33+P33+K33+F33 -> 14 | AN33: =AK33+AF33+AA33+V33+Q33+L33+G33 -> 19
A34: 55 | B34: محمود عادل حلمى | C34: سنوى | D34: سنوى | F34: 0 | G34: 0 | H34: غياب | I34: غياب | K34: 0 | L34: 0 | M34: غياب | N34: غياب | P34: 0 | Q34: 0 | R34: راحة | S34: راحة | U34: 0 | V34: 0 | W34: غياب | X34: غياب بدون اذن | Z34: 0 | AA34: 0 | AB34: غياب | AC34: غياب بدون اذن | AE34: 0 | AF34: 0 | AG34: غياب | AH34: غياب بدون اذن | AJ34: 0 | AK34: 0 | AM34: =AJ34+AE34+Z34+U34+P34+K34+F34 -> 0 | AN34: =AK34+AF34+AA34+V34+Q34+L34+G34 -> 0
A35: 37 | B35: عبد الرحمن عاطف | C35: 0.26180556 | D35: السواح | E35: العبور-بهتيم | F35: 2 | G35: 3 | H35: 0.25 | I35: السواح | J35: ثلاجه العبور | K35: 2 | L35: 2 | M35: 0.25694444 | N35: السواح | O35: شبرا-الدوران | P35: 2 | Q35: 3 | R35: راحة | S35: راحة | U35: 0 | V35: 0 | W35: 0.26388889 | X35: السواح | Y35: ثلاجه العبور | Z35: 2 | AA35: 2 | AB35: 0.26041667 | AC35: السواح | AD35: فيصل-الطوابق | AE35: 2 | AF35: 3 | AG35: 0.26041667 | AH35: السواح | AI35: عبور ثلاجه | AJ35: 2 | AK35: 2 | AM35: =AJ35+AE35+Z35+U35+P35+K35+F35 -> 12 | AN35: =AK35+AF35+AA35+V35+Q35+L35+G35 -> 15
A36: 38 | B36: جمال فؤاد | C36: 0.25 | D36: الشيراتون | E36: العاشر من رمضان | F36: 2 | G36: 2 | H36: 0.25 | I36: المطريه | J36: الكوربه-منتزه منفذ المصنع | K36: 2 | L36: 3 | M36: 0.25 | N36: الشريف | O36: بهتيم منفذ المصنع | P36: 3 | Q36: 3 | R36: راحة | S36: راحة | U36: 0 | V36: 0 | W36: 0.25 | X36: الوسط | Y36: الوسط-الشريف | Z36: 2 | AA36: 3 | AB36: 0.25 | AC36: الكوربه | AD36: العبور | AE36: 2 | AF36: 2 | AG36: 0.25 | AH36: الوسط | AI36: الوسط-الشريف بهتيم | AJ36: 3 | AK36: 4 | AM36: =AJ36+AE36+Z36+U36+P36+K36+F36 -> 14 | AN36: =AK36+AF36+AA36+V36+Q36+L36+G36 -> 17
A37: 39 | B37: على النبوى | C37: 0.26180556 | D37: عباسيه | E37: العاشر-مكرم | F37: 2 | G37: 3 | H37: 0.26736111 | I37: الجسر | J37: فيصل | K37: 2 | L37: 2 | M37: 0.26388889 | N37: النزهه | O37: عرابى-الدقى | P37: 2 | Q37: 3 | R37: راحة | S37: راحة | U37: 0 | V37: 0 | W37: 0.25347222 | X37: النزهة | Y37: المعادى 1 - المعادى 2 | Z37: 2 | AA37: 3 | AB37: 0.25 | AC37: فيصل | AD37: عباس- المرغنى | AE37: 2 | AF37: 3 | AG37: 0.26736111 | AH37: الطوابق | AI37: مسطرد بهتيم | AJ37: 3 | AK37: 3 | AM37: =AJ37+AE37+Z37+U37+P37+K37+F37 -> 13 | AN37: =AK37+AF37+AA37+V37+Q37+L37+G37 -> 17
A38: 40 | B38: احمد فوزى | C38: 0.26319444 | D38: شبرا-الدوران | E38: التجمع1-التجمع5 | F38: 2 | G38: 4 | H38: 0.25 | I38: عرابى-الدقى | J38: العاشر-مكرم | K38: 2 | L38: 4 | M38: سنوى | N38: سنوى | P38: 0 | Q38: 0 | R38: راحة | S38: راحة | U38: 0 | V38: 0 | W38: 0.25694444 | X38: العاشر | Y38: الدقى - عرابى | Z38: 2 | AA38: 3 | AB38: 0.26041667 | AC38: شبرا - الدوران | AD38: مكرم-العاشر | AE38: 2 | AF38: 4 | AG38: 0.26388889 | AH38: الجسر | AI38: مكرم-العاشر | AJ38: 2 | AK38: 3 | AM38: =AJ38+AE38+Z38+U38+P38+K38+F38 -> 10 | AN38: =AK38+AF38+AA38+V38+Q38+L38+G38 -> 18
A39: 65 | B39: محمود عبد الفتاح | C39: 0.28472222 | D39: المطريه | E39: جاردنبا-الشيراتون | F39: 2 | G39: 3 | H39: 0.29166667 | I39: الكوربه | J39: الوسط-الشريف | K39: 2 | L39: 3 | M39: 0.28472222 | N39: مسطرد | O39: مصر للطيران | P39: 2 | Q39: 2 | R39: راحة | S39: راحة | U39: 0 | V39: 0 | W39: 0.28472222 | X39: الدوران | Y39: الشيراتون - جاردينيا | Z39: 2 | AA39: 3 | AB39: 0.29166667 | AC39: ايس كريم(11فرع) | AE39: 1 | AF39: 11 | AG39: 0.28472222 | AH39: المطريه | AI39: جاردنيا-الشيراتون | AJ39: 2 | AK39: 3 | AM39: =AJ39+AE39+Z39+U39+P39+K39+F39 -> 11 | AN39: =AK39+AF39+AA39+V39+Q39+L39+G39 -> 25
A40: 28 | B40: سيد على | C40: 0.375 | D40: مبيعات | F40: 1 | G40: 1 | H40: 0.375 | K40: 1 | L40: 1 | M40: 0.375 | N40: مبيعات | P40: 1 | Q40: 1 | R40: راحة | S40: راحة | U40: 0 | V40: 0 | W40: سنوى | X40: عارضة | Z40: 0 | AA40: 0 | AB40: 0.375 | AC40: مبيعات | AE40: 1 | AF40: 1 | AG40: 0.375 | AH40: السادات | AJ40: 1 | AK40: 1 | AM40: =AJ40+AE40+Z40+U40+P40+K40+F40 -> 5 | AN40: =AK40+AF40+AA40+V40+Q40+L40+G40 -> 5
...

Sheet تحليل الاداء 
A1: م | B1: اسم السائق | C1: مواعيد الحضور | D1: 46140 | E1: 46140 | F1: عدد الرحلات | G1: عدد الفروع | H1: مواعيد الحضور | I1: 46141 | J1: 46141 | K1: عدد الرحلات | L1: عدد الفروع | M1: مواعيد الحضور | N1: 46142 | O1: 46142 | P1: عدد الرحلات | Q1: عدد الفروع | R1: مواعيد الحضور | S1: 46143 | T1: 46143 | U1: عدد الرحلات | V1: عدد الفروع | W1: مواعيد الحضور | X1: 46144 | Y1: 46144 | Z1: عدد الرحلات | AA1: عدد الفروع | AB1: مواعيد الحضور | AC1: 46145 | AD1: 46145 | AE1: عدد الرحلات | AF1: عدد الفروع | AG1: مواعيد الحضور | AH1: 46146 | AI1: 46146 | AJ1: عدد الرحلات | AK1: عدد الفروع | AM1: عدد الرحلات المجمع اسبوعى | AN1: عدد الفروع المجمع اسبوعى
A2: 2 | B2: عمرو محمد حسنى | C2: 0.25 | D2: الشروق1-الشروق3 | E2: سرياقوس | F2: 2 | G2: 3 | AM2: =AJ2+AE2+Z2+U2+P2+K2+F2 -> 2 | AN2: =AK2+AF2+AA2+V2+Q2+L2+G2 -> 3
A3: 3 | B3: محمد حسن حسان | C3: 0.23958333 | D3: الجسر | E3: الجسر-النزهه | F3: 2 | G3: 3 | AM3: =AJ3+AE3+Z3+U3+P3+K3+F3 -> 2 | AN3: =AK3+AF3+AA3+V3+Q3+L3+G3 -> 3
A4: 4 | B4: احمد حسن | C4: 0.25347222 | D4: الدقى | E4: المعادى1-المعادى2 | F4: 2 | G4: 3 | AM4: =AJ4+AE4+Z4+U4+P4+K4+F4 -> 2 | AN4: =AK4+AF4+AA4+V4+Q4+L4+G4 -> 3
A5: 7 | B5: عمرو عبد الرحمن | C5: 0.25694444 | D5: الطوابق | E5: مسطرد | F5: 2 | G5: 2 | AM5: =AJ5+AE5+Z5+U5+P5+K5+F5 -> 2 | AN5: =AK5+AF5+AA5+V5+Q5+L5+G5 -> 2
B6: كريم محمود | C6: 0.27777778 | D6: الشريف | E6: الشروق1-الشروق3 | F6: 2 | G6: 3 | AM6: =AJ6+AE6+Z6+U6+P6+K6+F6 -> 2 | AN6: =AK6+AF6+AA6+V6+Q6+L6+G6 -> 3
B7: على حمدى | C7: 0.26041667 | D7: عرابى | E7: وايلى-عباسيه | F7: 2 | G7: 3 | AM7: =AJ7+AE7+Z7+U7+P7+K7+F7 -> 2 | AN7: =AK7+AF7+AA7+V7+Q7+L7+G7 -> 3
A8: 8 | B8: رضا معروف | C8: سنوى | D8: سنوى | F8: 0 | G8: 0 | AM8: =AJ8+AE8+Z8+U8+P8+K8+F8 -> 0 | AN8: =AK8+AF8+AA8+V8+Q8+L8+G8 -> 0
A9: 10 | B9: وائل على | C9: 0.25 | D9: جاردنيا -مكرم | E9: فبصل- الطوابق | F9: 2 | G9: 4 | AM9: =AJ9+AE9+Z9+U9+P9+K9+F9 -> 2 | AN9: =AK9+AF9+AA9+V9+Q9+L9+G9 -> 4
B10: اسامه مصطفى | C10: 0.24652778 | D10: مسطرد-المطريه | E10: العبور2 | F10: 2 | G10: 3 | AM10: =AJ10+AE10+Z10+U10+P10+K10+F10 -> 2 | AN10: =AK10+AF10+AA10+V10+Q10+L10+G10 -> 3
A11: 12 | B11: على عادل عبد الفتاح | C11: 0.24652778 | D11: فيصل | E11: عرابى-الدقى | F11: 2 | G11: 3 | AM11: =AJ11+AE11+Z11+U11+P11+K11+F11 -> 2 | AN11: =AK11+AF11+AA11+V11+Q11+L11+G11 -> 3
A12: 41 | B12: رجب محمد مصطفى | C12: 0.24305556 | D12: الدوران شبرا | E12: السواح-المطريه | F12: 2 | G12: 4 | AM12: =AJ12+AE12+Z12+U12+P12+K12+F12 -> 2 | AN12: =AK12+AF12+AA12+V12+Q12+L12+G12 -> 4
B13: محمد صلاح | C13: 0.25 | D13: اكتوبر | E13: العاشر من رمضان | F13: 2 | G13: 2 | AM13: =AJ13+AE13+Z13+U13+P13+K13+F13 -> 2 | AN13: =AK13+AF13+AA13+V13+Q13+L13+G13 -> 2
A14: 13 | B14: علاء مجدى | C14: 0.23611111 | D14: المرغنى-عباس | E14: بهتيم | F14: 2 | G14: 3 | AM14: =AJ14+AE14+Z14+U14+P14+K14+F14 -> 2 | AN14: =AK14+AF14+AA14+V14+Q14+L14+G14 -> 3
A15: 14 | B15: مصطفى احمد | C15: 0.25 | D15: منتزه -وايلى | E15: منفذ المصنع ابومحرم | F15: 3 | G15: 4 | AM15: =AJ15+AE15+Z15+U15+P15+K15+F15 -> 3 | AN15: =AK15+AF15+AA15+V15+Q15+L15+G15 -> 4
A16: 17 | B16: الشناوى سرور | C16: سنوى | D16: سنوى | F16: 0 | G16: 0 | AM16: =AJ16+AE16+Z16+U16+P16+K16+F16 -> 0 | AN16: =AK16+AF16+AA16+V16+Q16+L16+G16 -> 0
A17: 18 | B17: احمد عواد | C17: راحة | D17: راحة | F17: 0 | G17: 0 | AM17: =AJ17+AE17+Z17+U17+P17+K17+F17 -> 0 | AN17: =AK17+AF17+AA17+V17+Q17+L17+G17 -> 0
B18: محمد مراد | C18: راحة | D18: راحة | F18: 0 | G18: 0 | AM18: =AJ18+AE18+Z18+U18+P18+K18+F18 -> 0 | AN18: =AK18+AF18+AA18+V18+Q18+L18+G18 -> 0
B19: خالد عبده | C19: راحة | D19: راحة | F19: 0 | G19: 0 | AM19: =AJ19+AE19+Z19+U19+P19+K19+F19 -> 0 | AN19: =AK19+AF19+AA19+V19+Q19+L19+G19 -> 0
A20: 19 | B20: سيد محمد العسال | C20: راحة | D20: راحة | F20: 0 | G20: 0 | AM20: =AJ20+AE20+Z20+U20+P20+K20+F20 -> 0 | AN20: =AK20+AF20+AA20+V20+Q20+L20+G20 -> 0
A21: 20 | B21: صبري امام | C21: راحة | D21: راحة | F21: 0 | G21: 0 | AM21: =AJ21+AE21+Z21+U21+P21+K21+F21 -> 0 | AN21: =AK21+AF21+AA21+V21+Q21+L21+G21 -> 0
A22: 22 | B22: سامح عبد السميع | C22: راحة | D22: راحة | F22: 0 | G22: 0 | AM22: =AJ22+AE22+Z22+U22+P22+K22+F22 -> 0 | AN22: =AK22+AF22+AA22+V22+Q22+L22+G22 -> 0
A23: 23 | B23: جمعه السيد | C23: 0.25 | D23: المطريه-مسطرد | E23: مصر للطيران سرياقوس | F23: 2 | G23: 3 | AM23: =AJ23+AE23+Z23+U23+P23+K23+F23 -> 2 | AN23: =AK23+AF23+AA23+V23+Q23+L23+G23 -> 3
B24: خالد صبرى | C24: سنوى | D24: سنوى | F24: 0 | G24: 0 | AM24: =AJ24+AE24+Z24+U24+P24+K24+F24 -> 0 | AN24: =AK24+AF24+AA24+V24+Q24+L24+G24 -> 0
B25: محمود أبو طالب | C25: سنوى | D25: سنوى | F25: 0 | G25: 0 | AM25: =AJ25+AE25+Z25+U25+P25+K25+F25 -> 0 | AN25: =AK25+AF25+AA25+V25+Q25+L25+G25 -> 0
A26: 25 | B26: عبد الرحمن محمد | C26: 0.25 | D26: العاشر من رمضان | E26: جاردنيا-الشيرتون | F26: 2 | G26: 3 | AM26: =AJ26+AE26+Z26+U26+P26+K26+F26 -> 2 | AN26: =AK26+AF26+AA26+V26+Q26+L26+G26 -> 3
A27: 26 | B27: خالد محمد ابراهيم | C27: 0.26041667 | D27: المعادى | E27: مكرم-العاشر | F27: 2 | G27: 3 | AM27: =AJ27+AE27+Z27+U27+P27+K27+F27 -> 2 | AN27: =AK27+AF27+AA27+V27+Q27+L27+G27 -> 3
A28: 27 | B28: رامى حسن محمد | C28: 0.23958333 | D28: العاشر | E28: عباس-المرغنى | F28: 2 | G28: 3 | AM28: =AJ28+AE28+Z28+U28+P28+K28+F28 -> 2 | AN28: =AK28+AF28+AA28+V28+Q28+L28+G28 -> 3
A29: 28 | B29: احمد سعيد سالم | C29: 0.26041667 | D29: الكوربه-توكيل | F29: 1 | G29: 2 | AM29: =AJ29+AE29+Z29+U29+P29+K29+F29 -> 1 | AN29: =AK29+AF29+AA29+V29+Q29+L29+G29 -> 2
A30: 33 | B30: رامى عادل | C30: 0.25694444 | D30: الشيراتون | F30: 1 | G30: 1 | AM30: =AJ30+AE30+Z30+U30+P30+K30+F30 -> 1 | AN30: =AK30+AF30+AA30+V30+Q30+L30+G30 -> 1
A31: 35 | B31: محمد عباس | C31: 0.26736111 | D31: الدوران | E31: مسطرد مأموريه | F31: 3 | G31: 3 | AM31: =AJ31+AE31+Z31+U31+P31+K31+F31 -> 3 | AN31: =AK31+AF31+AA31+V31+Q31+L31+G31 -> 3
B32: عمرو المهدى | C32: 0.25 | D32: العبور | E32: بهتيم | F32: 2 | G32: 2 | AM32: =AJ32+AE32+Z32+U32+P32+K32+F32 -> 2 | AN32: =AK32+AF32+AA32+V32+Q32+L32+G32 -> 2
B33: على الشحات | C33: 0.25347222 | D33: المعادى2 | E33: اكتوبر | F33: 2 | G33: 2 | AM33: =AJ33+AE33+Z33+U33+P33+K33+F33 -> 2 | AN33: =AK33+AF33+AA33+V33+Q33+L33+G33 -> 2
B34: محمود عادل حلمى | C34: استقاله | D34: استقاله | F34: 0 | G34: 0 | AM34: =AJ34+AE34+Z34+U34+P34+K34+F34 -> 0 | AN34: =AK34+AF34+AA34+V34+Q34+L34+G34 -> 0
B35: عبد الرحمن عاطف | C35: 0.26041667 | D35: السواح | E35: ثلاجه العبور | F35: 2 | G35: 2 | AM35: =AJ35+AE35+Z35+U35+P35+K35+F35 -> 2 | AN35: =AK35+AF35+AA35+V35+Q35+L35+G35 -> 2
B36: جمال فؤاد | C36: 0.25 | D36: الوسط | E36: مسطرد الكوربه-منتزه بهتيم | F36: 3 | G36: 4 | AM36: =AJ36+AE36+Z36+U36+P36+K36+F36 -> 3 | AN36: =AK36+AF36+AA36+V36+Q36+L36+G36 -> 4
B37: على النبوى | C37: 0.26041667 | D37: النزهه | E37: شبرا-الدوران | F37: 2 | G37: 3 | AM37: =AJ37+AE37+Z37+U37+P37+K37+F37 -> 2 | AN37: =AK37+AF37+AA37+V37+Q37+L37+G37 -> 3
B38: احمد فوزى | C38: 0.26388889 | D38: التجمع1-التجمع5 | E38: التجمع1-التجمع5 | F38: 2 | G38: 4 | AM38: =AJ38+AE38+Z38+U38+P38+K38+F38 -> 2 | AN38: =AK38+AF38+AA38+V38+Q38+L38+G38 -> 4
A39: 34 | B39: محمود عبد الفتاح | C39: 0.29166667 | D39: عباسيه | E39: الوسط-الشريف بهتيم | F39: 3 | G39: 4 | AM39: =AJ39+AE39+Z39+U39+P39+K39+F39 -> 3 | AN39: =AK39+AF39+AA39+V39+Q39+L39+G39 -> 4
B40: سيد على | C40: 0.375 | D40: مبيعات | F40: 1 | G40: 1 | AM40: =AJ40+AE40+Z40+U40+P40+K40+F40 -> 1 | AN40: =AK40+AF40+AA40+V40+Q40+L40+G40 -> 1
...

Sheet تحليل الاداء  
A1: م | B1: اسم السائق | C1: مواعيد الحضور | D1: 46147 | E1: 46147 | F1: عدد الرحلات | G1: عدد الفروع | H1: مواعيد الحضور | I1: 46148 | J1: 46148 | K1: عدد الرحلات | L1: عدد الفروع | M1: مواعيد الحضور | N1: 46149 | O1: 46149 | P1: عدد الرحلات | Q1: عدد الفروع | R1: مواعيد الحضور | S1: 46150 | T1: 46150 | U1: عدد الرحلات | V1: عدد الفروع | W1: مواعيد الحضور | X1: 46151 | Y1: 46151 | Z1: عدد الرحلات | AA1: عدد الفروع | AB1: مواعيد الحضور | AC1: 46152 | AD1: 46152 | AE1: عدد الرحلات | AF1: عدد الفروع | AG1: مواعيد الحضور | AH1: 46153 | AI1: 46153 | AJ1: عدد الرحلات | AK1: عدد الفروع | AM1: عدد الرحلات المجمع اسبوعى | AN1: عدد الفروع المجمع اسبوعى
A2: 2 | B2: عمرو محمد حسنى | AM2: =AJ2+AE2+Z2+U2+P2+K2+F2 -> 0 | AN2: =AK2+AF2+AA2+V2+Q2+L2+G2 -> 0
A3: 3 | B3: محمد حسن حسان | AM3: =AJ3+AE3+Z3+U3+P3+K3+F3 -> 0 | AN3: =AK3+AF3+AA3+V3+Q3+L3+G3 -> 0
A4: 4 | B4: احمد حسن | AM4: =AJ4+AE4+Z4+U4+P4+K4+F4 -> 0 | AN4: =AK4+AF4+AA4+V4+Q4+L4+G4 -> 0
A5: 7 | B5: عمرو عبد الرحمن | AM5: =AJ5+AE5+Z5+U5+P5+K5+F5 -> 0 | AN5: =AK5+AF5+AA5+V5+Q5+L5+G5 -> 0
B6: كريم محمود | AM6: =AJ6+AE6+Z6+U6+P6+K6+F6 -> 0 | AN6: =AK6+AF6+AA6+V6+Q6+L6+G6 -> 0
A7: 8 | B7: على حمدى | AM7: =AJ7+AE7+Z7+U7+P7+K7+F7 -> 0 | AN7: =AK7+AF7+AA7+V7+Q7+L7+G7 -> 0
A8: 10 | B8: رضا معروف | AM8: =AJ8+AE8+Z8+U8+P8+K8+F8 -> 0 | AN8: =AK8+AF8+AA8+V8+Q8+L8+G8 -> 0
A9: 11 | B9: وائل على | AM9: =AJ9+AE9+Z9+U9+P9+K9+F9 -> 0 | AN9: =AK9+AF9+AA9+V9+Q9+L9+G9 -> 0
A10: 44 | B10: اسامة مصطفي | AM10: =AJ10+AE10+Z10+U10+P10+K10+F10 -> 0 | AN10: =AK10+AF10+AA10+V10+Q10+L10+G10 -> 0
A11: 13 | B11: على عادل عبد الفتاح | AM11: =AJ11+AE11+Z11+U11+P11+K11+F11 -> 0 | AN11: =AK11+AF11+AA11+V11+Q11+L11+G11 -> 0
A12: 14 | B12: رجب محمد مصطفى | AM12: =AJ12+AE12+Z12+U12+P12+K12+F12 -> 0 | AN12: =AK12+AF12+AA12+V12+Q12+L12+G12 -> 0
A13: 17 | B13: محمد صلاح | AM13: =AJ13+AE13+Z13+U13+P13+K13+F13 -> 0 | AN13: =AK13+AF13+AA13+V13+Q13+L13+G13 -> 0
A14: 18 | B14: علاء مجدى | AM14: =AJ14+AE14+Z14+U14+P14+K14+F14 -> 0 | AN14: =AK14+AF14+AA14+V14+Q14+L14+G14 -> 0
B15: مصطفى احمد | AM15: =AJ15+AE15+Z15+U15+P15+K15+F15 -> 0 | AN15: =AK15+AF15+AA15+V15+Q15+L15+G15 -> 0
A16: 19 | B16: الشناوى سرور | AM16: =AJ16+AE16+Z16+U16+P16+K16+F16 -> 0 | AN16: =AK16+AF16+AA16+V16+Q16+L16+G16 -> 0
A17: 20 | B17: احمد عواد | AM17: =AJ17+AE17+Z17+U17+P17+K17+F17 -> 0 | AN17: =AK17+AF17+AA17+V17+Q17+L17+G17 -> 0
A18: 22 | B18: محمد مراد | AM18: =AJ18+AE18+Z18+U18+P18+K18+F18 -> 0 | AN18: =AK18+AF18+AA18+V18+Q18+L18+G18 -> 0
A19: 23 | B19: خالد عبده | AM19: =AJ19+AE19+Z19+U19+P19+K19+F19 -> 0 | AN19: =AK19+AF19+AA19+V19+Q19+L19+G19 -> 0
B20: سيد محمد العسال | AM20: =AJ20+AE20+Z20+U20+P20+K20+F20 -> 0 | AN20: =AK20+AF20+AA20+V20+Q20+L20+G20 -> 0
A21: 24 | B21: صبري امام | AM21: =AJ21+AE21+Z21+U21+P21+K21+F21 -> 0 | AN21: =AK21+AF21+AA21+V21+Q21+L21+G21 -> 0
A22: 25 | B22: سامح عبد السميع | AM22: =AJ22+AE22+Z22+U22+P22+K22+F22 -> 0 | AN22: =AK22+AF22+AA22+V22+Q22+L22+G22 -> 0
A23: 28 | B23: جمعه السيد | AM23: =AJ23+AE23+Z23+U23+P23+K23+F23 -> 0 | AN23: =AK23+AF23+AA23+V23+Q23+L23+G23 -> 0
A24: 33 | B24: خالد صبرى | AM24: =AJ24+AE24+Z24+U24+P24+K24+F24 -> 0 | AN24: =AK24+AF24+AA24+V24+Q24+L24+G24 -> 0
A25: 35 | B25: محمود أبو طالب | AM25: =AJ25+AE25+Z25+U25+P25+K25+F25 -> 0 | AN25: =AK25+AF25+AA25+V25+Q25+L25+G25 -> 0
B26: عبد الرحمن محمد | AM26: =AJ26+AE26+Z26+U26+P26+K26+F26 -> 0 | AN26: =AK26+AF26+AA26+V26+Q26+L26+G26 -> 0
B27: خالد محمد ابراهيم | AM27: =AJ27+AE27+Z27+U27+P27+K27+F27 -> 0 | AN27: =AK27+AF27+AA27+V27+Q27+L27+G27 -> 0
B28: رامى حسن محمد | AM28: =AJ28+AE28+Z28+U28+P28+K28+F28 -> 0 | AN28: =AK28+AF28+AA28+V28+Q28+L28+G28 -> 0
B29: احمد سعيد سالم | AM29: =AJ29+AE29+Z29+U29+P29+K29+F29 -> 0 | AN29: =AK29+AF29+AA29+V29+Q29+L29+G29 -> 0
A30: 55 | B30: رامى عادل | AM30: =AJ30+AE30+Z30+U30+P30+K30+F30 -> 0 | AN30: =AK30+AF30+AA30+V30+Q30+L30+G30 -> 0
A31: 37 | B31: محمد عباس | AM31: =AJ31+AE31+Z31+U31+P31+K31+F31 -> 0 | AN31: =AK31+AF31+AA31+V31+Q31+L31+G31 -> 0
A32: 67 | B32: عمرو المهدي | AM32: =AJ32+AE32+Z32+U32+P32+K32+F32 -> 0 | AN32: =AK32+AF32+AA32+V32+Q32+L32+G32 -> 0
B33: على الشحات | AM33: =AJ33+AE33+Z33+U33+P33+K33+F33 -> 0 | AN33: =AK33+AF33+AA33+V33+Q33+L33+G33 -> 0
A34: 38 | B34: محمود عادل حلمى | AM34: =AJ34+AE34+Z34+U34+P34+K34+F34 -> 0 | AN34: =AK34+AF34+AA34+V34+Q34+L34+G34 -> 0
B35: عبد الرحمن عاطف | AM35: =AJ35+AE35+Z35+U35+P35+K35+F35 -> 0 | AN35: =AK35+AF35+AA35+V35+Q35+L35+G35 -> 0
A36: 40 | B36: جمال فؤاد | AM36: =AJ36+AE36+Z36+U36+P36+K36+F36 -> 0 | AN36: =AK36+AF36+AA36+V36+Q36+L36+G36 -> 0
B37: على النبوى | AM37: =AJ37+AE37+Z37+U37+P37+K37+F37 -> 0 | AN37: =AK37+AF37+AA37+V37+Q37+L37+G37 -> 0
A38: 65 | B38: احمد فوزى | AM38: =AJ38+AE38+Z38+U38+P38+K38+F38 -> 0 | AN38: =AK38+AF38+AA38+V38+Q38+L38+G38 -> 0
B39: محمود عبد الفتاح | AM39: =AJ39+AE39+Z39+U39+P39+K39+F39 -> 0 | AN39: =AK39+AF39+AA39+V39+Q39+L39+G39 -> 0
B40: سيد على | AM40: =AJ40+AE40+Z40+U40+P40+K40+F40 -> 0 | AN40: =AK40+AF40+AA40+V40+Q40+L40+G40 -> 0
...

Sheet تحليل الاداء   
A1: م | B1: اسم السائق | C1: مواعيد الحضور | D1: 46154 | E1: 46154 | F1: عدد الرحلات | G1: عدد الفروع | H1: مواعيد الحضور | I1: 46155 | J1: 46155 | K1: عدد الرحلات | L1: عدد الفروع | M1: مواعيد الحضور | N1: 46156 | O1: 46156 | P1: عدد الرحلات | Q1: عدد الفروع | R1: مواعيد الحضور | S1: 46157 | T1: 46156 | U1: عدد الرحلات | V1: عدد الفروع | W1: مواعيد الحضور | X1: 46158 | Y1: 46158 | Z1: عدد الرحلات | AA1: عدد الفروع | AB1: مواعيد الحضور | AC1: 46159 | AD1: 46159 | AE1: عدد الرحلات | AF1: عدد الفروع | AG1: مواعيد الحضور | AH1: 46160 | AI1: 46160 | AJ1: عدد الرحلات | AK1: عدد الفروع | AL1: مواعيد الحضور | AM1: 46161 | AN1: 46161 | AO1: عدد الرحلات | AP1: عدد الفروع | AQ1: مواعيد الحضور | AR1: 46162 | AS1: 46162 | AT1: عدد الرحلات | AU1: عدد الفروع | AV1: عدد الرحلات المجمع اسبوعى | AW1: عدد الفروع المجمع اسبوعى | AX1: عدد الرحلات المجمع شهرى | AY1: عدد الفروع المجمع شهرى
A2: 2 | B2: عمرو محمد حسنى | AV2: =AT2+AE2+Z2+U2+P2+K2+F2 -> 0 | AW2: =AU2+AG2+AA2+V2+Q2+L2+G2 -> 0 | AX2: =AV2+'تحليل الاداء '!AM2+'تحليل الاداء '!AM2+'تحليل الاداء'!AM2 -> 14 | AY2: =AW2+'تحليل الاداء '!AN2+'تحليل الاداء '!AN2+'تحليل الاداء'!AN2 -> 22
A3: 3 | B3: محمد حسن حسان | AV3: =AT3+AE3+Z3+U3+P3+K3+F3 -> 0 | AW3: =AU3+AG3+AA3+V3+Q3+L3+G3 -> 0 | AX3: =AV3+'تحليل الاداء '!AM3+'تحليل الاداء '!AM3+'تحليل الاداء'!AM3 -> 15 | AY3: =AW3+'تحليل الاداء '!AN3+'تحليل الاداء '!AN3+'تحليل الاداء'!AN3 -> 22
A4: 4 | B4: احمد حسن | AV4: =AT4+AE4+Z4+U4+P4+K4+F4 -> 0 | AW4: =AU4+AG4+AA4+V4+Q4+L4+G4 -> 0 | AX4: =AV4+'تحليل الاداء '!AM4+'تحليل الاداء '!AM4+'تحليل الاداء'!AM4 -> 6 | AY4: =AW4+'تحليل الاداء '!AN4+'تحليل الاداء '!AN4+'تحليل الاداء'!AN4 -> 7
A5: 7 | B5: عمرو عبد الرحمن | AV5: =AT5+AE5+Z5+U5+P5+K5+F5 -> 0 | AW5: =AU5+AG5+AA5+V5+Q5+L5+G5 -> 0 | AX5: =AV5+'تحليل الاداء '!AM5+'تحليل الاداء '!AM5+'تحليل الاداء'!AM5 -> 10 | AY5: =AW5+'تحليل الاداء '!AN5+'تحليل الاداء '!AN5+'تحليل الاداء'!AN5 -> 17
B6: كريم محمود | AV6: =AT6+AE6+Z6+U6+P6+K6+F6 -> 0 | AW6: =AU6+AG6+AA6+V6+Q6+L6+G6 -> 0 | AX6: =AV6+'تحليل الاداء '!AM6+'تحليل الاداء '!AM6+'تحليل الاداء'!AM6 -> 15 | AY6: =AW6+'تحليل الاداء '!AN6+'تحليل الاداء '!AN6+'تحليل الاداء'!AN6 -> 25
A7: 8 | B7: على حمدى | AV7: =AT7+AE7+Z7+U7+P7+K7+F7 -> 0 | AW7: =AU7+AG7+AA7+V7+Q7+L7+G7 -> 0 | AX7: =AV7+'تحليل الاداء '!AM7+'تحليل الاداء '!AM7+'تحليل الاداء'!AM7 -> 4 | AY7: =AW7+'تحليل الاداء '!AN7+'تحليل الاداء '!AN7+'تحليل الاداء'!AN7 -> 5
A8: 10 | B8: رضا معروف | AV8: =AT8+AE8+Z8+U8+P8+K8+F8 -> 0 | AW8: =AU8+AG8+AA8+V8+Q8+L8+G8 -> 0 | AX8: =AV8+'تحليل الاداء '!AM8+'تحليل الاداء '!AM8+'تحليل الاداء'!AM8 -> 11 | AY8: =AW8+'تحليل الاداء '!AN8+'تحليل الاداء '!AN8+'تحليل الاداء'!AN8 -> 13
A9: 11 | B9: وائل على | AV9: =AT9+AE9+Z9+U9+P9+K9+F9 -> 0 | AW9: =AU9+AG9+AA9+V9+Q9+L9+G9 -> 0 | AX9: =AV9+'تحليل الاداء '!AM9+'تحليل الاداء '!AM9+'تحليل الاداء'!AM9 -> 13 | AY9: =AW9+'تحليل الاداء '!AN9+'تحليل الاداء '!AN9+'تحليل الاداء'!AN9 -> 22
A10: 65 | B10: اسامة مصطفي | AV10: =AT10+AE10+Z10+U10+P10+K10+F10 -> 0 | AW10: =AU10+AG10+AA10+V10+Q10+L10+G10 -> 0 | AX10: =AV10+'تحليل الاداء '!AM10+'تحليل الاداء '!AM10+'تحليل الاداء'!AM10 -> 14 | AY10: =AW10+'تحليل الاداء '!AN10+'تحليل الاداء '!AN10+'تحليل الاداء'!AN10 -> 19
A11: 13 | B11: على عادل عبد الفتاح | AV11: =AT11+AE11+Z11+U11+P11+K11+F11 -> 0 | AW11: =AU11+AG11+AA11+V11+Q11+L11+G11 -> 0 | AX11: =AV11+'تحليل الاداء '!AM11+'تحليل الاداء '!AM11+'تحليل الاداء'!AM11 -> 10 | AY11: =AW11+'تحليل الاداء '!AN11+'تحليل الاداء '!AN11+'تحليل الاداء'!AN11 -> 14
A12: 14 | B12: رجب محمد مصطفى | AV12: =AT12+AE12+Z12+U12+P12+K12+F12 -> 0 | AW12: =AU12+AG12+AA12+V12+Q12+L12+G12 -> 0 | AX12: =AV12+'تحليل الاداء '!AM12+'تحليل الاداء '!AM12+'تحليل الاداء'!AM12 -> 13 | AY12: =AW12+'تحليل الاداء '!AN12+'تحليل الاداء '!AN12+'تحليل الاداء'!AN12 -> 21
A13: 17 | B13: محمد صلاح | AV13: =AT13+AE13+Z13+U13+P13+K13+F13 -> 0 | AW13: =AU13+AG13+AA13+V13+Q13+L13+G13 -> 0 | AX13: =AV13+'تحليل الاداء '!AM13+'تحليل الاداء '!AM13+'تحليل الاداء'!AM13 -> 12 | AY13: =AW13+'تحليل الاداء '!AN13+'تحليل الاداء '!AN13+'تحليل الاداء'!AN13 -> 15
A14: 18 | B14: علاء مجدى | AV14: =AT14+AE14+Z14+U14+P14+K14+F14 -> 0 | AW14: =AU14+AG14+AA14+V14+Q14+L14+G14 -> 0 | AX14: =AV14+'تحليل الاداء '!AM14+'تحليل الاداء '!AM14+'تحليل الاداء'!AM14 -> 14 | AY14: =AW14+'تحليل الاداء '!AN14+'تحليل الاداء '!AN14+'تحليل الاداء'!AN14 -> 23
B15: مصطفى احمد | AV15: =AT15+AE15+Z15+U15+P15+K15+F15 -> 0 | AW15: =AU15+AG15+AA15+V15+Q15+L15+G15 -> 0 | AX15: =AV15+'تحليل الاداء '!AM15+'تحليل الاداء '!AM15+'تحليل الاداء'!AM15 -> 15 | AY15: =AW15+'تحليل الاداء '!AN15+'تحليل الاداء '!AN15+'تحليل الاداء'!AN15 -> 20
A16: 19 | B16: الشناوى سرور | AV16: =AT16+AE16+Z16+U16+P16+K16+F16 -> 0 | AW16: =AU16+AG16+AA16+V16+Q16+L16+G16 -> 0 | AX16: =AV16+'تحليل الاداء '!AM16+'تحليل الاداء '!AM16+'تحليل الاداء'!AM16 -> 12 | AY16: =AW16+'تحليل الاداء '!AN16+'تحليل الاداء '!AN16+'تحليل الاداء'!AN16 -> 15
A17: 20 | B17: احمد عواد | AV17: =AT17+AE17+Z17+U17+P17+K17+F17 -> 0 | AW17: =AU17+AG17+AA17+V17+Q17+L17+G17 -> 0 | AX17: =AV17+'تحليل الاداء '!AM17+'تحليل الاداء '!AM17+'تحليل الاداء'!AM17 -> 15 | AY17: =AW17+'تحليل الاداء '!AN17+'تحليل الاداء '!AN17+'تحليل الاداء'!AN17 -> 18
A18: 22 | B18: محمد مراد | AV18: =AT18+AE18+Z18+U18+P18+K18+F18 -> 0 | AW18: =AU18+AG18+AA18+V18+Q18+L18+G18 -> 0 | AX18: =AV18+'تحليل الاداء '!AM18+'تحليل الاداء '!AM18+'تحليل الاداء'!AM18 -> 12 | AY18: =AW18+'تحليل الاداء '!AN18+'تحليل الاداء '!AN18+'تحليل الاداء'!AN18 -> 15
A19: 23 | B19: خالد عبده | AV19: =AT19+AE19+Z19+U19+P19+K19+F19 -> 0 | AW19: =AU19+AG19+AA19+V19+Q19+L19+G19 -> 0 | AX19: =AV19+'تحليل الاداء '!AM19+'تحليل الاداء '!AM19+'تحليل الاداء'!AM19 -> 10 | AY19: =AW19+'تحليل الاداء '!AN19+'تحليل الاداء '!AN19+'تحليل الاداء'!AN19 -> 10
B20: سيد محمد العسال | AV20: =AT20+AE20+Z20+U20+P20+K20+F20 -> 0 | AW20: =AU20+AG20+AA20+V20+Q20+L20+G20 -> 0 | AX20: =AV20+'تحليل الاداء '!AM20+'تحليل الاداء '!AM20+'تحليل الاداء'!AM20 -> 11 | AY20: =AW20+'تحليل الاداء '!AN20+'تحليل الاداء '!AN20+'تحليل الاداء'!AN20 -> 18
A21: 24 | B21: صبري امام | AV21: =AT21+AE21+Z21+U21+P21+K21+F21 -> 0 | AW21: =AU21+AG21+AA21+V21+Q21+L21+G21 -> 0 | AX21: =AV21+'تحليل الاداء '!AM21+'تحليل الاداء '!AM21+'تحليل الاداء'!AM21 -> 12 | AY21: =AW21+'تحليل الاداء '!AN21+'تحليل الاداء '!AN21+'تحليل الاداء'!AN21 -> 14
A22: 25 | B22: سامح عبد السميع | AV22: =AT22+AE22+Z22+U22+P22+K22+F22 -> 0 | AW22: =AU22+AG22+AA22+V22+Q22+L22+G22 -> 0 | AX22: =AV22+'تحليل الاداء '!AM22+'تحليل الاداء '!AM22+'تحليل الاداء'!AM22 -> 12 | AY22: =AW22+'تحليل الاداء '!AN22+'تحليل الاداء '!AN22+'تحليل الاداء'!AN22 -> 16
A23: 26 | B23: جمعه السيد | AV23: =AT23+AE23+Z23+U23+P23+K23+F23 -> 0 | AW23: =AU23+AG23+AA23+V23+Q23+L23+G23 -> 0 | AX23: =AV23+'تحليل الاداء '!AM23+'تحليل الاداء '!AM23+'تحليل الاداء'!AM23 -> 13 | AY23: =AW23+'تحليل الاداء '!AN23+'تحليل الاداء '!AN23+'تحليل الاداء'!AN23 -> 15
A24: 27 | B24: خالد صبرى | AV24: =AT24+AE24+Z24+U24+P24+K24+F24 -> 0 | AW24: =AU24+AG24+AA24+V24+Q24+L24+G24 -> 0 | AX24: =AV24+'تحليل الاداء '!AM24+'تحليل الاداء '!AM24+'تحليل الاداء'!AM24 -> 2 | AY24: =AW24+'تحليل الاداء '!AN24+'تحليل الاداء '!AN24+'تحليل الاداء'!AN24 -> 2
A25: 28 | B25: محمود أبو طالب | AV25: =AT25+AE25+Z25+U25+P25+K25+F25 -> 0 | AW25: =AU25+AG25+AA25+V25+Q25+L25+G25 -> 0 | AX25: =AV25+'تحليل الاداء '!AM25+'تحليل الاداء '!AM25+'تحليل الاداء'!AM25 -> 2 | AY25: =AW25+'تحليل الاداء '!AN25+'تحليل الاداء '!AN25+'تحليل الاداء'!AN25 -> 3
A26: 35 | B26: عبد الرحمن محمد | AV26: =AT26+AE26+Z26+U26+P26+K26+F26 -> 0 | AW26: =AU26+AG26+AA26+V26+Q26+L26+G26 -> 0 | AX26: =AV26+'تحليل الاداء '!AM26+'تحليل الاداء '!AM26+'تحليل الاداء'!AM26 -> 14 | AY26: =AW26+'تحليل الاداء '!AN26+'تحليل الاداء '!AN26+'تحليل الاداء'!AN26 -> 19
B27: خالد محمد ابراهيم | AV27: =AT27+AE27+Z27+U27+P27+K27+F27 -> 0 | AW27: =AU27+AG27+AA27+V27+Q27+L27+G27 -> 0 | AX27: =AV27+'تحليل الاداء '!AM27+'تحليل الاداء '!AM27+'تحليل الاداء'!AM27 -> 10 | AY27: =AW27+'تحليل الاداء '!AN27+'تحليل الاداء '!AN27+'تحليل الاداء'!AN27 -> 15
B28: رامى حسن محمد | AV28: =AT28+AE28+Z28+U28+P28+K28+F28 -> 0 | AW28: =AU28+AG28+AA28+V28+Q28+L28+G28 -> 0 | AX28: =AV28+'تحليل الاداء '!AM28+'تحليل الاداء '!AM28+'تحليل الاداء'!AM28 -> 14 | AY28: =AW28+'تحليل الاداء '!AN28+'تحليل الاداء '!AN28+'تحليل الاداء'!AN28 -> 19
B29: احمد سعيد سالم | AV29: =AT29+AE29+Z29+U29+P29+K29+F29 -> 0 | AW29: =AU29+AG29+AA29+V29+Q29+L29+G29 -> 0 | AX29: =AV29+'تحليل الاداء '!AM29+'تحليل الاداء '!AM29+'تحليل الاداء'!AM29 -> 9 | AY29: =AW29+'تحليل الاداء '!AN29+'تحليل الاداء '!AN29+'تحليل الاداء'!AN29 -> 11
B30: رامى عادل | AV30: =AT30+AE30+Z30+U30+P30+K30+F30 -> 0 | AW30: =AU30+AG30+AA30+V30+Q30+L30+G30 -> 0 | AX30: =AV30+'تحليل الاداء '!AM30+'تحليل الاداء '!AM30+'تحليل الاداء'!AM30 -> 12 | AY30: =AW30+'تحليل الاداء '!AN30+'تحليل الاداء '!AN30+'تحليل الاداء'!AN30 -> 18
B31: محمد عباس | AV31: =AT31+AE31+Z31+U31+P31+K31+F31 -> 0 | AW31: =AU31+AG31+AA31+V31+Q31+L31+G31 -> 0 | AX31: =AV31+'تحليل الاداء '!AM31+'تحليل الاداء '!AM31+'تحليل الاداء'!AM31 -> 15 | AY31: =AW31+'تحليل الاداء '!AN31+'تحليل الاداء '!AN31+'تحليل الاداء'!AN31 -> 21
B32: عمرو المهدي | AV32: =AT32+AE32+Z32+U32+P32+K32+F32 -> 0 | AW32: =AU32+AG32+AA32+V32+Q32+L32+G32 -> 0 | AX32: =AV32+'تحليل الاداء '!AM32+'تحليل الاداء '!AM32+'تحليل الاداء'!AM32 -> 16 | AY32: =AW32+'تحليل الاداء '!AN32+'تحليل الاداء '!AN32+'تحليل الاداء'!AN32 -> 22
B33: على الشحات | AV33: =AT33+AE33+Z33+U33+P33+K33+F33 -> 0 | AW33: =AU33+AG33+AA33+V33+Q33+L33+G33 -> 0 | AX33: =AV33+'تحليل الاداء '!AM33+'تحليل الاداء '!AM33+'تحليل الاداء'!AM33 -> 16 | AY33: =AW33+'تحليل الاداء '!AN33+'تحليل الاداء '!AN33+'تحليل الاداء'!AN33 -> 21
A34: 34 | B34: محمود عادل حلمى | AV34: =AT34+AE34+Z34+U34+P34+K34+F34 -> 0 | AW34: =AU34+AG34+AA34+V34+Q34+L34+G34 -> 0 | AX34: =AV34+'تحليل الاداء '!AM34+'تحليل الاداء '!AM34+'تحليل الاداء'!AM34 -> 0 | AY34: =AW34+'تحليل الاداء '!AN34+'تحليل الاداء '!AN34+'تحليل الاداء'!AN34 -> 0
A35: 55 | B35: عبد الرحمن عاطف | AV35: =AT35+AE35+Z35+U35+P35+K35+F35 -> 0 | AW35: =AU35+AG35+AA35+V35+Q35+L35+G35 -> 0 | AX35: =AV35+'تحليل الاداء '!AM35+'تحليل الاداء '!AM35+'تحليل الاداء'!AM35 -> 14 | AY35: =AW35+'تحليل الاداء '!AN35+'تحليل الاداء '!AN35+'تحليل الاداء'!AN35 -> 17
A36: 37 | B36: جمال فؤاد | AV36: =AT36+AE36+Z36+U36+P36+K36+F36 -> 0 | AW36: =AU36+AG36+AA36+V36+Q36+L36+G36 -> 0 | AX36: =AV36+'تحليل الاداء '!AM36+'تحليل الاداء '!AM36+'تحليل الاداء'!AM36 -> 17 | AY36: =AW36+'تحليل الاداء '!AN36+'تحليل الاداء '!AN36+'تحليل الاداء'!AN36 -> 21
A37: 38 | B37: على النبوى | AV37: =AT37+AE37+Z37+U37+P37+K37+F37 -> 0 | AW37: =AU37+AG37+AA37+V37+Q37+L37+G37 -> 0 | AX37: =AV37+'تحليل الاداء '!AM37+'تحليل الاداء '!AM37+'تحليل الاداء'!AM37 -> 15 | AY37: =AW37+'تحليل الاداء '!AN37+'تحليل الاداء '!AN37+'تحليل الاداء'!AN37 -> 20
A38: 39 | B38: احمد فوزى | AV38: =AT38+AE38+Z38+U38+P38+K38+F38 -> 0 | AW38: =AU38+AG38+AA38+V38+Q38+L38+G38 -> 0 | AX38: =AV38+'تحليل الاداء '!AM38+'تحليل الاداء '!AM38+'تحليل الاداء'!AM38 -> 12 | AY38: =AW38+'تحليل الاداء '!AN38+'تحليل الاداء '!AN38+'تحليل الاداء'!AN38 -> 22
A39: 40 | B39: محمود عبد الفتاح | AV39: =AT39+AE39+Z39+U39+P39+K39+F39 -> 0 | AW39: =AU39+AG39+AA39+V39+Q39+L39+G39 -> 0 | AX39: =AV39+'تحليل الاداء '!AM39+'تحليل الاداء '!AM39+'تحليل الاداء'!AM39 -> 14 | AY39: =AW39+'تحليل الاداء '!AN39+'تحليل الاداء '!AN39+'تحليل الاداء'!AN39 -> 29
B40: سيد على | AV40: =AT40+AE40+Z40+U40+P40+K40+F40 -> 0 | AW40: =AU40+AG40+AA40+V40+Q40+L40+G40 -> 0 | AX40: =AV40+'تحليل الاداء '!AM40+'تحليل الاداء '!AM40+'تحليل الاداء'!AM40 -> 6 | AY40: =AW40+'تحليل الاداء '!AN40+'تحليل الاداء '!AN40+'تحليل الاداء'!AN40 -> 6
...
