Workbook

Sheet داتا
A1: شيت دخول وخروج السيارات ايتوال عن يوم الخميس الموافق 19/2/2026
A2: م | B2: رقم السيارة | C2: نوع السيارة | D2: الزمن المعيارى للتحميل | E2: اسم الفرع | F2: اسم السائق | G2: وقت الحضور المقرر | H2: الحضور فعلى | I2: مدة التأخير | J2: دخول الكيدج | K2: نزول من الكيدج | L2: أخصائى الدفترى | M2: أخصائى السيستم | N2: مدة التحميل | O2: مدة انحراف التحميل | P2: الزمن المعيارى لنزول الاذن | Q2: وقت نزول الاذن | R2: مدة انحراف نزول الاذن | S2: خروج من المصنع | T2: الزمن المعيارى لدخول الفرع | U2: دخول الفرع | V2: مدة انحراف دخول الفرع | W2: الزمن المعيارى لنزول المنتجات | X2: فتح السياره | Y2: غلق السياره | Z2: الوقت المستغرق | AA2: مدة انحراف نزول المنتجات فى الفرع | AB2: خروج من الفرع | AC2: ملاحظات
A3: 1 | B3: 2695 | C3: =VLOOKUP(B3,'[1]21-1-2026'!$B$3:$T$35,2,) -> تلتين | D3: =VLOOKUP(B3,'[1]21-1-2026'!$B$3:$T$35,3,) -> 0.03125 | E3: النزهة | F3: وائل علي | G3: 0.25 | H3: 0.25 | I3: =H3-G3 -> 0 | J3: 0.19791667 | K3: 0.25 | L3: احمد عبد الجواد | M3: احمد عبد الجواد | N3: =K3-J3 -> 0.052083333 | O3: =N3-D3 -> 0.020833333 | P3: 0.0069444444 | Q3: 0.25 | R3: 0 | S3: 0.28819444 | T3: =VLOOKUP(E3,'[1]21-1-2026'!$E$3:$T$35,16,FALSE) -> 0.013888889 | U3: 0.30555556 | V3: =U3-T3-S3 -> 0.0034722222 | W3: 0.03125 | X3: 0.30902778 | Y3: 0.32291667 | Z3: =Y3-X3 -> 0.013888889 | AA3: 0 | AB3: 0.32291667 | AD3: رحلة اولى ( شرقى ومخبوزات وغربى )
A4: 2 | B4: 2695 | C4: =VLOOKUP(B4,'[1]21-1-2026'!$B$3:$T$35,2,) -> تلتين | D4: =VLOOKUP(B4,'[1]21-1-2026'!$B$3:$T$35,3,) -> 0.03125 | E4: الجسر | F4: وائل علي | G4: 0.25 | H4: 0.25 | I4: =H4-G4 -> 0 | J4: 0.19791667 | K4: 0.25 | L4: احمد عبد الجواد | M4: احمد عبد الجواد | N4: =K4-J4 -> 0.052083333 | O4: =N4-D4 -> 0.020833333 | P4: 0.0069444444 | Q4: 0.25 | R4: 0 | S4: 0.28819444 | T4: =VLOOKUP(E4,'[1]21-1-2026'!$E$3:$T$35,16,FALSE) -> 0.010416667 | U4: 0.32708333 | V4: 0 | W4: 0.041666667 | X4: 0.33333333 | Y4: 0.375 | Z4: =Y4-X4 -> 0.041666667 | AA4: =Z4-W4 -> 0 | AB4: 0.38194444
A5: 3 | B5: 2917 | C5: =VLOOKUP(B5,'[1]21-1-2026'!$B$3:$T$35,2,) -> تلتين | D5: =VLOOKUP(B5,'[1]21-1-2026'!$B$3:$T$35,3,) -> 0.03125 | E5: المعادي 2 | F5: رجب محمد | G5: 0.25 | H5: 0.25347222 | I5: =H5-G5 -> 0.0034722222 | J5: 0.20833333 | K5: 0.27777778 | L5: محمد هشام | M5: محمد هشام | N5: =K5-J5 -> 0.069444444 | O5: =N5-D5 -> 0.038194444 | P5: 0.0069444444 | Q5: 0.27777778 | R5: 0 | S5: 0.28819444 | T5: =VLOOKUP(E5,'[1]21-1-2026'!$E$3:$T$35,16,FALSE) -> 0.034722222 | U5: 0.32986111 | V5: =U5-T5-S5 -> 0.0069444444 | W5: 0.03125 | X5: 0.34027778 | Y5: 0.37152778 | Z5: =Y5-X5 -> 0.03125 | AA5: =Z5-W5 -> 0 | AB5: 0.375
A6: 4 | B6: 2917 | C6: =VLOOKUP(B6,'[1]21-1-2026'!$B$3:$T$35,2,) -> تلتين | D6: =VLOOKUP(B6,'[1]21-1-2026'!$B$3:$T$35,3,) -> 0.03125 | E6: العاشر | F6: رجب محمد | G6: 0.25 | H6: 0.25347222 | I6: =H6-G6 -> 0.0034722222 | J6: 0.20833333 | K6: 0.27777778 | L6: محمد هشام | M6: محمد هشام | N6: =K6-J6 -> 0.069444444 | O6: 0 | P6: 0.0069444444 | Q6: 0.27777778 | R6: 0 | S6: 0.28819444 | T6: 0.010416667 | U6: 0.40138889 | V6: =U6-T6-S6 -> 0.10277778 | W6: 0.041666667 | X6: 0.40625 | Y6: 0.45833333 | Z6: =Y6-X6 -> 0.052083333 | AA6: =Z6-W6 -> 0.010416667 | AB6: 0.46180556
A7: 5 | B7: 459 | C7: =VLOOKUP(B7,'[1]21-1-2026'!$B$3:$T$35,2,) -> دبابة | D7: =VLOOKUP(B7,'[1]21-1-2026'!$B$3:$T$35,3,) -> 0.020833333 | E7: الوسط | F7: علي عادل | G7: 0.25 | H7: 0.25 | I7: =H7-G7 -> 0 | J7: 0.20833333 | K7: 0.22569444 | L7: باسم خالد | M7: باسم خالد | N7: =K7-J7 -> 0.017361111 | O7: 0 | P7: 0.0069444444 | Q7: 0.22569444 | R7: 0 | S7: 0.29513889 | T7: =VLOOKUP(E7,'[1]21-1-2026'!$E$3:$T$35,16,FALSE) -> 0.017361111 | U7: 0.31944444 | V7: =U7-T7-S7 -> 0.0069444444 | W7: 0.03125 | X7: 0.32291667 | Y7: 0.34583333 | Z7: =Y7-X7 -> 0.022916667 | AA7: 0 | AB7: 0.34722222
A8: 6 | B8: 1454 | C8: =VLOOKUP(B8,'[1]21-1-2026'!$B$3:$T$35,2,) -> تلتين | D8: =VLOOKUP(B8,'[1]21-1-2026'!$B$3:$T$35,3,) -> 0.03125 | E8: عرابي | F8: احمد فوزي | G8: 0.25 | H8: 0.25 | I8: =H8-G8 -> 0 | J8: 0.22569444 | K8: 0.25694444 | L8: عبد الله امير | M8: عبد الله امير | N8: =K8-J8 -> 0.03125 | O8: 0 | P8: 0.0069444444 | Q8: 0.25694444 | R8: 0 | S8: 0.29861111 | T8: =VLOOKUP(E8,'[1]21-1-2026'!$E$3:$T$35,16,FALSE) -> 0.017361111 | U8: 0.31875 | V8: =U8-T8-S8 -> 0.0027777778 | W8: 0.03125 | X8: 0.33888889 | Y8: 0.37152778 | Z8: =Y8-X8 -> 0.032638889 | AA8: =Z8-W8 -> 0.0013888889 | AB8: 0.37361111
A9: 7 | B9: 1454 | C9: =VLOOKUP(B9,'[1]21-1-2026'!$B$3:$T$35,2,) -> تلتين | D9: =VLOOKUP(B9,'[1]21-1-2026'!$B$3:$T$35,3,) -> 0.03125 | E9: الدقي | F9: احمد فوزي | G9: 0.25 | H9: 0.25 | I9: =H9-G9 -> 0 | J9: 0.22569444 | K9: 0.25694444 | L9: عبد الله امير | M9: عبد الله امير | N9: =K9-J9 -> 0.03125 | O9: 0 | P9: 0.0069444444 | Q9: 0.25694444 | R9: 0 | S9: 0.29861111 | T9: =VLOOKUP(E9,'[1]21-1-2026'!$E$3:$T$35,16,FALSE) -> 0.013888889 | U9: 0.37847222 | V9: =U9-T9-S9 -> 0.065972222 | W9: 0.041666667 | X9: 0.38194444 | Y9: 0.43194444 | Z9: =Y9-X9 -> 0.05 | AA9: =Z9-W9 -> 0.0083333333 | AB9: 0.43402778
A10: 8 | B10: 7464 | C10: =VLOOKUP(B10,'[1]21-1-2026'!$B$3:$T$35,2,) -> تلتين | D10: =VLOOKUP(B10,'[1]21-1-2026'!$B$3:$T$35,3,) -> 0.03125 | E10: فيصل | F10: عمرو محمد | G10: 0.25 | H10: 0.25 | I10: =H10-G10 -> 0 | J10: 0.19444444 | K10: 0.22569444 | L10: محمد صلاح | M10: محمد صلاح | N10: =K10-J10 -> 0.03125 | O10: 0 | P10: 0.0069444444 | Q10: 0.22569444 | R10: 0 | S10: 0.29166667 | T10: =VLOOKUP(E10,'[1]21-1-2026'!$E$3:$T$35,16,FALSE) -> 0.034722222 | U10: 0.33333333 | V10: =U10-T10-S10 -> 0.0069444444 | W10: 0.03125 | X10: 0.33680556 | Y10: 0.38888889 | Z10: =Y10-X10 -> 0.052083333 | AA10: =Z10-W10 -> 0.020833333 | AB10: 0.39236111
A11: 9 | B11: 7464 | C11: =VLOOKUP(B11,'[1]21-1-2026'!$B$3:$T$35,2,) -> تلتين | D11: =VLOOKUP(B11,'[1]21-1-2026'!$B$3:$T$35,3,) -> 0.03125 | E11: الطوابق | F11: عمرو محمد | G11: 0.25 | H11: 0.25 | I11: =H11-G11 -> 0 | J11: 0.19444444 | K11: 0.22569444 | L11: محمد صلاح | M11: محمد صلاح | N11: =K11-J11 -> 0.03125 | O11: =N11-D11 -> 0 | P11: 0.0069444444 | Q11: 0.22569444 | R11: 0 | S11: 0.29166667 | T11: =VLOOKUP(E11,'[1]21-1-2026'!$E$3:$T$35,16,FALSE) -> 0.034722222 | U11: 0.39930556 | V11: =U11-T11-S11 -> 0.072916667 | W11: 0.041666667 | X11: 0.40277778 | Y11: 0.45 | Z11: =Y11-X11 -> 0.047222222 | AA11: =Z11-W11 -> 0.0055555556 | AB11: 0.45486111
A12: 10 | B12: 6231 | C12: خارجية | D12: 0.0625 | E12: التجمع 1 | F12: سمير جمال | G12: 0.25 | H12: 0.25 | I12: =H12-G12 -> 0 | J12: 0.21527778 | K12: 0.28125 | L12: احمد خيري | M12: احمد خيري | N12: =K12-J12 -> 0.065972222 | O12: =N12-D12 -> 0.0034722222 | P12: 0.0069444444 | Q12: 0.28125 | R12: 0 | S12: 0.29166667 | T12: =VLOOKUP(E12,'[1]21-1-2026'!$E$3:$T$35,16,FALSE) -> 0.024305556 | U12: 0 | V12: 0 | W12: 0.041666667 | X12: 0 | Y12: 0 | Z12: =Y12-X12 -> 0 | AA12: 0 | AB12: 0
A13: 11 | B13: 6231 | C13: خارجية | D13: 0.0625 | E13: التجمع 5 | F13: سمير جمال | G13: 0.25 | H13: 0.25 | I13: =H13-G13 -> 0 | J13: 0.21527778 | K13: 0.28125 | L13: احمد خيري | M13: احمد خيري | N13: =K13-J13 -> 0.065972222 | O13: =N13-D13 -> 0.0034722222 | P13: 0.0069444444 | Q13: 0.28125 | R13: 0 | S13: 0.29166667 | T13: =VLOOKUP(E13,'[1]21-1-2026'!$E$3:$T$35,16,FALSE) -> 0.010416667 | U13: 0.40625 | V13: =U13-T13-S13 -> 0.10416667 | W13: 0.0625 | X13: 0.40972222 | Y13: 0.44097222 | Z13: =Y13-X13 -> 0.03125 | AA13: 0 | AB13: 0.44444444
A14: 12 | B14: 586 | C14: =VLOOKUP(B14,'[1]21-1-2026'!$B$3:$T$35,2,) -> سوزوكي | D14: =VLOOKUP(B14,'[1]21-1-2026'!$B$3:$T$35,3,) -> 0.020833333 | E14: الشروق 3 | F14: محمود عبد الفتاح | G14: 0.25 | H14: 0.25 | I14: =H14-G14 -> 0 | J14: 0.23958333 | K14: 0.25694444 | L14: باسم خالد | M14: باسم خالد | N14: =K14-J14 -> 0.017361111 | O14: 0 | P14: 0.0069444444 | Q14: 0.25694444 | R14: 0 | S14: 0.29861111 | T14: =VLOOKUP(E14,'[1]21-1-2026'!$E$3:$T$35,16,FALSE) -> 0.038194444 | U14: 0.35069444 | V14: =U14-T14-S14 -> 0.013888889 | W14: 0.03125 | X14: 0.35416667 | Y14: 0.38194444 | Z14: =Y14-X14 -> 0.027777778 | AA14: 0 | AB14: 0.45138889
A15: 13 | B15: 3495 | C15: =VLOOKUP(B15,'[1]21-1-2026'!$B$3:$T$35,2,) -> تلتين | D15: =VLOOKUP(B15,'[1]21-1-2026'!$B$3:$T$35,3,) -> 0.03125 | E15: مكرم | F15: محد صلاح | G15: 0.25 | H15: 0.25694444 | I15: =H15-G15 -> 0.0069444444 | J15: 0.23263889 | K15: 0.25 | L15: احمد عبد العزيز | M15: احمد عبد العزيز | N15: =K15-J15 -> 0.017361111 | O15: 0 | P15: 0.0069444444 | Q15: 0.25 | R15: 0 | S15: 0.29166667 | T15: =VLOOKUP(E15,'[1]21-1-2026'!$E$3:$T$35,16,FALSE) -> 0.017361111 | U15: 0.31597222 | V15: =U15-T15-S15 -> 0.0069444444 | W15: 0.03125 | X15: 0.31944444 | Y15: 0.36458333 | Z15: =Y15-X15 -> 0.045138889 | AA15: =Z15-W15 -> 0.013888889 | AB15: 0.36805556
A16: 14 | B16: 3495 | C16: =VLOOKUP(B16,'[1]21-1-2026'!$B$3:$T$35,2,) -> تلتين | D16: =VLOOKUP(B16,'[1]21-1-2026'!$B$3:$T$35,3,) -> 0.03125 | E16: جاردينيا | F16: محمد صلاح | G16: 0.25 | H16: 0.25694444 | I16: =H16-G16 -> 0.0069444444 | J16: 0.23263889 | K16: 0.25 | L16: احمد عبد العزيز | M16: احمد عبد العزيز | N16: =K16-J16 -> 0.017361111 | O16: 0 | P16: 0.0069444444 | Q16: 0.25 | R16: 0 | S16: 0.29166667 | T16: =VLOOKUP(E16,'[1]21-1-2026'!$E$3:$T$35,16,FALSE) -> 0.010416667 | U16: 0.37847222 | V16: =U16-T16-S16 -> 0.076388889 | W16: 0.041666667 | X16: 0.38194444 | Y16: 0.40625 | Z16: =Y16-X16 -> 0.024305556 | AA16: 0 | AB16: 0.41319444
A17: 15 | B17: 1538 | C17: =VLOOKUP(B17,'[1]21-1-2026'!$B$3:$T$35,2,) -> تلتين | D17: =VLOOKUP(B17,'[1]21-1-2026'!$B$3:$T$35,3,) -> 0.03125 | E17: الشروق | F17: احمد حسن | G17: 0.25 | H17: 0.25 | I17: =H17-G17 -> 0 | J17: 0.27083333 | K17: 0.29861111 | L17: باسم خالد | M17: باسم خالد | N17: =K17-J17 -> 0.027777778 | O17: 0 | P17: 0.0069444444 | Q17: 0.29861111 | R17: 0 | S17: 0.30902778 | T17: =VLOOKUP(E17,'[1]21-1-2026'!$E$3:$T$35,16,FALSE) -> 0.034722222 | U17: 0.35416667 | V17: =U17-T17-S17 -> 0.010416667 | W17: 0.03125 | X17: 0.35763889 | Y17: 0.38888889 | Z17: =Y17-X17 -> 0.03125 | AA17: =Z17-W17 -> 0 | AB17: 0.39236111
A18: 16 | B18: 1538 | C18: =VLOOKUP(B18,'[1]21-1-2026'!$B$3:$T$35,2,) -> تلتين | D18: =VLOOKUP(B18,'[1]21-1-2026'!$B$3:$T$35,3,) -> 0.03125 | E18: الشروق 3 | F18: احمد حسن | G18: 0.25 | H18: 0.25 | I18: =H18-G18 -> 0 | J18: 0.27083333 | K18: 0.29861111 | L18: باسم خالد | M18: باسم خالد | N18: =K18-J18 -> 0.027777778 | O18: 0 | P18: 0.0069444444 | Q18: 0.29861111 | R18: 0 | S18: 0.30902778 | T18: =VLOOKUP(E18,'[1]21-1-2026'!$E$3:$T$35,16,FALSE) -> 0.038194444 | U18: 0.40625 | V18: =U18-T18-S18 -> 0.059027778 | W18: 0.041666667 | X18: 0.40972222 | Y18: 0.42708333 | Z18: =Y18-X18 -> 0.017361111 | AA18: 0 | AB18: 0.45138889
A19: 17 | B19: 3492 | C19: =VLOOKUP(B19,'[1]21-1-2026'!$B$3:$T$35,2,) -> تلتين | D19: =VLOOKUP(B19,'[1]21-1-2026'!$B$3:$T$35,3,) -> 0.03125 | E19: العاشر من رمضان | F19: محمود عادل | G19: 0.25 | H19: 0.25 | I19: =H19-G19 -> 0 | J19: 0.25694444 | K19: 0.29166667 | L19: احمد عبد العزيز | M19: احمد عبد العزيز | N19: =K19-J19 -> 0.034722222 | O19: =N19-D19 -> 0.0034722222 | P19: 0.0069444444 | Q19: 0.29166667 | R19: 0 | S19: 0.31597222 | T19: =VLOOKUP(E19,'[1]21-1-2026'!$E$3:$T$35,16,FALSE) -> 0.0625 | U19: 0.37152778 | V19: 0 | W19: 0.041666667 | X19: 0.375 | Y19: 0.41527778 | Z19: =Y19-X19 -> 0.040277778 | AA19: 0 | AB19: 0.42361111
A20: 18 | B20: 3891 | C20: =VLOOKUP(B20,'[1]21-1-2026'!$B$3:$T$35,2,) -> تلتين | D20: =VLOOKUP(B20,'[1]21-1-2026'!$B$3:$T$35,3,) -> 0.03125 | E20: اكتوبر | F20: علاء مجدي | G20: 0.25 | H20: 0.25 | I20: =H20-G20 -> 0 | J20: 0.28125 | K20: 0.30555556 | L20: احمد عبد الجواد | M20: احمد عبد الجواد | N20: =K20-J20 -> 0.024305556 | O20: 0 | P20: 0.0069444444 | Q20: 0.30555556 | R20: 0 | S20: 0.31597222 | T20: =VLOOKUP(E20,'[1]21-1-2026'!$E$3:$T$35,16,FALSE) -> 0.041666667 | U20: 0.36111111 | V20: =U20-T20-S20 -> 0.0034722222 | W20: 0.041666667 | X20: 0.36458333 | Y20: 0.40972222 | Z20: =Y20-X20 -> 0.045138889 | AA20: =Z20-W20 -> 0.0034722222 | AB20: 0.41319444
A21: 19 | B21: 5898 | C21: =VLOOKUP(B21,'[1]21-1-2026'!$B$3:$T$35,2,) -> تلتين | D21: =VLOOKUP(B21,'[1]21-1-2026'!$B$3:$T$35,3,) -> 0.03125 | E21: عباس | F21: طه محسن | G21: 0.25 | H21: 0.25 | I21: =H21-G21 -> 0 | J21: 0.22916667 | K21: 0.26041667 | L21: محمد صلاح | M21: محمد صلاح | N21: =K21-J21 -> 0.03125 | O21: =N21-D21 -> 0 | P21: 0.0069444444 | Q21: 0.26041667 | R21: 0 | S21: 0.32291667 | T21: =VLOOKUP(E21,'[1]21-1-2026'!$E$3:$T$35,16,FALSE) -> 0.017361111 | U21: 0.33333333 | V21: 0 | W21: 0.03125 | X21: 0.34027778 | Y21: 0.36805556 | Z21: =Y21-X21 -> 0.027777778 | AA21: 0 | AB21: 0.37152778
A22: 20 | B22: 5898 | C22: =VLOOKUP(B22,'[1]21-1-2026'!$B$3:$T$35,2,) -> تلتين | D22: =VLOOKUP(B22,'[1]21-1-2026'!$B$3:$T$35,3,) -> 0.03125 | E22: الميرغني | F22: طه محسن | G22: 0.25 | H22: 0.25 | I22: =H22-G22 -> 0 | J22: 0.22916667 | K22: 0.26041667 | L22: محمد صلاح | M22: محمد صلاح | N22: =K22-J22 -> 0.03125 | O22: =N22-D22 -> 0 | P22: 0.0069444444 | Q22: 0.26041667 | R22: 0 | S22: 0.32291667 | T22: =VLOOKUP(E22,'[1]21-1-2026'!$E$3:$T$35,16,FALSE) -> 0.013888889 | U22: 0.37847222 | V22: =U22-T22-S22 -> 0.041666667 | W22: 0.041666667 | X22: 0.38055556 | Y22: 0.42361111 | Z22: =Y22-X22 -> 0.043055556 | AA22: =Z22-W22 -> 0.0013888889 | AB22: 0.42708333
A23: 21 | B23: 4987 | C23: =VLOOKUP(B23,'[1]21-1-2026'!$B$3:$T$35,2,) -> تلتين | D23: =VLOOKUP(B23,'[1]21-1-2026'!$B$3:$T$35,3,) -> 0.03125 | E23: الوايلي | F23: علي حمدي | G23: 0.25 | H23: 0.25 | I23: =H23-G23 -> 0 | J23: 0.27777778 | K23: 0.30902778 | L23: عبد الله امير | M23: عبد الله امير | N23: =K23-J23 -> 0.03125 | O23: =N23-D23 -> 0 | P23: 0.0069444444 | Q23: 0.30902778 | R23: 0 | S23: 0.31944444 | T23: =VLOOKUP(E23,'[1]21-1-2026'!$E$3:$T$35,16,FALSE) -> 0.010416667 | U23: 0.33333333 | V23: =U23-T23-S23 -> 0.0034722222 | W23: 0.03125 | X23: 0.33888889 | Y23: 0.38055556 | Z23: =Y23-X23 -> 0.041666667 | AA23: =Z23-W23 -> 0.010416667 | AB23: 0.38125
A24: 22 | B24: 4987 | C24: =VLOOKUP(B24,'[1]21-1-2026'!$B$3:$T$35,2,) -> تلتين | D24: =VLOOKUP(B24,'[1]21-1-2026'!$B$3:$T$35,3,) -> 0.03125 | E24: المنتزة | F24: علي حمدي | G24: 0.25 | H24: 0.25 | I24: =H24-G24 -> 0 | J24: 0.27777778 | K24: 0.30902778 | L24: عبد الله امير | M24: عبد الله امير | N24: =K24-J24 -> 0.03125 | O24: =N24-D24 -> 0 | P24: 0.0069444444 | Q24: 0.30902778 | R24: 0 | S24: 0.31944444 | T24: =VLOOKUP(E24,'[1]21-1-2026'!$E$3:$T$35,16,FALSE) -> 0.010416667 | U24: 0.38888889 | V24: =U24-T24-S24 -> 0.059027778 | W24: 0.041666667 | X24: 0.39236111 | Y24: 0.41666667 | Z24: =Y24-X24 -> 0.024305556 | AA24: 0 | AB24: 0.42361111
A25: 23 | B25: 7435 | C25: =VLOOKUP(B25,'[1]21-1-2026'!$B$3:$T$35,2,) -> تلتين | D25: =VLOOKUP(B25,'[1]21-1-2026'!$B$3:$T$35,3,) -> 0.03125 | E25: المعادي 1 | F25: محمود ابو طالب | G25: 0.25 | H25: 0.25 | I25: =H25-G25 -> 0 | J25: 0.28472222 | K25: 0.31597222 | L25: محمد هشام | M25: محمد هشام | N25: =K25-J25 -> 0.03125 | O25: =N25-D25 -> 0 | P25: 0.0069444444 | Q25: 0.31597222 | R25: 0 | S25: 0.32638889 | T25: =VLOOKUP(E25,'[1]21-1-2026'!$E$3:$T$35,16,FALSE) -> 0.034722222 | U25: 0.35763889 | V25: 0 | W25: 0.041666667 | X25: 0.36111111 | Y25: 0.40277778 | Z25: =Y25-X25 -> 0.041666667 | AA25: =Z25-W25 -> 0 | AB25: 0.40625
A26: 24 | B26: 3783 | C26: =VLOOKUP(B26,'[1]21-1-2026'!$B$3:$T$35,2,) -> دبابة | D26: =VLOOKUP(B26,'[1]21-1-2026'!$B$3:$T$35,3,) -> 0.020833333 | E26: الشيراتون | F26: الشناوي سرور | G26: 0.25 | H26: 0.26041667 | I26: =H26-G26 -> 0.010416667 | J26: 0.3125 | K26: 0.32638889 | L26: باسم خالد | M26: باسم خالد | N26: =K26-J26 -> 0.013888889 | O26: 0 | P26: 0.0069444444 | Q26: 0.32638889 | R26: 0 | S26: 0.34375 | T26: =VLOOKUP(E26,'[1]21-1-2026'!$E$3:$T$35,16,FALSE) -> 0.020833333 | U26: 0.36180556 | V26: 0 | W26: 0.03125 | X26: 0.36458333 | Y26: 0.39583333 | Z26: =Y26-X26 -> 0.03125 | AA26: =Z26-W26 -> 0 | AB26: 0.39930556
A27: 25 | B27: 796 | C27: =VLOOKUP(B27,'[1]21-1-2026'!$B$3:$T$35,2,) -> دبابة | D27: =VLOOKUP(B27,'[1]21-1-2026'!$B$3:$T$35,3,) -> 0.020833333 | E27: الدوران | F27: عمرو عبد الرحمن | G27: 0.25 | H27: 0.25 | I27: =H27-G27 -> 0 | J27: 0.3125 | K27: 0.33333333 | L27: احمد عبد الجواد | M27: احمد عبد الجواد | N27: =K27-J27 -> 0.020833333 | O27: =N27-D27 -> 0 | P27: 0.0069444444 | Q27: 0.33333333 | R27: 0 | S27: 0.34375 | T27: =VLOOKUP(E27,'[1]21-1-2026'!$E$3:$T$35,16,FALSE) -> 0.013888889 | U27: 0.35069444 | V27: 0 | W27: 0.03125 | X27: 0.35972222 | Y27: 0.38541667 | Z27: =Y27-X27 -> 0.025694444 | AA27: 0 | AB27: 0.38888889
A28: 26 | B28: 4879 | C28: =VLOOKUP(B28,'[1]21-1-2026'!$B$3:$T$35,2,) -> دبابة | D28: =VLOOKUP(B28,'[1]21-1-2026'!$B$3:$T$35,3,) -> 0.020833333 | E28: العباسية | F28: جمال فؤاد | G28: 0.25 | H28: 0.25 | I28: =H28-G28 -> 0 | J28: 0.29861111 | K28: 0.3125 | L28: احمد عبد العزيز | M28: احمد عبد العزيز | N28: =K28-J28 -> 0.013888889 | O28: 0 | P28: 0.0069444444 | Q28: 0.3125 | R28: 0 | S28: 0.35069444 | T28: =VLOOKUP(E28,'[1]21-1-2026'!$E$3:$T$35,16,FALSE) -> 0.020833333 | U28: 0.37152778 | V28: =U28-T28-S28 -> 0 | W28: 0.03125 | X28: 0.375 | Y28: 0.41666667 | Z28: =Y28-X28 -> 0.041666667 | AA28: =Z28-W28 -> 0.010416667 | AB28: 0.42708333
A29: 27 | B29: 3787 | C29: =VLOOKUP(B29,'[1]21-1-2026'!$B$3:$T$35,2,) -> دبابة | D29: =VLOOKUP(B29,'[1]21-1-2026'!$B$3:$T$35,3,) -> 0.020833333 | E29: العبور | F29: صبري إمام | G29: 0.25 | H29: 0.25 | I29: =H29-G29 -> 0 | J29: 0.29861111 | K29: 0.33680556 | L29: احمد خيري | M29: احمد خيري | N29: =K29-J29 -> 0.038194444 | O29: =N29-D29 -> 0.017361111 | P29: 0.0069444444 | Q29: 0.33680556 | R29: 0 | S29: 0.35069444 | T29: =VLOOKUP(E29,'[1]21-1-2026'!$E$3:$T$35,16,FALSE) -> 0.027777778 | U29: 0.37986111 | V29: =U29-T29-S29 -> 0.0013888889 | W29: 0.03125 | X29: 0.38333333 | Y29: 0.42638889 | Z29: =Y29-X29 -> 0.043055556 | AA29: =Z29-W29 -> 0.011805556 | AB29: 0.42708333
A30: 28 | B30: 8527 | C30: خارجية | D30: 0.0625 | E30: شبرا | F30: سائق خارجي | G30: 0.25 | H30: 0.25 | I30: =H30-G30 -> 0 | J30: 0.31597222 | K30: 0.39583333 | L30: حسام خليل | M30: حسام خليل | N30: =K30-J30 -> 0.079861111 | O30: =N30-D30 -> 0.017361111 | P30: 0.0069444444 | Q30: 0.39583333 | R30: 0 | S30: 0.39930556 | T30: =VLOOKUP(E30,'[1]21-1-2026'!$E$3:$T$35,16,FALSE) -> 0.013888889 | U30: 0 | V30: 0 | W30: 0.041666667 | X30: 0 | Y30: 0 | Z30: 0 | AA30: 0 | AB30: 0
A31: 29 | B31: 9652 | C31: خارجية | D31: 0.0625 | E31: مسطرد | F31: محمود عيد | G31: 0.25 | H31: 0.25 | I31: =H31-G31 -> 0 | J31: 0.34375 | K31: 0.39930556 | L31: محمد فؤاد | M31: محمد فؤاد | N31: =K31-J31 -> 0.055555556 | O31: 0 | P31: 0.0069444444 | Q31: 0.39930556 | R31: 0 | S31: 0.40277778 | T31: =VLOOKUP(E31,'[1]21-1-2026'!$E$3:$T$35,16,FALSE) -> 0.0034722222 | U31: 0 | V31: 0 | W31: 0.0625 | X31: 0 | Y31: 0 | Z31: =Y31-X31 -> 0 | AA31: 0 | AB31: 0
A32: 30 | B32: 634 | C32: =VLOOKUP(B32,'[1]21-1-2026'!$B$3:$T$35,2,) -> دبابة | D32: =VLOOKUP(B32,'[1]21-1-2026'!$B$3:$T$35,3,) -> 0.020833333 | E32: الشريف | F32: احمد عواد | G32: 0.25 | H32: 0.25 | I32: =H32-G32 -> 0 | J32: 0.31597222 | K32: 0.36458333 | L32: محمد دسوقي | M32: محمد دسوقي | N32: =K32-J32 -> 0.048611111 | O32: =N32-D32 -> 0.027777778 | P32: 0.0069444444 | Q32: 0.36458333 | R32: 0 | S32: 0.37152778 | T32: =VLOOKUP(E32,'[1]21-1-2026'!$E$3:$T$35,16,FALSE) -> 0.017361111 | U32: 0.39166667 | V32: =U32-T32-S32 -> 0.0027777778 | W32: 0.03125 | X32: 0.39513889 | Y32: 0.44166667 | Z32: =Y32-X32 -> 0.046527778 | AA32: =Z32-W32 -> 0.015277778 | AB32: 0.44236111
A33: 31 | B33: 3793 | C33: =VLOOKUP(B33,'[1]21-1-2026'!$B$3:$T$35,2,) -> دبابة | D33: =VLOOKUP(B33,'[1]21-1-2026'!$B$3:$T$35,3,) -> 0.020833333 | E33: الكوربة | F33: محمد مراد | G33: 0.25 | H33: 0.25 | I33: =H33-G33 -> 0 | J33: 0.31597222 | K33: 0.37152778 | L33: احمد فايز | M33: احمد فايز | N33: =K33-J33 -> 0.055555556 | O33: =N33-D33 -> 0.034722222 | P33: 0.0069444444 | Q33: 0.37152778 | R33: 0 | S33: 0.38194444 | T33: =VLOOKUP(E33,'[1]21-1-2026'!$E$3:$T$35,16,FALSE) -> 0.013888889 | U33: 0.39930556 | V33: =U33-T33-S33 -> 0.0034722222 | W33: 0.03125 | X33: 0.40208333 | Y33: 0.4375 | Z33: =Y33-X33 -> 0.035416667 | AA33: =Z33-W33 -> 0.0041666667 | AB33: 0.43888889
A34: 32 | B34: 714 | C34: خارجية | D34: 0.0625 | E34: السواح | F34: عبد العظيم رمضان | G34: 0.25 | H34: 0.25 | I34: =H34-G34 -> 0 | J34: 0.34375 | K34: 0.40625 | L34: محمد عادل | M34: محمد عادل | N34: =K34-J34 -> 0.0625 | O34: =N34-D34 -> 0 | P34: 0.0069444444 | Q34: 0.40625 | R34: 0 | S34: 0.42013889 | T34: =VLOOKUP(E34,'[1]21-1-2026'!$E$3:$T$35,16,FALSE) -> 0.010416667 | U34: 0.43055556 | V34: =U34-T34-S34 -> 0 | W34: 0.0625 | X34: 0.43402778 | Y34: 0.46875 | Z34: =Y34-X34 -> 0.034722222 | AA34: 0 | AB34: 0.47222222
A35: 33 | B35: 2714 | C35: =VLOOKUP(B35,'[1]21-1-2026'!$B$3:$T$35,2,) -> تلتين | D35: =VLOOKUP(B35,'[1]21-1-2026'!$B$3:$T$35,3,) -> 0.03125 | E35: المطرية | F35: جمعة السيد | G35: 0.25 | H35: 0.25 | I35: =H35-G35 -> 0 | J35: 0.36458333 | K35: 0.39236111 | L35: عبد الرحمن ابراهيم | M35: عبد الرحمن ابراهيم | N35: =K35-J35 -> 0.027777778 | O35: 0 | P35: 0.0069444444 | Q35: 0.39236111 | R35: 0 | S35: 0.39583333 | T35: =VLOOKUP(E35,'[1]21-1-2026'!$E$3:$T$35,16,FALSE) -> 0.0048611111 | U35: 0.40972222 | V35: =U35-T35-S35 -> 0.0090277778 | W35: 0.03125 | X35: 0.41319444 | Y35: 0.44930556 | Z35: =Y35-X35 -> 0.036111111 | AA35: =Z35-W35 -> 0.0048611111 | AB35: 0.45138889
B36: 2474 | C36: =VLOOKUP(B36,'[1]21-1-2026'!$B$3:$T$35,2,) -> دبابة | D36: 0.020833333
B37: 6143 | C37: تلتين | D37: 0.03125
B38: 6142 | C38: تلتين | D38: 0.03125
B39: 2694 | C39: =VLOOKUP(B39,'[1]21-1-2026'!$B$3:$T$35,2,) -> تلتين | D39: 0.03125
A40: 1 | B40: 1231 | C40: خارجية | D40: 0.041666667 | E40: الدقي | F40: محمود سعيد | G40: 0.25 | H40: 0.25 | I40: =H40-G40 -> 0 | J40: 0.38194444 | K40: 0.4375 | L40: محمد دسوقي | M40: محمد دسوقي | N40: =K40-J40 -> 0.055555556 | O40: =N40-D40 -> 0.013888889 | P40: 0.0069444444 | Q40: 0.4375 | R40: 0 | S40: 0.45138889 | T40: =VLOOKUP(E40,'[1]21-1-2026'!$E$36:$T$67,16,FALSE) -> 0.013888889 | U40: 0 | V40: 0 | W40: 0.03125 | X40: 0 | Y40: 0 | Z40: =Y40-X40 -> 0 | AA40: 0 | AB40: 0 | AD40: رحلة ثانية ( شرقى وغربى ومخبوزات )
...

Sheet 21-4-2026
A1: شيت دخول وخروج السيارات ايتوال عن يوم الثلاثاء الموافق 21/4/2026
A2: م | B2: رقم السيارة | C2: نوع السيارة | D2: الزمن المعيارى للتحميل | E2: اسم الفرع | F2: اسم السائق | G2: وقت الحضور المقرر | H2: الحضور فعلى | I2: مدة التأخير | J2: دخول الكيدج | K2: نزول من الكيدج | L2: أخصائى الدفترى | M2: أخصائى السيستم | N2: مدة التحميل | O2: مدة انحراف التحميل | P2: الزمن المعيارى لنزول الاذن | Q2: وقت نزول الاذن | R2: مدة انحراف نزول الاذن | S2: خروج من المصنع | T2: الزمن المعيارى لدخول الفرع | U2: دخول الفرع | V2: مدة انحراف دخول الفرع | W2: الزمن المعيارى لنزول المنتجات | X2: فتح السياره | Y2: غلق السياره | Z2: الوقت المستغرق | AA2: مدة انحراف نزول المنتجات فى الفرع | AB2: خروج من الفرع | AC2: ملاحظات
A3: 1 | B3: 4987 | C3: =VLOOKUP(B3,داتا!$B$3:$D$107,2,FALSE) -> تلتين | D3: =VLOOKUP(B3,داتا!$B$3:$D$107,3,FALSE) -> 0.03125 | E3: النزهة | F3: عمرو المهدي | G3: 0.25 | H3: 0.23958333 | I3: 0 | J3: 0.18402778 | K3: 0.20138889 | L3: عبدالرحمن هشام | M3: عبدالرحمن هشام | N3: =K3-J3 -> 0.017361111 | O3: 0 | P3: 0.0069444444 | Q3: 0.21180556 | R3: =Q3-P3-K3 -> 0.0034722222 | S3: 0.24652778 | T3: =VLOOKUP(E3,'[2]21-3-2026'!E$3:T$35,16,FALSE) -> 0.013888889 | U3: 0.26041667 | V3: =U3-T3-S3 -> 0 | W3: 0.041666667 | X3: 0.3 | Y3: 0.33680556 | Z3: =Y3-X3 -> 0.036805556 | AA3: 0 | AB3: 0.34027778 | AD3: رحلة اولى ( شرقى ومخبوزات وغربى )
A4: 2 | B4: 3495 | C4: =VLOOKUP(B4,داتا!$B$3:$D$107,2,FALSE) -> تلتين | D4: =VLOOKUP(B4,داتا!$B$3:$D$107,3,FALSE) -> 0.03125 | E4: اكتوبر | F4: رامي حسن | G4: 0.25 | H4: 0.22916667 | I4: 0 | J4: 0.21041667 | K4: 0.23611111 | L4: عبدالرحمن هشام | M4: عبدالرحمن هشام | N4: =K4-J4 -> 0.025694444 | O4: 0 | P4: 0.0069444444 | Q4: 0.24652778 | R4: =Q4-P4-K4 -> 0.0034722222 | S4: 0.24652778 | T4: =VLOOKUP(E4,'[2]21-3-2026'!E$3:T$35,16,FALSE) -> 0.041666667 | U4: 0.30208333 | V4: =U4-T4-S4 -> 0.013888889 | W4: 0.041666667 | X4: 0.33680556 | Y4: 0.37847222 | Z4: =Y4-X4 -> 0.041666667 | AA4: 0 | AB4: 0.38194444
A5: 3 | B5: 1451 | C5: تلتين | D5: 0.03125 | E5: الجسر | F5: مصطفى احمد | G5: 0.25 | H5: 0.25 | I5: =H5-G5 -> 0 | J5: 0.24652778 | K5: 0.26388889 | L5: عبدالرحمن هشام | M5: عبدالرحمن هشام | N5: =K5-J5 -> 0.017361111 | O5: 0 | P5: 0.0069444444 | Q5: 0.27430556 | R5: =Q5-P5-K5 -> 0.0034722222 | S5: 0.27430556 | T5: =VLOOKUP(E5,'[2]21-3-2026'!E$3:T$35,16,FALSE) -> 0.010416667 | U5: 0.29513889 | V5: =U5-T5-S5 -> 0.010416667 | W5: 0.041666667 | X5: 0.34236111 | Y5: 0.38888889 | Z5: =Y5-X5 -> 0.046527778 | AA5: =Z5-W5 -> 0.0048611111 | AB5: 0.39722222
A6: 4 | B6: 2714 | C6: =VLOOKUP(B6,داتا!$B$3:$D$107,2,FALSE) -> تلتين | D6: =VLOOKUP(B6,داتا!$B$3:$D$107,3,FALSE) -> 0.03125 | E6: العباسية | F6: علي النبوي | G6: 0.25 | H6: 0.26180556 | I6: =H6-G6 -> 0.011805556 | J6: 0.26736111 | K6: 0.29861111 | L6: عبدالرحمن هشام | M6: عبدالرحمن هشام | N6: =K6-J6 -> 0.03125 | O6: =N6-D6 -> 0 | P6: 0.0069444444 | Q6: 0.3125 | R6: =Q6-P6-K6 -> 0.0069444444 | S6: 0.3125 | T6: =VLOOKUP(E6,'[2]21-3-2026'!E$3:T$35,16,FALSE) -> 0.020833333 | U6: 0.34444444 | V6: =U6-T6-S6 -> 0.011111111 | W6: 0.041666667 | X6: 0.34861111 | Y6: 0.37916667 | Z6: =Y6-X6 -> 0.030555556 | AA6: 0 | AB6: 0.38194444
A7: 5 | B7: 3891 | C7: =VLOOKUP(B7,داتا!$B$3:$D$107,2,FALSE) -> تلتين | D7: =VLOOKUP(B7,داتا!$B$3:$D$107,3,FALSE) -> 0.03125 | E7: العاشر | F7: محمد صلاح | G7: 0.25 | H7: 0.24305556 | I7: 0 | J7: 0.1875 | K7: 0.21527778 | L7: محمد علي | M7: محمد علي | N7: =K7-J7 -> 0.027777778 | O7: 0 | P7: 0.0069444444 | Q7: 0.22569444 | R7: =Q7-P7-K7 -> 0.0034722222 | S7: 0.24305556 | T7: =VLOOKUP(E7,'[2]21-3-2026'!E$3:T$35,16,FALSE) -> 0.010416667 | U7: 0.27777778 | V7: =U7-T7-S7 -> 0.024305556 | W7: 0.041666667 | X7: 0.29861111 | Y7: 0.32638889 | Z7: =Y7-X7 -> 0.027777778 | AA7: 0 | AB7: 0.32986111
A8: 6 | B8: 3787 | C8: =VLOOKUP(B8,داتا!$B$3:$D$107,2,FALSE) -> دبابة | D8: =VLOOKUP(B8,داتا!$B$3:$D$107,3,FALSE) -> 0.020833333 | E8: الوسط | F8: جمعة السيد | G8: 0.25 | H8: 0.23958333 | I8: 0 | J8: 0.22222222 | K8: 0.24305556 | L8: محمد علي | M8: محمد علي | N8: =K8-J8 -> 0.020833333 | O8: =N8-D8 -> 4.1633363e-17 | P8: 0.0069444444 | Q8: 0.25694444 | R8: =Q8-P8-K8 -> 0.0069444444 | S8: 0.28125 | T8: =VLOOKUP(E8,'[2]21-3-2026'!E$3:T$35,16,FALSE) -> 0.017361111 | U8: 0.30555556 | V8: =U8-T8-S8 -> 0.0069444444 | W8: 0.03125 | X8: 0.30902778 | Y8: 0.32291667 | Z8: =Y8-X8 -> 0.013888889 | AA8: 0 | AB8: 0.32638889
A9: 7 | B9: 1537 | C9: =VLOOKUP(B9,داتا!$B$3:$D$107,2,FALSE) -> تلتين | D9: =VLOOKUP(B9,داتا!$B$3:$D$107,3,FALSE) -> 0.03125 | E9: المعادي 1 | F9: خالد محمد | G9: 0.25 | H9: 0.25694444 | I9: =H9-G9 -> 0.0069444444 | J9: 0.25 | K9: 0.27777778 | L9: محمد علي | M9: محمد علي | N9: =K9-J9 -> 0.027777778 | O9: 0 | P9: 0.0069444444 | Q9: 0.28472222 | R9: =Q9-P9-K9 -> 0 | S9: 0.28125 | T9: =VLOOKUP(E9,'[2]21-3-2026'!E$3:T$35,16,FALSE) -> 0.034722222 | U9: 0.32291667 | V9: =U9-T9-S9 -> 0.0069444444 | W9: 0.041666667 | X9: 0.33333333 | Y9: 0.37152778 | Z9: =Y9-X9 -> 0.038194444 | AA9: 0 | AB9: 0.375
A10: 8 | B10: 3783 | C10: =VLOOKUP(B10,داتا!$B$3:$D$107,2,FALSE) -> دبابة | D10: =VLOOKUP(B10,داتا!$B$3:$D$107,3,FALSE) -> 0.020833333 | E10: المعادي 2 | F10: الشناوي سرور | G10: 0.25 | H10: 0.25347222 | I10: =H10-G10 -> 0.0034722222 | J10: 0.28472222 | K10: 0.29513889 | L10: محمد علي | M10: محمد علي | N10: =K10-J10 -> 0.010416667 | O10: 0 | P10: 0.0069444444 | Q10: 0.29861111 | R10: 0 | S10: 0.29861111 | T10: =VLOOKUP(E10,'[2]21-3-2026'!E$3:T$35,16,FALSE) -> 0.034722222 | U10: 0.33680556 | V10: =U10-T10-S10 -> 0.0034722222 | W10: 0.03125 | X10: 0.34375 | Y10: 0.37152778 | Z10: =Y10-X10 -> 0.027777778 | AA10: 0 | AB10: 0.38194444
A11: 9 | B11: 6143 | C11: =VLOOKUP(B11,داتا!$B$3:$D$107,2,FALSE) -> تلتين | D11: =VLOOKUP(B11,داتا!$B$3:$D$107,3,FALSE) -> 0.03125 | E11: مكرم | F11: محمد حسان | G11: 0.25 | H11: 0.23958333 | I11: 0 | J11: 0.18402778 | K11: 0.23611111 | L11: محمد صادق | M11: محمد صادق | N11: =K11-J11 -> 0.052083333 | O11: =N11-D11 -> 0.020833333 | P11: 0.0069444444 | Q11: 0.24652778 | R11: =Q11-P11-K11 -> 0.0034722222 | S11: 0.24305556 | T11: =VLOOKUP(E11,'[2]21-3-2026'!E$3:T$35,16,FALSE) -> 0.017361111 | U11: 0.25833333 | V11: 0 | W11: 0.03125 | X11: 0.29513889 | Y11: 0.32291667 | Z11: =Y11-X11 -> 0.027777778 | AA11: 0 | AB11: 0.32638889
A12: 10 | B12: 6143 | C12: =VLOOKUP(B12,داتا!$B$3:$D$107,2,FALSE) -> تلتين | D12: =VLOOKUP(B12,داتا!$B$3:$D$107,3,FALSE) -> 0.03125 | E12: جاردينيا | F12: محمد حسان | G12: 0.25 | H12: 0.23958333 | I12: 0 | J12: 0.18402778 | K12: 0.23611111 | L12: محمد صادق | M12: محمد صادق | N12: =K12-J12 -> 0.052083333 | O12: =N12-D12 -> 0.020833333 | P12: 0.0069444444 | Q12: 0.24652778 | R12: =Q12-P12-K12 -> 0.0034722222 | S12: 0.24305556 | T12: =VLOOKUP(E12,'[2]21-3-2026'!E$3:T$35,16,FALSE) -> 0.010416667 | U12: 0.34375 | V12: 0.0069444444 | W12: 0.041666667 | X12: 0.35416667 | Y12: 0.375 | Z12: =Y12-X12 -> 0.020833333 | AA12: 0 | AB12: 0.38541667
A13: 11 | B13: 2917 | C13: =VLOOKUP(B13,داتا!$B$3:$D$107,2,FALSE) -> تلتين | D13: =VLOOKUP(B13,داتا!$B$3:$D$107,3,FALSE) -> 0.03125 | E13: الشروق | F13: رجب محمد | G13: 0.25 | H13: 0.24305556 | I13: 0 | J13: 0.24305556 | K13: 0.29166667 | L13: محمد صادق | M13: محمد صادق | N13: =K13-J13 -> 0.048611111 | O13: =N13-D13 -> 0.017361111 | P13: 0.0069444444 | Q13: 0.29861111 | R13: =Q13-P13-K13 -> 0 | S13: 0.29861111 | T13: =VLOOKUP(E13,'[2]21-3-2026'!E$3:T$35,16,FALSE) -> 0.034722222 | U13: 0.34375 | V13: =U13-T13-S13 -> 0.010416667 | W13: 0.03125 | X13: 0.34513889 | Y13: 0.36319444 | Z13: =Y13-X13 -> 0.018055556 | AA13: 0 | AB13: 0.36458333
A14: 12 | B14: 2917 | C14: =VLOOKUP(B14,داتا!$B$3:$D$107,2,FALSE) -> تلتين | D14: =VLOOKUP(B14,داتا!$B$3:$D$107,3,FALSE) -> 0.03125 | E14: الشروق 3 | F14: رجب محمد | G14: 0.25 | H14: 0.24305556 | I14: 0 | J14: 0.24305556 | K14: 0.29166667 | L14: محمد صادق | M14: محمد صادق | N14: =K14-J14 -> 0.048611111 | O14: =N14-D14 -> 0.017361111 | P14: 0.0069444444 | Q14: 0.29861111 | R14: =Q14-P14-K14 -> 0 | S14: 0.29861111 | T14: 0.010416667 | U14: 0.38055556 | V14: 0.0055555556 | W14: 0.041666667 | X14: 0.38541667 | Y14: 0.42013889 | Z14: =Y14-X14 -> 0.034722222 | AA14: 0 | AB14: 0.42361111
A15: 13 | B15: 5898 | C15: =VLOOKUP(B15,داتا!$B$3:$D$107,2,FALSE) -> تلتين | D15: =VLOOKUP(B15,داتا!$B$3:$D$107,3,FALSE) -> 0.03125 | E15: الدقي | F15: علاء مجدي | G15: 0.25 | H15: 0.23958333 | I15: 0 | J15: 0.1875 | K15: 0.23611111 | L15: عمر الجوهري | M15: عمر الجوهري | N15: =K15-J15 -> 0.048611111 | O15: =N15-D15 -> 0.017361111 | P15: 0.0069444444 | Q15: 0.24305556 | R15: =Q15-P15-K15 -> 0 | S15: 0.25 | T15: =VLOOKUP(E15,'[2]21-3-2026'!E$3:T$35,16,FALSE) -> 0.013888889 | U15: 0.29166667 | V15: =U15-T15-S15 -> 0.027777778 | W15: 0.03125 | X15: 0.30208333 | Y15: 0.33958333 | Z15: =Y15-X15 -> 0.0375 | AA15: =Z15-W15 -> 0.00625 | AB15: 0.34027778
A16: 14 | B16: 5898 | C16: =VLOOKUP(B16,داتا!$B$3:$D$107,2,FALSE) -> تلتين | D16: =VLOOKUP(B16,داتا!$B$3:$D$107,3,FALSE) -> 0.03125 | E16: عرابي | F16: علاء مجدي | G16: 0.25 | H16: 0.23958333 | I16: 0 | J16: 0.1875 | K16: 0.23611111 | L16: عمر الجوهري | M16: عمر الجوهري | N16: =K16-J16 -> 0.048611111 | O16: =N16-D16 -> 0.017361111 | P16: 0.0069444444 | Q16: 0.24305556 | R16: =Q16-P16-K16 -> 0 | S16: 0.25 | T16: =VLOOKUP(E16,'[2]21-3-2026'!E$3:T$35,16,FALSE) -> 0.017361111 | U16: 0.35416667 | V16: 0 | W16: 0.041666667 | X16: 0.35763889 | Y16: 0.39236111 | Z16: =Y16-X16 -> 0.034722222 | AA16: 0 | AB16: 0.39583333
A17: 15 | B17: 2695 | C17: =VLOOKUP(B17,داتا!$B$3:$D$107,2,FALSE) -> تلتين | D17: =VLOOKUP(B17,داتا!$B$3:$D$107,3,FALSE) -> 0.03125 | E17: الوايلي | F17: رامي عادل | G17: 0.25 | H17: 0.25347222 | I17: =H17-G17 -> 0.0034722222 | J17: 0.23958333 | K17: 0.26388889 | L17: عمر الجوهري | M17: عمر الجوهري | N17: =K17-J17 -> 0.024305556 | O17: 0 | P17: 0.0069444444 | Q17: 0.27430556 | R17: =Q17-P17-K17 -> 0.0034722222 | S17: 0.27430556 | T17: =VLOOKUP(E17,'[2]21-3-2026'!E$3:T$35,16,FALSE) -> 0.010416667 | U17: 0.28819444 | V17: =U17-T17-S17 -> 0.0034722222 | W17: 0.03125 | X17: 0.30138889 | Y17: 0.32986111 | Z17: =Y17-X17 -> 0.028472222 | AA17: 0 | AB17: 0.33333333
A18: 16 | B18: 2695 | C18: =VLOOKUP(B18,داتا!$B$3:$D$107,2,FALSE) -> تلتين | D18: =VLOOKUP(B18,داتا!$B$3:$D$107,3,FALSE) -> 0.03125 | E18: المنتزة | F18: رامي عادل | G18: 0.25 | H18: 0.25347222 | I18: =H18-G18 -> 0.0034722222 | J18: 0.23958333 | K18: 0.26388889 | L18: عمر الجوهري | M18: عمر الجوهري | N18: =K18-J18 -> 0.024305556 | O18: 0 | P18: 0.0069444444 | Q18: 0.27430556 | R18: =Q18-P18-K18 -> 0.0034722222 | S18: 0.27430556 | T18: =VLOOKUP(E18,'[2]21-3-2026'!E$3:T$35,16,FALSE) -> 0.010416667 | U18: 0.35763889 | V18: 0.013888889 | W18: 0.041666667 | X18: 0.36111111 | Y18: 0.37847222 | Z18: =Y18-X18 -> 0.017361111 | AA18: 0 | AB18: 0.38194444
A19: 17 | B19: 459 | C19: =VLOOKUP(B19,داتا!$B$3:$D$107,2,FALSE) -> دبابة | D19: =VLOOKUP(B19,داتا!$B$3:$D$107,3,FALSE) -> 0.020833333 | E19: الشريف | F19: عبدالرحمن محمد | G19: 0.25 | H19: 0.26041667 | I19: =H19-G19 -> 0.010416667 | J19: 0.26736111 | K19: 0.29166667 | L19: عمر الجوهري | M19: عمر الجوهري | N19: =K19-J19 -> 0.024305556 | O19: =N19-D19 -> 0.0034722222 | P19: 0.0069444444 | Q19: 0.29861111 | R19: =Q19-P19-K19 -> 0 | S19: 0.29861111 | T19: =VLOOKUP(E19,'[2]21-3-2026'!E$3:T$35,16,FALSE) -> 0.017361111 | U19: 0.31597222 | V19: =U19-T19-S19 -> 0 | W19: 0.03125 | X19: 0.33333333 | Y19: 0.37152778 | Z19: =Y19-X19 -> 0.038194444 | AA19: =Z19-W19 -> 0.0069444444 | AB19: 0.375
A20: 18 | B20: 1538 | C20: =VLOOKUP(B20,داتا!$B$3:$D$107,2,FALSE) -> تلتين | D20: =VLOOKUP(B20,داتا!$B$3:$D$107,3,FALSE) -> 0.03125 | E20: فيصل | F20: اسامه مصطفى | G20: 0.25 | H20: 0.24305556 | I20: 0 | J20: 0.19791667 | K20: 0.21875 | L20: احمد امام | M20: احمد امام | N20: =K20-J20 -> 0.020833333 | O20: 0 | P20: 0.0069444444 | Q20: 0.22222222 | R20: 0 | S20: 0.24305556 | T20: =VLOOKUP(E20,'[2]21-3-2026'!E$3:T$35,16,FALSE) -> 0.034722222 | U20: 0.27986111 | V20: =U20-T20-S20 -> 0.0020833333 | W20: 0.041666667 | X20: 0.29513889 | Y20: 0.33263889 | Z20: =Y20-X20 -> 0.0375 | AA20: 0 | AB20: 0.33888889
A21: 19 | B21: 2694 | C21: =VLOOKUP(B21,داتا!$B$3:$D$107,2,FALSE) -> تلتين | D21: =VLOOKUP(B21,داتا!$B$3:$D$107,3,FALSE) -> 0.03125 | E21: الطوابق | F21: رضا معروف | G21: 0.25 | H21: 0.26388889 | I21: =H21-G21 -> 0.013888889 | J21: 0.22222222 | K21: 0.24305556 | L21: احمد امام | M21: احمد امام | N21: =K21-J21 -> 0.020833333 | O21: 0 | P21: 0.0069444444 | Q21: 0.25347222 | R21: =Q21-P21-K21 -> 0.0034722222 | S21: 0.26736111 | T21: =VLOOKUP(E21,'[2]21-3-2026'!E$3:T$35,16,FALSE) -> 0.034722222 | U21: 0.30208333 | V21: =U21-T21-S21 -> 0 | W21: 0.041666667 | X21: 0.34166667 | Y21: 0.37847222 | Z21: =Y21-X21 -> 0.036805556 | AA21: 0 | AB21: 0.38541667
A22: 20 | B22: 4879 | C22: =VLOOKUP(B22,داتا!$B$3:$D$107,2,FALSE) -> دبابة | D22: =VLOOKUP(B22,داتا!$B$3:$D$107,3,FALSE) -> 0.020833333 | E22: الشيراتون | F22: جمال فؤاد | G22: 0.25 | H22: 0.25 | I22: =H22-G22 -> 0 | J22: 0.24652778 | K22: 0.26388889 | L22: احمد امام | M22: احمد امام | N22: =K22-J22 -> 0.017361111 | O22: 0 | P22: 0.0069444444 | Q22: 0.26736111 | R22: 0 | S22: 0.26041667 | T22: =VLOOKUP(E22,'[2]21-3-2026'!E$3:T$35,16,FALSE) -> 0.020833333 | U22: 0.28125 | V22: =U22-T22-S22 -> 0 | W22: 0.03125 | X22: 0.33680556 | Y22: 0.36458333 | Z22: =Y22-X22 -> 0.027777778 | AA22: 0 | AB22: 0.36805556
A23: 21 | B23: 675 | C23: =VLOOKUP(B23,داتا!$B$3:$D$107,2,FALSE) -> جامبو | D23: =VLOOKUP(B23,داتا!$B$3:$D$107,3,FALSE) -> 0.041666667 | E23: السواح | F23: عبدالرحمن عاطف | G23: 0.25 | H23: 0.26180556 | I23: =H23-G23 -> 0.011805556 | J23: 0.26736111 | K23: 0.29513889 | L23: احمد امام | M23: احمد امام | N23: =K23-J23 -> 0.027777778 | O23: 0 | P23: 0.0069444444 | Q23: 0.29861111 | R23: 0 | S23: 0.29861111 | T23: =VLOOKUP(E23,'[2]21-3-2026'!E$3:T$35,16,FALSE) -> 0.010416667 | U23: 0.31597222 | V23: =U23-T23-S23 -> 0.0069444444 | W23: 0.0625 | X23: 0.33680556 | Y23: 0.38194444 | Z23: =Y23-X23 -> 0.045138889 | AA23: 0 | AB23: 0.38541667
A24: 22 | B24: 7464 | C24: =VLOOKUP(B24,داتا!$B$3:$D$107,2,FALSE) -> تلتين | D24: =VLOOKUP(B24,داتا!$B$3:$D$107,3,FALSE) -> 0.03125 | E24: التجمع 1 | F24: عمرو محمد | G24: 0.25 | H24: 0.25347222 | I24: =H24-G24 -> 0.0034722222 | J24: 0.1875 | K24: 0.22222222 | L24: احمد خيري | M24: احمد خيري | N24: =K24-J24 -> 0.034722222 | O24: =N24-D24 -> 0.0034722222 | P24: 0.0069444444 | Q24: 0.23263889 | R24: =Q24-P24-K24 -> 0.0034722222 | S24: 0.25694444 | T24: =VLOOKUP(E24,'[2]21-3-2026'!E$3:T$35,16,FALSE) -> 0.024305556 | U24: 0.28125 | V24: =U24-T24-S24 -> 0 | W24: 0.03125 | X24: 0.29861111 | Y24: 0.32638889 | Z24: =Y24-X24 -> 0.027777778 | AA24: 0 | AB24: 0.32986111
A25: 23 | B25: 7464 | C25: =VLOOKUP(B25,داتا!$B$3:$D$107,2,FALSE) -> تلتين | D25: =VLOOKUP(B25,داتا!$B$3:$D$107,3,FALSE) -> 0.03125 | E25: التجمع 5 | F25: عمرو محمد | G25: 0.25 | H25: 0.25347222 | I25: =H25-G25 -> 0.0034722222 | J25: 0.1875 | K25: 0.22222222 | L25: احمد خيري | M25: احمد خيري | N25: =K25-J25 -> 0.034722222 | O25: =N25-D25 -> 0.0034722222 | P25: 0.0069444444 | Q25: 0.23263889 | R25: =Q25-P25-K25 -> 0.0034722222 | S25: 0.25694444 | T25: =VLOOKUP(E25,'[2]21-3-2026'!E$3:T$35,16,FALSE) -> 0.010416667 | U25: 0.35069444 | V25: 0.010416667 | W25: 0.041666667 | X25: 0.35416667 | Y25: 0.38888889 | Z25: =Y25-X25 -> 0.034722222 | AA25: 0 | AB25: 0.39236111
A26: 24 | B26: 586 | C26: =VLOOKUP(B26,داتا!$B$3:$D$107,2,FALSE) -> سوزوكي | D26: =VLOOKUP(B26,داتا!$B$3:$D$107,3,FALSE) -> 0.020833333 | E26: الدوران | F26: خالد صبري | G26: 0.25 | H26: 0.26388889 | I26: =H26-G26 -> 0.013888889 | J26: 0.22916667 | K26: 0.23263889 | L26: احمد خيري | M26: احمد خيري | N26: =K26-J26 -> 0.0034722222 | O26: 0 | P26: 0.0069444444 | Q26: 0.23958333 | R26: =Q26-P26-K26 -> 0 | S26: 0.26736111 | T26: =VLOOKUP(E26,'[2]21-3-2026'!E$3:T$35,16,FALSE) -> 0.013888889 | U26: 0.29166667 | V26: =U26-T26-S26 -> 0.010416667 | W26: 0.03125 | X26: 0.34027778 | Y26: 0.35416667 | Z26: =Y26-X26 -> 0.013888889 | AA26: 0 | AB26: 0.36458333
A27: 25 | B27: 1454 | C27: =VLOOKUP(B27,داتا!$B$3:$D$107,2,FALSE) -> تلتين | D27: =VLOOKUP(B27,داتا!$B$3:$D$107,3,FALSE) -> 0.03125 | E27: شبرا | F27: احمد فوزي | G27: 0.25 | H27: 0.26319444 | I27: =H27-G27 -> 0.013194444 | J27: 0.23611111 | K27: 0.26041667 | L27: احمد خيري | M27: احمد خيري | N27: =K27-J27 -> 0.024305556 | O27: 0 | P27: 0.0069444444 | Q27: 0.27777778 | R27: =Q27-P27-K27 -> 0.010416667 | S27: 0.27083333 | T27: =VLOOKUP(E27,'[2]21-3-2026'!E$3:T$35,16,FALSE) -> 0.013888889 | U27: 0.28263889 | V27: 0 | W27: 0.03125 | X27: 0.33333333 | Y27: 0.36805556 | Z27: =Y27-X27 -> 0.034722222 | AA27: =Z27-W27 -> 0.0034722222 | AB27: 0.37152778
A28: 26 | B28: 1454 | C28: =VLOOKUP(B28,داتا!$B$3:$D$107,2,FALSE) -> تلتين | D28: =VLOOKUP(B28,داتا!$B$3:$D$107,3,FALSE) -> 0.03125 | E28: الدوران | F28: احمد فوزي | G28: 0.25 | H28: 0.26319444 | I28: =H28-G28 -> 0.013194444 | J28: 0.23611111 | K28: 0.26041667 | L28: احمد خيري | M28: احمد خيري | N28: =K28-J28 -> 0.024305556 | O28: 0 | P28: 0.0069444444 | Q28: 0.27777778 | R28: =Q28-P28-K28 -> 0.010416667 | S28: 0.27083333 | T28: =VLOOKUP(E28,'[2]21-3-2026'!E$3:T$35,16,FALSE) -> 0.013888889 | U28: 0.38194444 | V28: 0 | W28: 0.041666667 | X28: 0.38888889 | Y28: 0.41319444 | Z28: =Y28-X28 -> 0.024305556 | AA28: 0 | AB28: 0.41666667
A29: 27 | B29: 9198 | C29: =VLOOKUP(B29,داتا!$B$3:$D$107,2,FALSE) -> دبابة | D29: =VLOOKUP(B29,داتا!$B$3:$D$107,3,FALSE) -> 0.020833333 | E29: مسطرد | F29: كريم محمود | G29: 0.25 | H29: 0.27083333 | I29: =H29-G29 -> 0.020833333 | J29: 0.27430556 | K29: 0.28819444 | L29: احمد خيري | M29: احمد خيري | N29: =K29-J29 -> 0.013888889 | O29: 0 | P29: 0.0069444444 | Q29: 0.29513889 | R29: =Q29-P29-K29 -> 0 | S29: 0.29166667 | T29: =VLOOKUP(E29,'[2]21-3-2026'!E$3:T$35,16,FALSE) -> 0.0034722222 | U29: 0.29513889 | V29: =U29-T29-S29 -> 0 | W29: 0.03125 | X29: 0.33333333 | Y29: 0.37152778 | Z29: =Y29-X29 -> 0.038194444 | AA29: =Z29-W29 -> 0.0069444444 | AB29: 0.375
A30: 28 | B30: 634 | C30: =VLOOKUP(B30,داتا!$B$3:$D$107,2,FALSE) -> دبابة | D30: =VLOOKUP(B30,داتا!$B$3:$D$107,3,FALSE) -> 0.020833333 | E30: المطرية | F30: محمود عبدالفتاح | G30: 0.29166667 | H30: 0.28472222 | I30: 0 | J30: 0.29166667 | K30: 0.30555556 | L30: احمد خيري | M30: احمد خيري | N30: =K30-J30 -> 0.013888889 | O30: 0 | P30: 0.0069444444 | Q30: 0.3125 | R30: =Q30-P30-K30 -> 0 | S30: 0.31597222 | T30: =VLOOKUP(E30,'[2]21-3-2026'!E$3:T$35,16,FALSE) -> 0.0048611111 | U30: 0.32986111 | V30: =U30-T30-S30 -> 0.0090277778 | W30: 0.03125 | X30: 0.33333333 | Y30: 0.36805556 | Z30: =Y30-X30 -> 0.034722222 | AA30: =Z30-W30 -> 0.0034722222 | AB30: 0.36875
A31: 29 | B31: 6142 | C31: =VLOOKUP(B31,داتا!$B$3:$D$107,2,FALSE) -> تلتين | D31: =VLOOKUP(B31,داتا!$B$3:$D$107,3,FALSE) -> 0.03125 | E31: عباس | F31: علي عادل | G31: 0.25 | H31: 0.25 | I31: =H31-G31 -> 0 | J31: 0.1875 | K31: 0.23263889 | L31: سيد رزق | M31: احمد حسين | N31: =K31-J31 -> 0.045138889 | O31: =N31-D31 -> 0.013888889 | P31: 0.0069444444 | Q31: 0.23958333 | R31: =Q31-P31-K31 -> 0 | S31: 0.25347222 | T31: =VLOOKUP(E31,'[2]21-3-2026'!E$3:T$35,16,FALSE) -> 0.017361111 | U31: 0.27083333 | V31: =U31-T31-S31 -> 0 | W31: 0.03125 | X31: 0.29861111 | Y31: 0.32638889 | Z31: =Y31-X31 -> 0.027777778 | AA31: 0 | AB31: 0.32986111
A32: 30 | B32: 6142 | C32: =VLOOKUP(B32,داتا!$B$3:$D$107,2,FALSE) -> تلتين | D32: =VLOOKUP(B32,داتا!$B$3:$D$107,3,FALSE) -> 0.03125 | E32: الميرغني | F32: علي عادل | G32: 0.25 | H32: 0.25 | I32: =H32-G32 -> 0 | J32: 0.1875 | K32: 0.23263889 | L32: سيد رزق | M32: احمد حسين | N32: =K32-J32 -> 0.045138889 | O32: =N32-D32 -> 0.013888889 | P32: 0.0069444444 | Q32: 0.23958333 | R32: =Q32-P32-K32 -> 0 | S32: 0.25347222 | T32: =VLOOKUP(E32,'[2]21-3-2026'!E$3:T$35,16,FALSE) -> 0.013888889 | U32: 0.34097222 | V32: 0 | W32: 0.041666667 | X32: 0.34236111 | Y32: 0.36458333 | Z32: =Y32-X32 -> 0.022222222 | AA32: 0 | AB32: 0.36805556
A33: 31 | B33: 2474 | C33: =VLOOKUP(B33,داتا!$B$3:$D$107,2,FALSE) -> دبابة | D33: =VLOOKUP(B33,داتا!$B$3:$D$107,3,FALSE) -> 0.020833333 | E33: العاشر من رمضان | F33: احمد سعيد | G33: 0.25 | H33: 0.25347222 | I33: =H33-G33 -> 0.0034722222 | J33: 0.23958333 | K33: 0.25347222 | L33: سيد رزق | M33: احمد حسين | N33: =K33-J33 -> 0.013888889 | O33: 0 | P33: 0.0069444444 | Q33: 0.26041667 | R33: =Q33-P33-K33 -> 0 | S33: 0.26041667 | T33: =VLOOKUP(E33,'[2]21-3-2026'!E$3:T$35,16,FALSE) -> 0.0625 | U33: 0.30555556 | V33: 0 | W33: 0.03125 | X33: 0.33680556 | Y33: 0.36805556 | Z33: =Y33-X33 -> 0.03125 | AA33: =Z33-W33 -> 0 | AB33: 0.37152778
A34: 32 | B34: 3492 | C34: =VLOOKUP(B34,داتا!$B$3:$D$107,2,FALSE) -> تلتين | D34: =VLOOKUP(B34,داتا!$B$3:$D$107,3,FALSE) -> 0.03125 | E34: العبور | F34: محمود ابو طالب | G34: 0.25 | H34: 0.25347222 | I34: =H34-G34 -> 0.0034722222 | J34: 0.26041667 | K34: 0.27777778 | L34: سيد رزق | M34: احمد حسين | N34: =K34-J34 -> 0.017361111 | O34: 0 | P34: 0.0069444444 | Q34: 0.28472222 | R34: =Q34-P34-K34 -> 0 | S34: 0.27777778 | T34: =VLOOKUP(E34,'[2]21-3-2026'!E$3:T$35,16,FALSE) -> 0.027777778 | U34: 0.3125 | V34: =U34-T34-S34 -> 0.0069444444 | W34: 0.041666667 | X34: 0.34027778 | Y34: 0.37152778 | Z34: =Y34-X34 -> 0.03125 | AA34: 0 | AB34: 0.37847222
A35: 33 | B35: 796 | C35: =VLOOKUP(B35,داتا!$B$3:$D$107,2,FALSE) -> دبابة | D35: =VLOOKUP(B35,داتا!$B$3:$D$107,3,FALSE) -> 0.020833333 | E35: الكوربة | F35: محمد عباس | G35: 0.25 | H35: 0.26041667 | I35: =H35-G35 -> 0.010416667 | J35: 0.28819444 | K35: 0.30555556 | L35: سيد رزق | M35: احمد حسين | N35: =K35-J35 -> 0.017361111 | O35: 0 | P35: 0.0069444444 | Q35: 0.3125 | R35: =Q35-P35-K35 -> 0 | S35: 0.31597222 | T35: =VLOOKUP(E35,'[2]21-3-2026'!E$3:T$35,16,FALSE) -> 0.013888889 | U35: 0.34722222 | V35: =U35-T35-S35 -> 0.017361111 | W35: 0.03125 | X35: 0.34861111 | Y35: 0.375 | Z35: =Y35-X35 -> 0.026388889 | AA35: 0 | AB35: 0.37847222
A36: 1 | B36: 634 | C36: =VLOOKUP(B36,داتا!$B$3:$D$107,2,FALSE) -> دبابة | D36: =VLOOKUP(B36,داتا!$B$3:$D$107,3,FALSE) -> 0.020833333 | E36: الشيراتون | F36: محمود عبدالفتاح | G36: 0.25 | H36: =VLOOKUP(F36,$F$3:$H$35,3,FALSE) -> 0.28472222 | I36: =H36-G36 -> 0.034722222 | J36: 0.40277778 | K36: 0.41319444 | L36: محمد امام | M36: محمد امام | N36: =K36-J36 -> 0.010416667 | O36: 0 | P36: 0.0069444444 | Q36: 0.41666667 | R36: 0 | S36: 0.41666667 | T36: =VLOOKUP(E36,'[2]21-3-2026'!E$3:T$35,16,FALSE) -> 0.020833333 | U36: 0.45486111 | V36: =U36-T36-S36 -> 0.017361111 | W36: 0.020833333 | X36: 0.45833333 | Y36: 0.46875 | Z36: =Y36-X36 -> 0.010416667 | AA36: 0 | AB36: 0.47222222 | AD36: رحلة ثانية ( شرقى وغربى ومخبوزات )
A37: 2 | B37: 634 | C37: =VLOOKUP(B37,داتا!$B$3:$D$107,2,FALSE) -> دبابة | D37: =VLOOKUP(B37,داتا!$B$3:$D$107,3,FALSE) -> 0.020833333 | E37: جاردينيا | F37: محمود عبدالفتاح | G37: 0.25 | H37: =VLOOKUP(F37,$F$3:$H$35,3,FALSE) -> 0.28472222 | I37: =H37-G37 -> 0.034722222 | J37: 0.40277778 | K37: 0.41319444 | L37: محمد امام | M37: محمد امام | N37: =K37-J37 -> 0.010416667 | O37: 0 | P37: 0.0069444444 | Q37: 0.41666667 | R37: 0 | S37: 0.41666667 | T37: =VLOOKUP(E37,'[2]21-3-2026'!E$3:T$35,16,FALSE) -> 0.010416667 | U37: 0.48958333 | V37: 0.0069444444 | W37: 0.03125 | X37: 0.49305556 | Y37: 0.50694444 | Z37: =Y37-X37 -> 0.013888889 | AA37: 0 | AB37: 0.51736111
A38: 3 | B38: 459 | C38: =VLOOKUP(B38,داتا!$B$3:$D$107,2,FALSE) -> دبابة | D38: =VLOOKUP(B38,داتا!$B$3:$D$107,3,FALSE) -> 0.020833333 | E38: المنتزة | F38: عبدالرحمن محمد | G38: 0.25 | H38: =VLOOKUP(F38,$F$3:$H$35,3,FALSE) -> 0.26041667 | I38: =H38-G38 -> 0.010416667 | J38: 0.42361111 | K38: 0.4375 | L38: محمد امام | M38: محمد امام | N38: =K38-J38 -> 0.013888889 | O38: 0 | P38: 0.0069444444 | Q38: 0.44097222 | R38: 0 | S38: 0.44097222 | T38: =VLOOKUP(E38,'[2]21-3-2026'!E$3:T$35,16,FALSE) -> 0.010416667 | U38: 0.45625 | V38: =U38-T38-S38 -> 0.0048611111 | W38: 0.020833333 | X38: 0.45833333 | Y38: 0.47083333 | Z38: =Y38-X38 -> 0.0125 | AA38: 0 | AB38: 0.47222222
A39: 4 | B39: 459 | C39: =VLOOKUP(B39,داتا!$B$3:$D$107,2,FALSE) -> دبابة | D39: =VLOOKUP(B39,داتا!$B$3:$D$107,3,FALSE) -> 0.020833333 | E39: الكوربة | F39: عبدالرحمن محمد | G39: 0.25 | H39: =VLOOKUP(F39,$F$3:$H$35,3,FALSE) -> 0.26041667 | I39: =H39-G39 -> 0.010416667 | J39: 0.42361111 | K39: 0.4375 | L39: محمد امام | M39: محمد امام | N39: =K39-J39 -> 0.013888889 | O39: 0 | P39: 0.0069444444 | Q39: 0.44097222 | R39: 0 | S39: 0.44097222 | T39: =VLOOKUP(E39,'[2]21-3-2026'!E$3:T$35,16,FALSE) -> 0.013888889 | U39: 0.47916667 | V39: 0 | W39: 0.03125 | X39: 0.48263889 | Y39: 0.49305556 | Z39: =Y39-X39 -> 0.010416667 | AA39: 0 | AB39: 0.49652778
A40: 5 | B40: 3783 | C40: =VLOOKUP(B40,داتا!$B$3:$D$107,2,FALSE) -> دبابة | D40: =VLOOKUP(B40,داتا!$B$3:$D$107,3,FALSE) -> 0.020833333 | E40: الشروق 3 | F40: الشناوي سرور | G40: 0.25 | H40: =VLOOKUP(F40,$F$3:$H$35,3,FALSE) -> 0.25347222 | I40: =H40-G40 -> 0.0034722222 | J40: 0.45138889 | K40: 0.49305556 | L40: محمد امام | M40: محمد امام | N40: =K40-J40 -> 0.041666667 | O40: =N40-D40 -> 0.020833333 | P40: 0.0069444444 | Q40: 0.49305556 | R40: 0 | S40: 0.49305556 | T40: =VLOOKUP(E40,'[2]21-3-2026'!E$3:T$35,16,FALSE) -> 0.038194444 | U40: 0.52083333 | V40: 0 | W40: 0.020833333 | X40: 0.53472222 | Y40: 0.54166667 | Z40: =Y40-X40 -> 0.0069444444 | AA40: 0 | AB40: 0.54513889
...

Sheet 22-4-2026
A1: شيت دخول وخروج السيارات ايتوال عن يوم الاربعاء الموافق 22/4/2026
A2: م | B2: رقم السيارة | C2: نوع السيارة | D2: الزمن المعيارى للتحميل | E2: اسم الفرع | F2: اسم السائق | G2: وقت الحضور المقرر | H2: الحضور فعلى | I2: مدة التأخير | J2: دخول الكيدج | K2: نزول من الكيدج | L2: أخصائى الدفترى | M2: أخصائى السيستم | N2: مدة التحميل | O2: مدة انحراف التحميل | P2: الزمن المعيارى لنزول الاذن | Q2: وقت نزول الاذن | R2: مدة انحراف نزول الاذن | S2: خروج من المصنع | T2: الزمن المعيارى لدخول الفرع | U2: دخول الفرع | V2: مدة انحراف دخول الفرع | W2: الزمن المعيارى لنزول المنتجات | X2: فتح السياره | Y2: غلق السياره | Z2: الوقت المستغرق | AA2: مدة انحراف نزول المنتجات فى الفرع | AB2: خروج من الفرع | AC2: ملاحظات
A3: 1 | B3: 3495 | C3: =VLOOKUP(B3,داتا!$B$3:$D$107,2,FALSE) -> تلتين | D3: =VLOOKUP(B3,داتا!$B$3:$D$107,3,FALSE) -> 0.03125 | E3: النزهة | F3: رامي حسن | G3: 0.25 | H3: 0.22569444 | I3: 0 | J3: 0.18402778 | K3: 0.20138889 | L3: عبدالرحمن هشام | M3: عبدالرحمن هشام | N3: =K3-J3 -> 0.017361111 | O3: 0 | P3: 0.0069444444 | Q3: 0.20833333 | R3: =Q3-P3-K3 -> 0 | S3: 0.24652778 | T3: =VLOOKUP(E3,'[2]21-3-2026'!E$3:T$35,16,FALSE) -> 0.013888889 | U3: 0.26111111 | V3: =U3-T3-S3 -> 0.00069444444 | W3: 0.041666667 | X3: 0.30208333 | Y3: 0.33333333 | Z3: =Y3-X3 -> 0.03125 | AA3: 0 | AB3: 0.33680556 | AD3: رحلة اولى ( شرقى ومخبوزات وغربى )
A4: 2 | B4: 1538 | C4: =VLOOKUP(B4,داتا!$B$3:$D$107,2,FALSE) -> تلتين | D4: =VLOOKUP(B4,داتا!$B$3:$D$107,3,FALSE) -> 0.03125 | E4: اكتوبر | F4: عمرو المهدي | G4: 0.25 | H4: 0.23958333 | I4: 0 | J4: 0.20486111 | K4: 0.23611111 | L4: عبدالرحمن هشام | M4: عبدالرحمن هشام | N4: =K4-J4 -> 0.03125 | O4: =N4-D4 -> 0 | P4: 0.0069444444 | Q4: 0.24652778 | R4: =Q4-P4-K4 -> 0.0034722222 | S4: 0.25 | T4: =VLOOKUP(E4,'[2]21-3-2026'!E$3:T$35,16,FALSE) -> 0.041666667 | U4: 0.29513889 | V4: =U4-T4-S4 -> 0.0034722222 | W4: 0.041666667 | X4: 0.33333333 | Y4: 0.36458333 | Z4: =Y4-X4 -> 0.03125 | AA4: 0 | AB4: 0.36805556
A5: 3 | B5: 2714 | C5: =VLOOKUP(B5,داتا!$B$3:$D$107,2,FALSE) -> تلتين | D5: =VLOOKUP(B5,داتا!$B$3:$D$107,3,FALSE) -> 0.03125 | E5: الجسر | F5: علي النبوي | G5: 0.25 | H5: 0.26736111 | I5: =H5-G5 -> 0.017361111 | J5: 0.23958333 | K5: 0.27430556 | L5: عبدالرحمن هشام | M5: عبدالرحمن هشام | N5: =K5-J5 -> 0.034722222 | O5: =N5-D5 -> 0.0034722222 | P5: 0.0069444444 | Q5: 0.28125 | R5: =Q5-P5-K5 -> 0 | S5: 0.28472222 | T5: =VLOOKUP(E5,'[2]21-3-2026'!E$3:T$35,16,FALSE) -> 0.010416667 | U5: 0.31597222 | V5: =U5-T5-S5 -> 0.020833333 | W5: 0.041666667 | X5: 0.33819444 | Y5: 0.39930556 | Z5: =Y5-X5 -> 0.061111111 | AA5: =Z5-W5 -> 0.019444444 | AB5: 0.40625
A6: 4 | B6: 4987 | C6: =VLOOKUP(B6,داتا!$B$3:$D$107,2,FALSE) -> تلتين | D6: =VLOOKUP(B6,داتا!$B$3:$D$107,3,FALSE) -> 0.03125 | E6: العباسية | F6: محمد عباس | G6: 0.25 | H6: 0.26041667 | I6: =H6-G6 -> 0.010416667 | J6: 0.28125 | K6: 0.29166667 | L6: عبدالرحمن هشام | M6: عبدالرحمن هشام | N6: =K6-J6 -> 0.010416667 | O6: 0 | P6: 0.0069444444 | Q6: 0.29166667 | R6: 0 | S6: 0.30208333 | T6: =VLOOKUP(E6,'[2]21-3-2026'!E$3:T$35,16,FALSE) -> 0.020833333 | U6: 0.34722222 | V6: =U6-T6-S6 -> 0.024305556 | W6: 0.041666667 | X6: 0.35069444 | Y6: 0.36805556 | Z6: =Y6-X6 -> 0.017361111 | AA6: 0 | AB6: 0.37152778
A7: 5 | B7: 2917 | C7: =VLOOKUP(B7,داتا!$B$3:$D$107,2,FALSE) -> تلتين | D7: =VLOOKUP(B7,داتا!$B$3:$D$107,3,FALSE) -> 0.03125 | E7: العاشر | F7: رجب محمد | G7: 0.25 | H7: 0.23958333 | I7: 0 | J7: 0.20833333 | K7: 0.25694444 | L7: محمد علي | M7: محمد علي | N7: =K7-J7 -> 0.048611111 | O7: =N7-D7 -> 0.017361111 | P7: 0.0069444444 | Q7: 0.26736111 | R7: =Q7-P7-K7 -> 0.0034722222 | S7: 0.26388889 | T7: =VLOOKUP(E7,'[2]21-3-2026'!E$3:T$35,16,FALSE) -> 0.010416667 | U7: 0.29166667 | V7: =U7-T7-S7 -> 0.017361111 | W7: 0.03125 | X7: 0.29652778 | Y7: 0.32083333 | Z7: =Y7-X7 -> 0.024305556 | AA7: 0 | AB7: 0.32291667
A8: 6 | B8: 2917 | C8: =VLOOKUP(B8,داتا!$B$3:$D$107,2,FALSE) -> تلتين | D8: =VLOOKUP(B8,داتا!$B$3:$D$107,3,FALSE) -> 0.03125 | E8: المعادي 1 | F8: رجب محمد | G8: 0.25 | H8: 0.23958333 | I8: 0 | J8: 0.20833333 | K8: 0.25694444 | L8: محمد علي | M8: محمد علي | N8: =K8-J8 -> 0.048611111 | O8: =N8-D8 -> 0.017361111 | P8: 0.0069444444 | Q8: 0.26736111 | R8: =Q8-P8-K8 -> 0.0034722222 | S8: 0.26388889 | T8: =VLOOKUP(E8,'[2]21-3-2026'!E$3:T$35,16,FALSE) -> 0.034722222 | U8: 0.33333333 | V8: 0 | W8: 0.041666667 | X8: 0.34027778 | Y8: 0.37152778 | Z8: =Y8-X8 -> 0.03125 | AA8: 0 | AB8: 0.375
A9: 7 | B9: 3793 | C9: =VLOOKUP(B9,داتا!$B$3:$D$107,2,FALSE) -> دبابة | D9: =VLOOKUP(B9,داتا!$B$3:$D$107,3,FALSE) -> 0.020833333 | E9: المعادي 2 | F9: محمد مراد | G9: 0.25 | H9: 0.26388889 | I9: =H9-G9 -> 0.013888889 | J9: 0.26388889 | K9: 0.27430556 | L9: محمد علي | M9: محمد علي | N9: =K9-J9 -> 0.010416667 | O9: 0 | P9: 0.0069444444 | Q9: 0.28819444 | R9: =Q9-P9-K9 -> 0.0069444444 | S9: 0.28472222 | T9: =VLOOKUP(E9,'[2]21-3-2026'!E$3:T$35,16,FALSE) -> 0.034722222 | U9: 0.32291667 | V9: =U9-T9-S9 -> 0.0034722222 | W9: 0.03125 | X9: 0.33680556 | Y9: 0.36458333 | Z9: =Y9-X9 -> 0.027777778 | AA9: 0 | AB9: 0.36805556
A10: 8 | B10: 5898 | C10: =VLOOKUP(B10,داتا!$B$3:$D$107,2,FALSE) -> تلتين | D10: =VLOOKUP(B10,داتا!$B$3:$D$107,3,FALSE) -> 0.03125 | E10: مكرم | F10: علاء مجدي | G10: 0.25 | H10: 0.23958333 | I10: 0 | J10: 0.1875 | K10: 0.21527778 | L10: مصطفى ابراهيم | M10: مصطفى ابراهيم | N10: =K10-J10 -> 0.027777778 | O10: 0 | P10: 0.0069444444 | Q10: 0.22916667 | R10: =Q10-P10-K10 -> 0.0069444444 | S10: 0.26388889 | T10: =VLOOKUP(E10,'[2]21-3-2026'!E$3:T$35,16,FALSE) -> 0.017361111 | U10: 0.28819444 | V10: =U10-T10-S10 -> 0.0069444444 | W10: 0.03125 | X10: 0.29166667 | Y10: 0.32986111 | Z10: =Y10-X10 -> 0.038194444 | AA10: =Z10-W10 -> 0.0069444444 | AB10: 0.33333333
A11: 9 | B11: 5898 | C11: =VLOOKUP(B11,داتا!$B$3:$D$107,2,FALSE) -> تلتين | D11: =VLOOKUP(B11,داتا!$B$3:$D$107,3,FALSE) -> 0.03125 | E11: جاردينيا | F11: علاء مجدي | G11: 0.25 | H11: 0.23958333 | I11: 0 | J11: 0.1875 | K11: 0.21527778 | L11: مصطفى ابراهيم | M11: مصطفى ابراهيم | N11: =K11-J11 -> 0.027777778 | O11: 0 | P11: 0.0069444444 | Q11: 0.22916667 | R11: =Q11-P11-K11 -> 0.0069444444 | S11: 0.26388889 | T11: =VLOOKUP(E11,'[2]21-3-2026'!E$3:T$35,16,FALSE) -> 0.010416667 | U11: 0.34027778 | V11: 0 | W11: 0.041666667 | X11: 0.34375 | Y11: 0.37847222 | Z11: =Y11-X11 -> 0.034722222 | AA11: 0 | AB11: 0.38194444
A12: 10 | B12: 7464 | C12: =VLOOKUP(B12,داتا!$B$3:$D$107,2,FALSE) -> تلتين | D12: =VLOOKUP(B12,داتا!$B$3:$D$107,3,FALSE) -> 0.03125 | E12: الشروق | F12: عمرو محمد | G12: 0.25 | H12: 0.25 | I12: 0 | J12: 0.22916667 | K12: 0.25694444 | L12: مصطفى ابراهيم | M12: مصطفى ابراهيم | N12: =K12-J12 -> 0.027777778 | O12: 0 | P12: 0.0069444444 | Q12: 0.26736111 | R12: =Q12-P12-K12 -> 0.0034722222 | S12: 0.26388889 | T12: =VLOOKUP(E12,'[2]21-3-2026'!E$3:T$35,16,FALSE) -> 0.034722222 | U12: 0.29861111 | V12: =U12-T12-S12 -> 0 | W12: 0.03125 | X12: 0.33472222 | Y12: 0.36111111 | Z12: =Y12-X12 -> 0.026388889 | AA12: 0 | AB12: 0.36319444
A13: 11 | B13: 7464 | C13: =VLOOKUP(B13,داتا!$B$3:$D$107,2,FALSE) -> تلتين | D13: =VLOOKUP(B13,داتا!$B$3:$D$107,3,FALSE) -> 0.03125 | E13: الشروق 3 | F13: عمرو محمد | G13: 0.25 | H13: 0.25 | I13: 0 | J13: 0.22916667 | K13: 0.25694444 | L13: مصطفى ابراهيم | M13: مصطفى ابراهيم | N13: =K13-J13 -> 0.027777778 | O13: 0 | P13: 0.0069444444 | Q13: 0.26736111 | R13: =Q13-P13-K13 -> 0.0034722222 | S13: 0.26388889 | T13: =VLOOKUP(E13,'[2]21-3-2026'!E$3:T$35,16,FALSE) -> 0.038194444 | U13: 0.37847222 | V13: 0 | W13: 0.041666667 | X13: 0.38194444 | Y13: 0.41319444 | Z13: =Y13-X13 -> 0.03125 | AA13: 0 | AB13: 0.41666667
A14: 12 | B14: 4879 | C14: =VLOOKUP(B14,داتا!$B$3:$D$107,2,FALSE) -> دبابة | D14: =VLOOKUP(B14,داتا!$B$3:$D$107,3,FALSE) -> 0.020833333 | E14: المطرية | F14: جمال فؤاد | G14: 0.25 | H14: 0.25 | I14: =H14-G14 -> 0 | J14: 0.26736111 | K14: 0.28125 | L14: مصطفى ابراهيم | M14: مصطفى ابراهيم | N14: =K14-J14 -> 0.013888889 | O14: 0 | P14: 0.0069444444 | Q14: 0.28472222 | R14: 0 | S14: 0.28472222 | T14: =VLOOKUP(E14,'[2]21-3-2026'!E$3:T$35,16,FALSE) -> 0.0048611111 | U14: 0.29861111 | V14: =U14-T14-S14 -> 0.0090277778 | W14: 0.03125 | X14: 0.33333333 | Y14: 0.36458333 | Z14: =Y14-X14 -> 0.03125 | AA14: =Z14-W14 -> 0 | AB14: 0.36736111
A15: 13 | B15: 1454 | C15: =VLOOKUP(B15,داتا!$B$3:$D$107,2,FALSE) -> تلتين | D15: =VLOOKUP(B15,داتا!$B$3:$D$107,3,FALSE) -> 0.03125 | E15: الدقي | F15: احمد فوزي | G15: 0.25 | H15: 0.25 | I15: 0 | J15: 0.1875 | K15: 0.22569444 | L15: عمر الجوهري | M15: عمر الجوهري | N15: =K15-J15 -> 0.038194444 | O15: =N15-D15 -> 0.0069444444 | P15: 0.0069444444 | Q15: 0.23263889 | R15: =Q15-P15-K15 -> 0 | S15: 0.26041667 | T15: =VLOOKUP(E15,'[2]21-3-2026'!E$3:T$35,16,FALSE) -> 0.013888889 | U15: 0.28819444 | V15: =U15-T15-S15 -> 0.013888889 | W15: 0.03125 | X15: 0.29513889 | Y15: 0.33333333 | Z15: =Y15-X15 -> 0.038194444 | AA15: =Z15-W15 -> 0.0069444444 | AB15: 0.33680556
A16: 14 | B16: 1454 | C16: =VLOOKUP(B16,داتا!$B$3:$D$107,2,FALSE) -> تلتين | D16: =VLOOKUP(B16,داتا!$B$3:$D$107,3,FALSE) -> 0.03125 | E16: عرابي | F16: احمد فوزي | G16: 0.25 | H16: 0.25 | I16: 0 | J16: 0.1875 | K16: 0.22569444 | L16: عمر الجوهري | M16: عمر الجوهري | N16: =K16-J16 -> 0.038194444 | O16: =N16-D16 -> 0.0069444444 | P16: 0.0069444444 | Q16: 0.23263889 | R16: =Q16-P16-K16 -> 0 | S16: 0.26041667 | T16: =VLOOKUP(E16,'[2]21-3-2026'!E$3:T$35,16,FALSE) -> 0.017361111 | U16: 0.34375 | V16: 0 | W16: 0.041666667 | X16: 0.35069444 | Y16: 0.39236111 | Z16: =Y16-X16 -> 0.041666667 | AA16: =Z16-W16 -> 0 | AB16: 0.39583333
A17: 15 | B17: 2694 | C17: =VLOOKUP(B17,داتا!$B$3:$D$107,2,FALSE) -> تلتين | D17: =VLOOKUP(B17,داتا!$B$3:$D$107,3,FALSE) -> 0.03125 | E17: الوايلي | F17: رضا معروف | G17: 0.25 | H17: 0.25 | I17: =H17-G17 -> 0 | J17: 0.23263889 | K17: 0.25694444 | L17: عمر الجوهري | M17: عمر الجوهري | N17: =K17-J17 -> 0.024305556 | O17: 0 | P17: 0.0069444444 | Q17: 0.26041667 | R17: 0 | S17: 0.26041667 | T17: =VLOOKUP(E17,'[2]21-3-2026'!E$3:T$35,16,FALSE) -> 0.010416667 | U17: 0.27430556 | V17: =U17-T17-S17 -> 0.0034722222 | W17: 0.03125 | X17: 0.30277778 | Y17: 0.32638889 | Z17: =Y17-X17 -> 0.023611111 | AA17: 0 | AB17: 0.32986111
A18: 16 | B18: 2694 | C18: =VLOOKUP(B18,داتا!$B$3:$D$107,2,FALSE) -> تلتين | D18: =VLOOKUP(B18,داتا!$B$3:$D$107,3,FALSE) -> 0.03125 | E18: المنتزة | F18: رضا معروف | G18: 0.25 | H18: 0.25 | I18: =H18-G18 -> 0 | J18: 0.23263889 | K18: 0.25694444 | L18: عمر الجوهري | M18: عمر الجوهري | N18: =K18-J18 -> 0.024305556 | O18: 0 | P18: 0.0069444444 | Q18: 0.26041667 | R18: 0 | S18: 0.26041667 | T18: =VLOOKUP(E18,'[2]21-3-2026'!E$3:T$35,16,FALSE) -> 0.010416667 | U18: 0.35069444 | V18: 0.010416667 | W18: 0.041666667 | X18: 0.35416667 | Y18: 0.37083333 | Z18: =Y18-X18 -> 0.016666667 | AA18: 0 | AB18: 0.38194444
A19: 17 | B19: 3783 | C19: =VLOOKUP(B19,داتا!$B$3:$D$107,2,FALSE) -> دبابة | D19: =VLOOKUP(B19,داتا!$B$3:$D$107,3,FALSE) -> 0.020833333 | E19: الوسط | F19: الشناوي سرور | G19: 0.25 | H19: 0.25 | I19: =H19-G19 -> 0 | J19: 0.26041667 | K19: 0.27083333 | L19: عمر الجوهري | M19: عمر الجوهري | N19: =K19-J19 -> 0.010416667 | O19: 0 | P19: 0.0069444444 | Q19: 0.28125 | R19: 5 | S19: 0.28472222 | T19: =VLOOKUP(E19,'[2]21-3-2026'!E$3:T$35,16,FALSE) -> 0.017361111 | U19: 0.29861111 | V19: 0 | W19: 0.03125 | X19: 0.30208333 | Y19: 0.31944444 | Z19: =Y19-X19 -> 0.017361111 | AA19: 0 | AB19: 0.32291667
A20: 18 | B20: 796 | C20: =VLOOKUP(B20,داتا!$B$3:$D$107,2,FALSE) -> دبابة | D20: =VLOOKUP(B20,داتا!$B$3:$D$107,3,FALSE) -> 0.020833333 | E20: الشريف | F20: عمرو عبدالرحمن | G20: 0.25 | H20: 0.27083333 | I20: =H20-G20 -> 0.020833333 | J20: 0.27430556 | K20: 0.29166667 | L20: عمر الجوهري | M20: عمر الجوهري | N20: =K20-J20 -> 0.017361111 | O20: 0 | P20: 0.0069444444 | Q20: 0.29166667 | R20: 0 | S20: 0.30555556 | T20: =VLOOKUP(E20,'[2]21-3-2026'!E$3:T$35,16,FALSE) -> 0.017361111 | U20: 0.32638889 | V20: =U20-T20-S20 -> 0.0034722222 | W20: 0.03125 | X20: 0.33819444 | Y20: 0.37083333 | Z20: =Y20-X20 -> 0.032638889 | AA20: =Z20-W20 -> 0.0013888889 | AB20: 0.375
A21: 19 | B21: 1537 | C21: =VLOOKUP(B21,داتا!$B$3:$D$107,2,FALSE) -> تلتين | D21: =VLOOKUP(B21,داتا!$B$3:$D$107,3,FALSE) -> 0.03125 | E21: فيصل | F21: اسامه مصطفى | G21: 0.25 | H21: 0.24305556 | I21: 0 | J21: 0.18402778 | K21: 0.21527778 | L21: محمد صادق | M21: محمد صادق | N21: =K21-J21 -> 0.03125 | O21: =N21-D21 -> 0 | P21: 0.0069444444 | Q21: 0.22222222 | R21: =Q21-P21-K21 -> 0 | S21: 0.26736111 | T21: =VLOOKUP(E21,'[2]21-3-2026'!E$3:T$35,16,FALSE) -> 0.034722222 | U21: 0.30277778 | V21: =U21-T21-S21 -> 0.00069444444 | W21: 0.041666667 | X21: 0.30555556 | Y21: 0.34513889 | Z21: =Y21-X21 -> 0.039583333 | AA21: 0 | AB21: 0.35069444
