Workbook

Sheet داتا
A1: شيت دخول وخروج السيارات أبو محرم عن يوم الخميس الموافق 19/2/2026
A2: م | B2: رقم السيارة | C2: نوع السيارة | D2: الزمن المعيارى للتحميل | E2: اسم الفرع | F2: اسم السائق | G2: وقت الحضور المقرر | H2: الحضور فعلى | I2: مدة التأخير | J2: دخول الكيدج | K2: نزول من الكيدج | L2: أخصائى الدفترى | M2: أخصائى السيستم | N2: مدة التحميل | O2: مدة انحراف التحميل | P2: الزمن المعيارى لنزول الاذن | Q2: وقت نزول الاذن | R2: مدة انحراف نزول الاذن | S2: خروج من المصنع | T2: الزمن المعيارى لدخول الفرع | U2: دخول الفرع | V2: مدة انحراف دخول الفرع | W2: الزمن المعيارى لنزول المنتجات | X2: فتح السياره | Y2: غلق السياره | Z2: الوقت المستغرق | AA2: مدة انحراف نزول المنتجات فى الفرع | AB2: خروج من الفرع | AC2: ملاحظات
A3: 1 | B3: 892 | C3: =VLOOKUP(B3,'[1]22-1-2026'!$B$3:$D$38,2,FALSE) -> تلتين | D3: =VLOOKUP(B3,'[1]22-1-2026'!$B$3:$D$38,3,FALSE) -> 0.03125 | E3: اول جمال | F3: ابراهيم محمود | G3: 0.29166667 | H3: 0.29166667 | I3: =H3-G3 -> 0 | J3: 0.29513889 | K3: 0.31597222 | N3: =K3-J3 -> 0.020833333 | O3: 0 | P3: 0.0069444444 | Q3: 0.31597222 | R3: 0 | S3: 0.31597222 | T3: =VLOOKUP(E3,'[1]22-1-2026'!$E$3:$T$13,16,FALSE) -> 0.024305556 | U3: 0.34375 | V3: =U3-T3-S3 -> 0.0034722222 | W3: 0.03125 | X3: 0.35416667 | Y3: 0.375 | Z3: =Y3-X3 -> 0.020833333 | AA3: 0 | AB3: 0.37847222 | AD3: رحلة اولى ( شرقى ومخبوزات وغربى )
A4: 2 | B4: 892 | C4: =VLOOKUP(B4,'[1]22-1-2026'!$B$3:$D$38,2,FALSE) -> تلتين | D4: =VLOOKUP(B4,'[1]22-1-2026'!$B$3:$D$38,3,FALSE) -> 0.03125 | E4: السلام | F4: ابراهيم محمود | G4: 0.29166667 | H4: 0.29166667 | I4: =H4-G4 -> 0 | J4: 0.29513889 | K4: 0.31597222 | N4: =K4-J4 -> 0.020833333 | O4: 0 | P4: 0.0069444444 | Q4: 0.31597222 | R4: 0 | S4: 0.31597222 | T4: 0.010416667 | U4: 0.39236111 | V4: 0.0034722222 | W4: 0.041666667 | X4: 0.39375 | Y4: 0.4375 | Z4: =Y4-X4 -> 0.04375 | AA4: =Z4-W4 -> 0.0020833333 | AB4: 0.43958333
A5: 3 | B5: 2694 | C5: تلتين | D5: 0.03125 | E5: الشارع | F5: مصطفي عادل | G5: 0.29166667 | H5: 0.29166667 | I5: =H5-G5 -> 0 | J5: 0.31597222 | K5: 0.32638889 | N5: =K5-J5 -> 0.010416667 | O5: 0 | P5: 0.0069444444 | Q5: 0.32638889 | R5: 0 | S5: 0.32638889 | T5: =VLOOKUP(E5,'[1]22-1-2026'!$E$3:$T$13,16,FALSE) -> 0.013888889 | U5: 0.33888889 | V5: 0 | W5: 0.03125 | X5: 0.34722222 | Y5: 0.38055556 | Z5: =Y5-X5 -> 0.033333333 | AA5: =Z5-W5 -> 0.0020833333 | AB5: 0.38194444
A6: 4 | B6: 2694 | C6: تلتين | D6: 0.03125 | E6: التعاون | F6: مصطفي عادل | G6: 0.29166667 | H6: 0.29166667 | I6: =H6-G6 -> 0 | J6: 0.31597222 | K6: 0.32638889 | N6: =K6-J6 -> 0.010416667 | O6: 0 | P6: 0.0069444444 | Q6: 0.32638889 | R6: 0 | S6: 0.32638889 | T6: 0.010416667 | U6: 0.39236111 | V6: 0 | W6: 0.041666667 | X6: 0.39583333 | Y6: 0.42847222 | Z6: =Y6-X6 -> 0.032638889 | AA6: 0 | AB6: 0.43055556
A7: 5 | B7: 539 | C7: =VLOOKUP(B7,'[1]22-1-2026'!$B$3:$D$38,2,FALSE) -> دبابة | D7: =VLOOKUP(B7,'[1]22-1-2026'!$B$3:$D$38,3,FALSE) -> 0.020833333 | E7: الشروق | F7: احمد اشرف | G7: 0.29166667 | H7: 0.29166667 | I7: =H7-G7 -> 0 | J7: 0.27777778 | K7: 0.30902778 | N7: =K7-J7 -> 0.03125 | O7: =N7-D7 -> 0.010416667 | P7: 0.0069444444 | Q7: 0.30902778 | R7: 0 | S7: 0.30902778 | T7: =VLOOKUP(E7,'[1]22-1-2026'!$E$3:$T$13,16,FALSE) -> 0.034722222 | U7: 0.34722222 | V7: =U7-T7-S7 -> 0.0034722222 | W7: 0.020833333 | X7: 0.35069444 | Y7: 0.39236111 | Z7: =Y7-X7 -> 0.041666667 | AA7: =Z7-W7 -> 0.020833333 | AB7: 0.39583333
A8: 6 | B8: 539 | C8: =VLOOKUP(B8,'[1]22-1-2026'!$B$3:$D$38,2,FALSE) -> دبابة | D8: =VLOOKUP(B8,'[1]22-1-2026'!$B$3:$D$38,3,FALSE) -> 0.020833333 | E8: بدر | F8: احمد اشرف | G8: 0.29166667 | H8: 0.29166667 | I8: =H8-G8 -> 0 | J8: 0.27777778 | K8: 0.30902778 | N8: =K8-J8 -> 0.03125 | O8: =N8-D8 -> 0.010416667 | P8: 0.0069444444 | Q8: 0.30902778 | R8: 0 | S8: 0.30902778 | T8: 0.010416667 | U8: 0.41319444 | V8: 0.0069444444 | W8: 0.03125 | X8: 0.42013889 | Y8: 0.56944444 | Z8: =Y8-X8 -> 0.14930556 | AA8: =Z8-W8 -> 0.11805556 | AB8: 0.57291667
A9: 7 | B9: 762 | C9: =VLOOKUP(B9,'[1]22-1-2026'!$B$3:$D$38,2,FALSE) -> دبابة | D9: =VLOOKUP(B9,'[1]22-1-2026'!$B$3:$D$38,3,FALSE) -> 0.020833333 | E9: العبور | F9: ممدوح عبد العال | G9: 0.29166667 | H9: 0.28472222 | I9: 0 | J9: 0.30902778 | K9: 0.31944444 | N9: =K9-J9 -> 0.010416667 | O9: 0 | P9: 0.0069444444 | Q9: 0.31944444 | R9: 0 | S9: 0.31944444 | T9: =VLOOKUP(E9,'[1]22-1-2026'!$E$3:$T$13,16,FALSE) -> 0.017361111 | U9: 0.35416667 | V9: =U9-T9-S9 -> 0.017361111 | W9: 0.03125 | X9: 0.35972222 | Y9: 0.3875 | Z9: =Y9-X9 -> 0.027777778 | AA9: 0 | AB9: 0.38888889
A10: 8 | B10: 876 | C10: =VLOOKUP(B10,'[1]22-1-2026'!$B$3:$D$38,2,FALSE) -> دبابة | D10: =VLOOKUP(B10,'[1]22-1-2026'!$B$3:$D$38,3,FALSE) -> 0.020833333 | E10: بافاريا | F10: مجدي صبحي | G10: 0.29166667 | H10: 0.28819444 | I10: 0 | J10: 0.27430556 | K10: 0.29513889 | N10: =K10-J10 -> 0.020833333 | O10: =N10-D10 -> 0 | P10: 0.0069444444 | Q10: 0.29513889 | R10: 0 | S10: 0.29513889 | T10: 0.010416667 | U10: 0.31944444 | V10: =U10-T10-S10 -> 0.013888889 | W10: 0.03125 | X10: 0.35416667 | Y10: 0.37847222 | Z10: =Y10-X10 -> 0.024305556 | AA10: 0 | AB10: 0.38194444
A11: 9 | B11: 529 | C11: =VLOOKUP(B11,'[1]22-1-2026'!$B$3:$D$38,2,FALSE) -> دبابة | D11: =VLOOKUP(B11,'[1]22-1-2026'!$B$3:$D$38,3,FALSE) -> 0.020833333 | E11: مسرة | F11: محمد احمد | G11: 0.29166667 | H11: 0.29166667 | I11: =H11-G11 -> 0 | J11: 0.32638889 | K11: 0.33333333 | N11: =K11-J11 -> 0.0069444444 | O11: 0 | P11: 0.0069444444 | Q11: 0.33333333 | R11: 0 | S11: 0.33333333 | T11: =VLOOKUP(E11,'[1]22-1-2026'!$E$3:$T$13,16,FALSE) -> 0.013888889 | U11: 0.34375 | V11: 0 | W11: 0.03125 | X11: 0.35069444 | Y11: 0.38194444 | Z11: =Y11-X11 -> 0.03125 | AA11: =Z11-W11 -> 0 | AB11: 0.38541667
A12: 10 | B12: 492 | C12: =VLOOKUP(B12,'[1]22-1-2026'!$B$3:$D$38,2,FALSE) -> دبابة | D12: =VLOOKUP(B12,'[1]22-1-2026'!$B$3:$D$38,3,FALSE) -> 0.020833333 | E12: العباسية | F12: محمد ابراهيم | G12: 0.29166667 | H12: 0.29166667 | I12: =H12-G12 -> 0 | J12: 0.31944444 | K12: 0.32638889 | N12: =K12-J12 -> 0.0069444444 | O12: 0 | P12: 0.0069444444 | Q12: 0.32638889 | R12: 0 | S12: 0.32638889 | T12: =VLOOKUP(E12,'[1]22-1-2026'!$E$3:$T$13,16,FALSE) -> 0.013888889 | U12: 0 | V12: 0 | W12: 0.03125 | X12: 0 | Y12: 0 | Z12: =Y12-X12 -> 0 | AA12: 0 | AB12: 0
A13: 11 | B13: 315 | C13: =VLOOKUP(B13,'[1]22-1-2026'!$B$3:$D$38,2,FALSE) -> دبابة | D13: =VLOOKUP(B13,'[1]22-1-2026'!$B$3:$D$38,3,FALSE) -> 0.020833333 | E13: اللبيني | F13: محمد صديق | G13: 0.29166667 | H13: 0.28819444 | I13: 0 | J13: 0.27430556 | K13: 0.28472222 | N13: =K13-J13 -> 0.010416667 | O13: 0 | P13: 0.0069444444 | Q13: 0.28472222 | R13: 0 | S13: 0.28472222 | T13: =VLOOKUP(E13,'[1]22-1-2026'!$E$3:$T$13,16,FALSE) -> 0.041666667 | U13: 0.33263889 | V13: =U13-T13-S13 -> 0.00625 | W13: 0.020833333 | X13: 0.33472222 | Y13: 0.35763889 | Z13: =Y13-X13 -> 0.022916667 | AA13: =Z13-W13 -> 0.0020833333 | AB13: 0.36111111
A14: 12 | B14: 315 | C14: =VLOOKUP(B14,'[1]22-1-2026'!$B$3:$D$38,2,FALSE) -> دبابة | D14: =VLOOKUP(B14,'[1]22-1-2026'!$B$3:$D$38,3,FALSE) -> 0.020833333 | E14: ترسا | F14: محمد صديق | G14: 0.29166667 | H14: 0.28819444 | I14: 0 | J14: 0.27430556 | K14: 0.28472222 | N14: =K14-J14 -> 0.010416667 | O14: 0 | P14: 0.0069444444 | Q14: 0.28472222 | R14: 0 | S14: 0.28472222 | T14: =VLOOKUP(E14,'[1]22-1-2026'!$E$3:$T$13,16,FALSE) -> 0.0069444444 | U14: 0.36458333 | V14: 0 | W14: 0.03125 | X14: 0.36666667 | Y14: 0.39861111 | Z14: =Y14-X14 -> 0.031944444 | AA14: =Z14-W14 -> 0.00069444444 | AB14: 0.40277778
A15: 13 | B15: 249 | C15: =VLOOKUP(B15,'[1]22-1-2026'!$B$3:$D$38,2,FALSE) -> دبابة | D15: =VLOOKUP(B15,'[1]22-1-2026'!$B$3:$D$38,3,FALSE) -> 0.020833333 | E15: بورسعيد | F15: حسن علي | G15: 0.29166667 | H15: 0.29166667 | I15: =H15-G15 -> 0 | J15: 0.32986111 | K15: 0.36805556 | N15: =K15-J15 -> 0.038194444 | O15: =N15-D15 -> 0.017361111 | P15: 0.0069444444 | Q15: 0.37152778 | R15: 0 | S15: 0.37152778 | T15: =VLOOKUP(E15,'[1]22-1-2026'!$E$3:$T$13,16,FALSE) -> 0.0034722222 | U15: 0.375 | V15: =U15-T15-S15 -> 0 | W15: 0.03125 | X15: 0.37569444 | Y15: 0.41319444 | Z15: =Y15-X15 -> 0.0375 | AA15: =Z15-W15 -> 0.00625 | AB15: 0.41666667
A16: 14 | B16: 492 | C16: =VLOOKUP(B16,'[1]22-1-2026'!$B$3:$D$38,2,FALSE) -> دبابة | D16: =VLOOKUP(B16,'[1]22-1-2026'!$B$3:$D$38,3,FALSE) -> 0.020833333 | E16: اول جمال | F16: محمد ابراهيم | G16: 0.29166667 | H16: =VLOOKUP(F16,$F$3:$H$12,3,FALSE) -> 0.29166667 | I16: =H16-G16 -> 0 | J16: 0.40277778 | K16: 0.4375 | N16: =K16-J16 -> 0.034722222 | O16: =N16-D16 -> 0.013888889 | P16: 0.0069444444 | Q16: 0.4375 | R16: 0 | S16: 0.4375 | T16: =VLOOKUP(E16,'[1]18-2-2026'!$E$16:$W$27,16,FALSE) -> 0.024305556 | U16: 0.47916667 | V16: =U16-T16-S16 -> 0.017361111 | W16: 0.020833333 | X16: 0.48263889 | Y16: 0.51388889 | Z16: =Y16-X16 -> 0.03125 | AA16: =Z16-W16 -> 0.010416667 | AB16: 0.51736111 | AD16: رحلة ثانية ( شرقى وغربى ومخبوزات )
A17: 15 | B17: 492 | C17: =VLOOKUP(B17,'[1]22-1-2026'!$B$3:$D$38,2,FALSE) -> دبابة | D17: =VLOOKUP(B17,'[1]22-1-2026'!$B$3:$D$38,3,FALSE) -> 0.020833333 | E17: العبور | F17: محمد ابراهيم | G17: 0.29166667 | H17: =VLOOKUP(F17,$F$3:$H$12,3,FALSE) -> 0.29166667 | I17: =H17-G17 -> 0 | J17: 0.40277778 | K17: 0.4375 | N17: =K17-J17 -> 0.034722222 | O17: =N17-D17 -> 0.013888889 | P17: 0.0069444444 | Q17: 0.4375 | R17: 0 | S17: 0.4375 | T17: 0.010416667 | U17: 0.52777778 | V17: 0 | W17: 0.03125 | X17: 0.53263889 | Y17: 0.57152778 | Z17: =Y17-X17 -> 0.038888889 | AA17: =Z17-W17 -> 0.0076388889 | AB17: 0.57291667
A18: 16 | B18: 529 | C18: =VLOOKUP(B18,'[1]22-1-2026'!$B$3:$D$38,2,FALSE) -> دبابة | D18: =VLOOKUP(B18,'[1]22-1-2026'!$B$3:$D$38,3,FALSE) -> 0.020833333 | E18: الشروق | F18: محمد احمد | G18: 0.29166667 | H18: =VLOOKUP(F18,$F$3:$H$12,3,FALSE) -> 0.29166667 | I18: =H18-G18 -> 0 | J18: 0.40277778 | K18: 0.4375 | N18: =K18-J18 -> 0.034722222 | O18: =N18-D18 -> 0.013888889 | P18: 0.0069444444 | Q18: 0.4375 | R18: 0 | S18: 0.4375 | T18: =VLOOKUP(E18,'[1]18-2-2026'!$E$16:$W$27,16,FALSE) -> 0.034722222 | U18: 0.46875 | V18: 0 | W18: 0.020833333 | X18: 0.47569444 | Y18: 0.51041667 | Z18: =Y18-X18 -> 0.034722222 | AA18: =Z18-W18 -> 0.013888889 | AB18: 0.51388889
A19: 17 | B19: 529 | C19: =VLOOKUP(B19,'[1]22-1-2026'!$B$3:$D$38,2,FALSE) -> دبابة | D19: =VLOOKUP(B19,'[1]22-1-2026'!$B$3:$D$38,3,FALSE) -> 0.020833333 | E19: بدر | F19: محمد احمد | G19: 0.29166667 | H19: =VLOOKUP(F19,$F$3:$H$12,3,FALSE) -> 0.29166667 | I19: =H19-G19 -> 0 | J19: 0.40277778 | K19: 0.4375 | N19: =K19-J19 -> 0.034722222 | O19: =N19-D19 -> 0.013888889 | P19: 0.0069444444 | Q19: 0.4375 | R19: 0 | S19: 0.4375 | T19: =VLOOKUP(E19,'[1]18-2-2026'!$E$16:$W$27,16,FALSE) -> 0.020833333 | U19: 0.53472222 | V19: 0 | W19: 0.03125 | X19: 0.54166667 | Y19: 0.84722222 | Z19: =Y19-X19 -> 0.30555556 | AA19: =Z19-W19 -> 0.27430556 | AB19: 0.85069444
A20: 18 | B20: 762 | C20: =VLOOKUP(B20,'[1]22-1-2026'!$B$3:$D$38,2,FALSE) -> دبابة | D20: =VLOOKUP(B20,'[1]22-1-2026'!$B$3:$D$38,3,FALSE) -> 0.020833333 | E20: بافاريا | F20: ممدوح عبد العال | G20: 0.29166667 | H20: =VLOOKUP(F20,$F$3:$H$12,3,FALSE) -> 0.28472222 | I20: 0 | J20: 0.4375 | K20: 0.47569444 | N20: =K20-J20 -> 0.038194444 | O20: =N20-D20 -> 0.017361111 | P20: 0.0069444444 | Q20: 0.45833333 | R20: 0 | S20: 0.45833333 | T20: 0.017361111 | U20: 0 | V20: 0 | W20: 0.03125 | X20: 0 | Y20: 0 | Z20: =Y20-X20 -> 0 | AA20: 0 | AB20: 0
A21: 19 | B21: 249 | C21: =VLOOKUP(B21,'[1]22-1-2026'!$B$3:$D$38,2,FALSE) -> دبابة | D21: =VLOOKUP(B21,'[1]22-1-2026'!$B$3:$D$38,3,FALSE) -> 0.020833333 | E21: العباسية | F21: حسن علي | G21: 0.29166667 | H21: 0.29166667 | I21: =H21-G21 -> 0 | J21: 0.4375 | K21: 0.47569444 | N21: =K21-J21 -> 0.038194444 | O21: =N21-D21 -> 0.017361111 | P21: 0.0069444444 | Q21: 0.48263889 | R21: 0 | S21: 0.48263889 | T21: =VLOOKUP(E21,'[1]18-2-2026'!$E$16:$W$27,16,FALSE) -> 0.013888889 | U21: 0.49375 | V21: 0 | W21: 0.020833333 | X21: 0.49583333 | Y21: 0.52708333 | Z21: =Y21-X21 -> 0.03125 | AA21: =Z21-W21 -> 0.010416667 | AB21: 0.53125
A22: 20 | B22: 249 | C22: =VLOOKUP(B22,'[1]22-1-2026'!$B$3:$D$38,2,FALSE) -> دبابة | D22: =VLOOKUP(B22,'[1]22-1-2026'!$B$3:$D$38,3,FALSE) -> 0.020833333 | E22: مسرة | F22: حسن علي | G22: 0.29166667 | H22: 0.29166667 | I22: =H22-G22 -> 0 | J22: 0.4375 | K22: 0.48263889 | N22: =K22-J22 -> 0.045138889 | O22: =N22-D22 -> 0.024305556 | P22: 0.0069444444 | Q22: 0.48263889 | R22: 0 | S22: 0.48263889 | T22: =VLOOKUP(E22,'[1]18-2-2026'!$E$16:$W$27,16,FALSE) -> 0.013888889 | U22: 0.54305556 | V22: 0 | W22: 0.03125 | X22: 0.54652778 | Y22: 0.57083333 | Z22: =Y22-X22 -> 0.024305556 | AA22: 0 | AB22: 0.57291667
A23: 21 | B23: 315 | C23: =VLOOKUP(B23,'[1]22-1-2026'!$B$3:$D$38,2,FALSE) -> دبابة | D23: =VLOOKUP(B23,'[1]22-1-2026'!$B$3:$D$38,3,FALSE) -> 0.020833333 | E23: السلام | F23: محمد صديق | G23: 0.29166667 | H23: 0.29166667 | I23: =H23-G23 -> 0 | J23: 0.46875 | K23: 0.50694444 | N23: =K23-J23 -> 0.038194444 | O23: =N23-D23 -> 0.017361111 | P23: 0.0069444444 | Q23: 0.48263889 | R23: 0 | S23: 0.48263889 | T23: =VLOOKUP(E23,'[1]18-2-2026'!$E$16:$W$27,16,FALSE) -> 0.027777778 | U23: 0.51597222 | V23: =U23-T23-S23 -> 0.0055555556 | W23: 0.03125 | X23: 0.52083333 | Y23: 0.54513889 | Z23: =Y23-X23 -> 0.024305556 | AA23: 0 | AB23: 0.54652778
A24: 22 | B24: 876 | C24: =VLOOKUP(B24,'[1]22-1-2026'!$B$3:$D$38,2,FALSE) -> دبابة | D24: =VLOOKUP(B24,'[1]22-1-2026'!$B$3:$D$38,3,FALSE) -> 0.020833333 | E24: اللبيني | F24: مجدي صبحي | G24: 0.29166667 | H24: =VLOOKUP(F24,$F$3:$H$12,3,FALSE) -> 0.28819444 | I24: 0 | J24: 0.47569444 | K24: 0.50694444 | N24: =K24-J24 -> 0.03125 | O24: =N24-D24 -> 0.010416667 | P24: 0.0069444444 | Q24: 0.51388889 | R24: 0 | S24: 0.51388889 | T24: =VLOOKUP(E24,'[1]18-2-2026'!$E$16:$W$27,16,FALSE) -> 0.041666667 | U24: 0.53819444 | V24: 0 | W24: 0.020833333 | X24: 0.54166667 | Y24: 0.56944444 | Z24: =Y24-X24 -> 0.027777778 | AA24: =Z24-W24 -> 0.0069444444 | AB24: 0.57291667
A25: 23 | B25: 876 | C25: =VLOOKUP(B25,'[1]22-1-2026'!$B$3:$D$38,2,FALSE) -> دبابة | D25: =VLOOKUP(B25,'[1]22-1-2026'!$B$3:$D$38,3,FALSE) -> 0.020833333 | E25: ترسا | F25: مجدي صبحي | G25: 0.29166667 | H25: =VLOOKUP(F25,$F$3:$H$12,3,FALSE) -> 0.28819444 | I25: 0 | J25: 0.47569444 | K25: 0.50694444 | N25: =K25-J25 -> 0.03125 | O25: =N25-D25 -> 0.010416667 | P25: 0.0069444444 | Q25: 0.51388889 | R25: 0 | S25: 0.51388889 | T25: 0.010416667 | U25: 0.58333333 | V25: 0 | W25: 0.03125 | X25: 0.58680556 | Y25: 0.60694444 | Z25: =Y25-X25 -> 0.020138889 | AA25: 0 | AB25: 0.60972222
A26: 24 | B26: 2694 | C26: تلتين | D26: 0.03125 | E26: الشارع | F26: مصطفي عادل | G26: 0.29166667 | H26: =VLOOKUP(F26,$F$3:$H$12,3,FALSE) -> 0.29166667 | I26: =H26-G26 -> 0 | J26: 0.48611111 | K26: 0.54166667 | N26: =K26-J26 -> 0.055555556 | O26: =N26-D26 -> 0.024305556 | P26: 0.0069444444 | Q26: 0.54166667 | R26: 0 | S26: 0.54166667 | T26: =VLOOKUP(E26,'[1]18-2-2026'!$E$16:$W$27,16,FALSE) -> 0.013888889 | U26: 0.54861111 | V26: 0 | W26: 0.03125 | X26: 0.55069444 | Y26: 0.58125 | Z26: =Y26-X26 -> 0.030555556 | AA26: 0 | AB26: 0.58333333
A27: 25 | B27: 2694 | C27: تلتين | D27: 0.03125 | E27: التعاون | F27: مصطفي عادل | G27: 0.29166667 | H27: =VLOOKUP(F27,$F$3:$H$12,3,FALSE) -> 0.29166667 | I27: =H27-G27 -> 0 | J27: 0.48611111 | K27: 0.54166667 | N27: =K27-J27 -> 0.055555556 | O27: =N27-D27 -> 0.024305556 | P27: 0.0069444444 | Q27: 0.54166667 | R27: 0 | S27: 0.54166667 | T27: =VLOOKUP(E27,'[1]18-2-2026'!$E$16:$W$27,16,FALSE) -> 0.013888889 | U27: 0.59722222 | V27: 0 | W27: 0.041666667 | X27: 0.60069444 | Y27: 0.64444444 | Z27: =Y27-X27 -> 0.04375 | AA27: =Z27-W27 -> 0.0020833333 | AB27: 0.64583333
A28: 26 | B28: 892 | C28: =VLOOKUP(B28,'[1]22-1-2026'!$B$3:$D$38,2,FALSE) -> تلتين | D28: =VLOOKUP(B28,'[1]22-1-2026'!$B$3:$D$38,3,FALSE) -> 0.03125 | E28: بورسعيد | F28: ابراهيم محمود | G28: 0.29166667 | H28: =VLOOKUP(F28,$F$3:$H$12,3,FALSE) -> 0.29166667 | I28: =H28-G28 -> 0 | J28: 0.51041667 | K28: 0.54166667 | N28: =K28-J28 -> 0.03125 | O28: =N28-D28 -> 0 | P28: 0.0069444444 | Q28: 0.54166667 | R28: 0 | S28: 0.54166667 | T28: =VLOOKUP(E28,'[1]18-2-2026'!$E$16:$W$27,16,FALSE) -> 0.0034722222 | U28: 0.49652778 | V28: 0 | W28: 0.041666667 | X28: 0.49722222 | Y28: 0.52291667 | Z28: =Y28-X28 -> 0.025694444 | AA28: 0 | AB28: 0.52361111
A29: 27 | B29: 892 | C29: =VLOOKUP(B29,'[1]22-1-2026'!$B$3:$D$38,2,FALSE) -> تلتين | D29: =VLOOKUP(B29,'[1]22-1-2026'!$B$3:$D$38,3,FALSE) -> 0.03125 | E29: اول جمال | F29: ابراهيم محمود | G29: 0.29166667 | H29: =VLOOKUP(F29,$F$3:$H$12,3,FALSE) -> 0.29166667 | I29: =H29-G29 -> 0 | J29: 0.56944444 | K29: 0.62847222 | N29: =K29-J29 -> 0.059027778 | O29: =N29-D29 -> 0.027777778 | P29: 0.0069444444 | Q29: 0.64236111 | R29: =Q29-P29-K29 -> 0.0069444444 | S29: 0.64236111 | T29: =VLOOKUP(E29,'[1]22-1-2026'!$E$27:$T$38,16,FALSE) -> 0.024305556 | U29: 0.58680556 | V29: 0 | W29: 0.03125 | X29: 0.59027778 | Y29: 0.60416667 | Z29: =Y29-X29 -> 0.013888889 | AA29: 0 | AB29: 0.60555556 | AD29: رحلة ثالثة ( شرقى وغربى ومخبوزات )
A30: 28 | B30: 892 | C30: =VLOOKUP(B30,'[1]22-1-2026'!$B$3:$D$38,2,FALSE) -> تلتين | D30: =VLOOKUP(B30,'[1]22-1-2026'!$B$3:$D$38,3,FALSE) -> 0.03125 | E30: السلام | F30: ابراهيم محمود | G30: 0.29166667 | H30: =VLOOKUP(F30,$F$3:$H$12,3,FALSE) -> 0.29166667 | I30: =H30-G30 -> 0 | J30: 0.56944444 | K30: 0.62847222 | N30: =K30-J30 -> 0.059027778 | O30: =N30-D30 -> 0.027777778 | P30: 0.0069444444 | Q30: 0.64236111 | R30: =Q30-P30-K30 -> 0.0069444444 | S30: 0.64236111 | T30: =VLOOKUP(E30,'[1]22-1-2026'!$E$27:$T$38,16,FALSE) -> 0.013888889 | U30: 0.61458333 | V30: 0 | W30: 0.041666667 | X30: 0.61597222 | Y30: 0.65833333 | Z30: =Y30-X30 -> 0.042361111 | AA30: =Z30-W30 -> 0.00069444444 | AB30: 0.65972222
A31: 29 | B31: 249 | C31: =VLOOKUP(B31,'[1]22-1-2026'!$B$3:$D$38,2,FALSE) -> دبابة | D31: =VLOOKUP(B31,'[1]22-1-2026'!$B$3:$D$38,3,FALSE) -> 0.020833333 | E31: العباسية | F31: حسن علي | G31: 0.29166667 | H31: 0.29166667 | I31: =H31-G31 -> 0 | J31: 0.59027778 | K31: 0.625 | N31: =K31-J31 -> 0.034722222 | O31: =N31-D31 -> 0.013888889 | P31: 0.0069444444 | Q31: 0.63888889 | R31: =Q31-P31-K31 -> 0.0069444444 | S31: 0.63888889 | T31: =VLOOKUP(E31,'[1]22-1-2026'!$E$27:$T$38,16,FALSE) -> 0.013888889 | U31: 0.65625 | V31: =U31-T31-S31 -> 0.0034722222 | W31: 0.020833333 | X31: 0.6625 | Y31: 0.69791667 | Z31: =Y31-X31 -> 0.035416667 | AA31: =Z31-W31 -> 0.014583333 | AB31: 0.7
A32: 30 | B32: 249 | C32: =VLOOKUP(B32,'[1]22-1-2026'!$B$3:$D$38,2,FALSE) -> دبابة | D32: =VLOOKUP(B32,'[1]22-1-2026'!$B$3:$D$38,3,FALSE) -> 0.020833333 | E32: مسرة | F32: حسن علي | G32: 0.29166667 | H32: 0.29166667 | I32: =H32-G32 -> 0 | J32: 0.59027778 | K32: 0.625 | N32: =K32-J32 -> 0.034722222 | O32: =N32-D32 -> 0.013888889 | P32: 0.0069444444 | Q32: 0.63888889 | R32: =Q32-P32-K32 -> 0.0069444444 | S32: 0.63888889 | T32: =VLOOKUP(E32,'[1]22-1-2026'!$E$27:$T$38,16,FALSE) -> 0.010416667 | U32: 0.72916667 | V32: 0.01875 | W32: 0.03125 | X32: 0.73263889 | Y32: 0.75833333 | Z32: =Y32-X32 -> 0.025694444 | AA32: 0 | AB32: 0.76597222
A33: 31 | B33: 539 | C33: =VLOOKUP(B33,'[1]22-1-2026'!$B$3:$D$38,2,FALSE) -> دبابة | D33: =VLOOKUP(B33,'[1]22-1-2026'!$B$3:$D$38,3,FALSE) -> 0.020833333 | E33: اللبيني | F33: احمد اشرف | G33: 0.29166667 | H33: =VLOOKUP(F33,$F$3:$H$12,3,FALSE) -> 0.29166667 | I33: =H33-G33 -> 0 | J33: 0.625 | K33: 0.64583333 | N33: =K33-J33 -> 0.020833333 | O33: =N33-D33 -> 3.8163916e-17 | P33: 0.0069444444 | Q33: 0.64583333 | R33: 0 | S33: 0.64583333 | T33: 0.038194444 | U33: 0.67708333 | V33: 0 | W33: 0.020833333 | X33: 0.68055556 | Y33: 0.69097222 | Z33: =Y33-X33 -> 0.010416667 | AA33: 0 | AB33: 0.69444444
A34: 32 | B34: 539 | C34: =VLOOKUP(B34,'[1]22-1-2026'!$B$3:$D$38,2,FALSE) -> دبابة | D34: =VLOOKUP(B34,'[1]22-1-2026'!$B$3:$D$38,3,FALSE) -> 0.020833333 | E34: ترسا | F34: احمد اشرف | G34: 0.29166667 | H34: =VLOOKUP(F34,$F$3:$H$12,3,FALSE) -> 0.29166667 | I34: =H34-G34 -> 0 | J34: 0.625 | K34: 0.64583333 | N34: =K34-J34 -> 0.020833333 | O34: =N34-D34 -> 3.8163916e-17 | P34: 0.0069444444 | Q34: 0.64583333 | R34: 0 | S34: 0.64583333 | T34: 0.010416667 | U34: 0.70138889 | V34: 0 | W34: 0.03125 | X34: 0.70347222 | Y34: 0.70486111 | Z34: =Y34-X34 -> 0.0013888889 | AA34: 0 | AB34: 0.70833333
A35: 33 | B35: 492 | C35: =VLOOKUP(B35,'[1]22-1-2026'!$B$3:$D$38,2,FALSE) -> دبابة | D35: =VLOOKUP(B35,'[1]22-1-2026'!$B$3:$D$38,3,FALSE) -> 0.020833333 | E35: الشروق | F35: محمد ابراهيم | G35: 0.29166667 | H35: =VLOOKUP(F35,$F$3:$H$12,3,FALSE) -> 0.29166667 | I35: =H35-G35 -> 0 | J35: 0.63888889 | K35: 0.65972222 | N35: =K35-J35 -> 0.020833333 | O35: =N35-D35 -> 3.8163916e-17 | P35: 0.0069444444 | Q35: 0.65972222 | R35: 0 | S35: 0.65972222 | T35: 0.038194444 | U35: 0.70833333 | V35: =U35-T35-S35 -> 0.010416667 | W35: 0.020833333 | X35: 0.71180556 | Y35: 0.72083333 | Z35: =Y35-X35 -> 0.0090277778 | AA35: 0 | AB35: 0.72222222
A36: 34 | B36: 492 | C36: =VLOOKUP(B36,'[1]22-1-2026'!$B$3:$D$38,2,FALSE) -> دبابة | D36: =VLOOKUP(B36,'[1]22-1-2026'!$B$3:$D$38,3,FALSE) -> 0.020833333 | E36: بدر | F36: محمد ابراهيم | G36: 0.29166667 | H36: =VLOOKUP(F36,$F$3:$H$12,3,FALSE) -> 0.29166667 | I36: =H36-G36 -> 0 | J36: 0.63888889 | K36: 0.65972222 | N36: =K36-J36 -> 0.020833333 | O36: =N36-D36 -> 3.8163916e-17 | P36: 0.0069444444 | Q36: 0.65972222 | R36: 0 | S36: 0.65972222 | T36: =VLOOKUP(E36,'[1]22-1-2026'!$E$27:$T$38,16,FALSE) -> 0.052083333 | U36: 0.73263889 | V36: 0 | W36: 0.03125 | X36: 0.74305556 | Y36: 0.86597222 | Z36: =Y36-X36 -> 0.12291667 | AA36: =Z36-W36 -> 0.091666667 | AB36: 0.875
A37: 35 | B37: 762 | C37: =VLOOKUP(B37,'[1]22-1-2026'!$B$3:$D$38,2,FALSE) -> دبابة | D37: =VLOOKUP(B37,'[1]22-1-2026'!$B$3:$D$38,3,FALSE) -> 0.020833333 | E37: بافاريا | F37: ممدوح عبد العال | G37: 0.29166667 | H37: =VLOOKUP(F37,$F$3:$H$12,3,FALSE) -> 0.28472222 | I37: 0 | J37: 0.64583333 | K37: 0.65277778 | N37: =K37-J37 -> 0.0069444444 | O37: 0 | P37: 0.0069444444 | Q37: 0.65277778 | R37: 0 | S37: 0.65277778 | T37: =VLOOKUP(E37,'[1]22-1-2026'!$E$27:$T$38,16,FALSE) -> 0.017361111 | U37: 0 | V37: 0 | W37: 0.03125 | X37: 0 | Y37: 0 | Z37: =Y37-X37 -> 0 | AA37: 0 | AB37: 0
A38: 36 | B38: 876 | C38: =VLOOKUP(B38,'[1]22-1-2026'!$B$3:$D$38,2,FALSE) -> دبابة | D38: =VLOOKUP(B38,'[1]22-1-2026'!$B$3:$D$38,3,FALSE) -> 0.020833333 | E38: العبور | F38: مجدي صبحي | G38: 0.29166667 | H38: =VLOOKUP(F38,$F$3:$H$12,3,FALSE) -> 0.28819444 | I38: 0 | J38: 0.65625 | K38: 0.67013889 | N38: =K38-J38 -> 0.013888889 | O38: 0 | P38: 0.0069444444 | Q38: 0.67708333 | R38: 0 | S38: 0.67708333 | T38: =VLOOKUP(E38,'[1]22-1-2026'!$E$27:$T$38,16,FALSE) -> 0.013888889 | U38: 0.71875 | V38: =U38-T38-S38 -> 0.027777778 | W38: 0.03125 | X38: 0.72083333 | Y38: 0.73819444 | Z38: =Y38-X38 -> 0.017361111 | AA38: 0 | AB38: 0.73958333
A39: 37 | B39: 2694 | C39: تلتين | D39: 0.03125 | E39: التعاون | F39: مصطفي عادل | G39: 0.29166667 | H39: =VLOOKUP(F39,$F$3:$H$12,3,FALSE) -> 0.29166667 | I39: =H39-G39 -> 0 | J39: 0.65972222 | K39: 0.67708333 | N39: =K39-J39 -> 0.017361111 | O39: 0 | P39: 0.0069444444 | Q39: 0.67708333 | R39: 0 | S39: 0.67708333 | T39: =VLOOKUP(E39,'[1]22-1-2026'!$E$27:$T$38,16,FALSE) -> 0.010416667 | U39: 0.6875 | V39: =U39-T39-S39 -> 0 | W39: 0.03125 | X39: 0.69097222 | Y39: 0.69583333 | Z39: =Y39-X39 -> 0.0048611111 | AA39: 0 | AB39: 0.69791667
A40: 38 | B40: 2694 | C40: تلتين | D40: 0.03125 | E40: الشارع | F40: مصطفي عادل | G40: 0.29166667 | H40: =VLOOKUP(F40,$F$3:$H$12,3,FALSE) -> 0.29166667 | I40: =H40-G40 -> 0 | J40: 0.65972222 | K40: 0.67708333 | N40: =K40-J40 -> 0.017361111 | O40: 0 | P40: 0.0069444444 | Q40: 0.67708333 | R40: 0 | S40: 0.67708333 | T40: =VLOOKUP(E40,'[1]22-1-2026'!$E$27:$T$38,16,FALSE) -> 0.013888889 | U40: 0.71180556 | V40: 0 | W40: 0.041666667 | X40: 0.71458333 | Y40: 0.72916667 | Z40: =Y40-X40 -> 0.014583333 | AA40: 0 | AB40: 0.73611111
...

Sheet 21-4-2026
A1: شيت دخول وخروج السيارات أبو محرم
A2: م | B2: رقم السيارة | C2: نوع السيارة | D2: الزمن المعيارى للتحميل | E2: اسم الفرع | F2: اسم السائق | G2: وقت الحضور المقرر | H2: الحضور فعلى | I2: مدة التأخير | J2: دخول الكيدج | K2: نزول من الكيدج | L2: أخصائى الدفترى | M2: أخصائى السيستم | N2: مدة التحميل | O2: مدة انحراف التحميل | P2: الزمن المعيارى لنزول الاذن | Q2: وقت نزول الاذن | R2: مدة انحراف نزول الاذن | S2: خروج من المصنع | T2: الزمن المعيارى لدخول الفرع | U2: دخول الفرع | V2: مدة انحراف دخول الفرع | W2: الزمن المعيارى لنزول المنتجات | X2: فتح السياره | Y2: غلق السياره | Z2: الوقت المستغرق | AA2: مدة انحراف نزول المنتجات فى الفرع | AB2: خروج من الفرع | AC2: ملاحظات
A3: 1 | B3: 539 | C3: =VLOOKUP(B3,داتا!$B$3:$D$42,2,FALSE) -> دبابة | D3: =VLOOKUP(B3,داتا!$B$3:$D$42,3,FALSE) -> 0.020833333 | E3: الشروق | F3: احمد اشرف | G3: 0.25 | H3: 0.26388889 | I3: =H3-G3 -> 0.013888889 | J3: 0.22916667 | K3: 0.23958333 | L3: كريم سمير | M3: اسلام حمدان | N3: =K3-J3 -> 0.010416667 | O3: 0 | P3: 0.0069444444 | Q3: 0.26736111 | R3: =Q3-P3-K3 -> 0.020833333 | S3: 0.26736111 | T3: =VLOOKUP(E3,'[1]22-1-2026'!$E$3:$T$13,16,FALSE) -> 0.034722222 | U3: 0.30902778 | V3: =U3-T3-S3 -> 0.0069444444 | W3: 0.020833333 | X3: 0.33472222 | Y3: 0.35833333 | Z3: =Y3-X3 -> 0.023611111 | AA3: =Z3-W3 -> 0.0027777778 | AB3: 0.36111111 | AD3: رحلة اولى ( شرقى ومخبوزات وغربى )
A4: 2 | B4: 539 | C4: =VLOOKUP(B4,داتا!$B$3:$D$42,2,FALSE) -> دبابة | D4: =VLOOKUP(B4,داتا!$B$3:$D$42,3,FALSE) -> 0.020833333 | E4: بدر | F4: احمد اشرف | G4: 0.25 | H4: 0.26388889 | I4: =H4-G4 -> 0.013888889 | J4: 0.22916667 | K4: 0.23958333 | L4: كريم سمير | M4: اسلام حمدان | N4: =K4-J4 -> 0.010416667 | O4: 0 | P4: 0.0069444444 | Q4: 0.26736111 | R4: =Q4-P4-K4 -> 0.020833333 | S4: 0.26736111 | T4: 0.020833333 | U4: 0.375 | V4: 0 | W4: 0.03125 | X4: 0.41666667 | Y4: 0.4375 | Z4: =Y4-X4 -> 0.020833333 | AA4: 0 | AB4: 0.44097222
A5: 3 | B5: 892 | C5: =VLOOKUP(B5,داتا!$B$3:$D$42,2,FALSE) -> تلتين | D5: =VLOOKUP(B5,داتا!$B$3:$D$42,3,FALSE) -> 0.03125 | E5: اول جمال | F5: احمد جمعة | G5: 0.25 | H5: 0.26388889 | I5: =H5-G5 -> 0.013888889 | J5: 0.22916667 | K5: 0.23958333 | L5: كريم سمير | M5: اسلام حمدان | N5: =K5-J5 -> 0.010416667 | O5: 0 | P5: 0.0069444444 | Q5: 0.26736111 | R5: =Q5-P5-K5 -> 0.020833333 | S5: 0.26736111 | T5: =VLOOKUP(E5,'[1]22-1-2026'!$E$3:$T$13,16,FALSE) -> 0.024305556 | U5: 0.29166667 | V5: =U5-T5-S5 -> 0 | W5: 0.03125 | X5: 0.30555556 | Y5: 0.34513889 | Z5: =Y5-X5 -> 0.039583333 | AA5: =Z5-W5 -> 0.0083333333 | AB5: 0.35208333
A6: 4 | B6: 892 | C6: =VLOOKUP(B6,داتا!$B$3:$D$42,2,FALSE) -> تلتين | D6: =VLOOKUP(B6,داتا!$B$3:$D$42,3,FALSE) -> 0.03125 | E6: السلام | F6: احمد جمعة | G6: 0.25 | H6: 0.26388889 | I6: =H6-G6 -> 0.013888889 | J6: 0.22916667 | K6: 0.23958333 | L6: كريم سمير | M6: اسلام حمدان | N6: =K6-J6 -> 0.010416667 | O6: 0 | P6: 0.0069444444 | Q6: 0.26736111 | R6: =Q6-P6-K6 -> 0.020833333 | S6: 0.26736111 | T6: =VLOOKUP(E6,'[1]22-1-2026'!$E$3:$T$13,16,FALSE) -> 0.027777778 | U6: 0.3625 | V6: 0 | W6: 0.041666667 | X6: 0.36805556 | Y6: 0.38958333 | Z6: =Y6-X6 -> 0.021527778 | AA6: 0 | AB6: 0.39583333
A7: 5 | B7: 876 | C7: =VLOOKUP(B7,داتا!$B$3:$D$42,2,FALSE) -> دبابة | D7: =VLOOKUP(B7,داتا!$B$3:$D$42,3,FALSE) -> 0.020833333 | E7: اللبيني | F7: احمد السعيد | G7: 0.25 | H7: 0.25 | I7: =H7-G7 -> 0 | J7: 0.25 | K7: 0.25694444 | L7: كريم سمير | M7: اسلام حمدان | N7: =K7-J7 -> 0.0069444444 | O7: 0 | P7: 0.0069444444 | Q7: 0.26388889 | R7: =Q7-P7-K7 -> 0 | S7: 0.26388889 | T7: =VLOOKUP(E7,'[1]22-1-2026'!$E$3:$T$13,16,FALSE) -> 0.041666667 | U7: 0.28819444 | V7: 0 | W7: 0.020833333 | X7: 0.33194444 | Y7: 0.35277778 | Z7: =Y7-X7 -> 0.020833333 | AA7: =Z7-W7 -> 3.8163916e-17 | AB7: 0.35833333
A8: 6 | B8: 876 | C8: =VLOOKUP(B8,داتا!$B$3:$D$42,2,FALSE) -> دبابة | D8: =VLOOKUP(B8,داتا!$B$3:$D$42,3,FALSE) -> 0.020833333 | E8: ترسا | F8: احمد السعيد | G8: 0.25 | H8: 0.25 | I8: =H8-G8 -> 0 | J8: 0.25 | K8: 0.25694444 | L8: كريم سمير | M8: اسلام حمدان | N8: =K8-J8 -> 0.0069444444 | O8: 0 | P8: 0.0069444444 | Q8: 0.26388889 | R8: =Q8-P8-K8 -> 0 | S8: 0.26388889 | T8: =VLOOKUP(E8,'[1]22-1-2026'!$E$3:$T$13,16,FALSE) -> 0.0069444444 | U8: 0.36458333 | V8: 0 | W8: 0.03125 | X8: 0.37152778 | Y8: 0.38888889 | Z8: =Y8-X8 -> 0.017361111 | AA8: 0 | AB8: 0.39444444
A9: 7 | B9: 7435 | C9: =VLOOKUP(B9,داتا!$B$3:$D$42,2,FALSE) -> تلتين | D9: =VLOOKUP(B9,داتا!$B$3:$D$42,3,FALSE) -> 0.03125 | E9: الشارع | F9: مصطفى عادل | G9: 0.25 | H9: 0.25347222 | I9: =H9-G9 -> 0.0034722222 | J9: 0.24305556 | K9: 0.25694444 | L9: كريم سمير | M9: اسلام حمدان | N9: =K9-J9 -> 0.013888889 | O9: 0 | P9: 0.0069444444 | Q9: 0.26736111 | R9: =Q9-P9-K9 -> 0.0034722222 | S9: 0.26736111 | T9: =VLOOKUP(E9,'[1]22-1-2026'!$E$3:$T$13,16,FALSE) -> 0.013888889 | U9: 0.28472222 | V9: =U9-T9-S9 -> 0.0034722222 | W9: 0.03125 | X9: 0.33333333 | Y9: 0.35763889 | Z9: =Y9-X9 -> 0.024305556 | AA9: 0 | AB9: 0.36111111
A10: 8 | B10: 7435 | C10: =VLOOKUP(B10,داتا!$B$3:$D$42,2,FALSE) -> تلتين | D10: =VLOOKUP(B10,داتا!$B$3:$D$42,3,FALSE) -> 0.03125 | E10: التعاون | F10: مصطفى عادل | G10: 0.25 | H10: 0.25347222 | I10: =H10-G10 -> 0.0034722222 | J10: 0.24305556 | K10: 0.25694444 | L10: كريم سمير | M10: اسلام حمدان | N10: =K10-J10 -> 0.013888889 | O10: 0 | P10: 0.0069444444 | Q10: 0.26736111 | R10: =Q10-P10-K10 -> 0.0034722222 | S10: 0.26736111 | T10: =VLOOKUP(E10,'[1]22-1-2026'!$E$3:$T$13,16,FALSE) -> 0.013888889 | U10: 0.375 | V10: 0 | W10: 0.041666667 | X10: 0.37708333 | Y10: 0.39930556 | Z10: =Y10-X10 -> 0.022222222 | AA10: 0 | AB10: 0.40277778
A11: 9 | B11: 762 | C11: =VLOOKUP(B11,داتا!$B$3:$D$42,2,FALSE) -> دبابة | D11: =VLOOKUP(B11,داتا!$B$3:$D$42,3,FALSE) -> 0.020833333 | E11: العبور | F11: ممدوح عبدالعال | G11: 0.25 | H11: 0.20833333 | I11: 0 | J11: 0.25694444 | K11: 0.26388889 | L11: كريم سمير | M11: اسلام حمدان | N11: =K11-J11 -> 0.0069444444 | O11: 0 | P11: 0.0069444444 | Q11: 0.26388889 | R11: 0 | S11: 0.26388889 | T11: =VLOOKUP(E11,'[1]22-1-2026'!$E$3:$T$13,16,FALSE) -> 0.017361111 | U11: 0.29513889 | V11: =U11-T11-S11 -> 0.013888889 | W11: 0.03125 | X11: 0.34027778 | Y11: 0.36111111 | Z11: =Y11-X11 -> 0.020833333 | AA11: 0 | AB11: 0.36458333
A12: 10 | B12: 529 | C12: =VLOOKUP(B12,داتا!$B$3:$D$42,2,FALSE) -> دبابة | D12: =VLOOKUP(B12,داتا!$B$3:$D$42,3,FALSE) -> 0.020833333 | E12: العباسية | F12: اسلام سلطان | G12: 0.25 | H12: 0.25 | I12: =H12-G12 -> 0 | J12: 0.25694444 | K12: 0.26041667 | L12: كريم سمير | M12: اسلام حمدان | N12: =K12-J12 -> 0.0034722222 | O12: 0 | P12: 0.0069444444 | Q12: 0.26388889 | R12: 0 | S12: 0.26388889 | T12: =VLOOKUP(E12,'[1]22-1-2026'!$E$3:$T$13,16,FALSE) -> 0.013888889 | U12: 0.27430556 | V12: 0 | W12: 0.03125 | X12: 0.31944444 | Y12: 0.34513889 | Z12: =Y12-X12 -> 0.025694444 | AA12: 0 | AB12: 0.35069444
A13: 11 | B13: 249 | C13: =VLOOKUP(B13,داتا!$B$3:$D$42,2,FALSE) -> دبابة | D13: =VLOOKUP(B13,داتا!$B$3:$D$42,3,FALSE) -> 0.020833333 | E13: مسرة | F13: حسن علي | G13: 0.25 | H13: 0.25 | I13: =H13-G13 -> 0 | J13: 0.26388889 | K13: 0.27083333 | L13: كريم سمير | M13: اسلام حمدان | N13: =K13-J13 -> 0.0069444444 | O13: 0 | P13: 0.0069444444 | Q13: 0.27083333 | R13: 0 | S13: 0.27083333 | T13: =VLOOKUP(E13,'[1]22-1-2026'!$E$3:$T$13,16,FALSE) -> 0.013888889 | U13: 0.28472222 | V13: =U13-T13-S13 -> 0 | W13: 0.03125 | X13: 0.30555556 | Y13: 0.34027778 | Z13: =Y13-X13 -> 0.034722222 | AA13: =Z13-W13 -> 0.0034722222 | AB13: 0.34375
A14: 12 | B14: 529 | C14: تويوتا | D14: =VLOOKUP(B14,داتا!$B$3:$D$42,3,FALSE) -> 0.020833333 | E14: النزهة | F14: مجدي صبحي | G14: 0.25 | H14: 0.24652778 | I14: 0 | J14: 0.26388889 | K14: 0.28472222 | L14: كريم سمير | M14: اسلام حمدان | N14: =K14-J14 -> 0.020833333 | O14: 0 | P14: 0.0069444444 | Q14: 0.28472222 | R14: 0 | S14: 0.28472222 | T14: 0.013888889 | U14: 0.30555556 | V14: =U14-T14-S14 -> 0.0069444444 | W14: 0.03125 | X14: 0.34722222 | Y14: 0.37152778 | Z14: =Y14-X14 -> 0.024305556 | AA14: 0 | AB14: 0.375
A15: 13 | B15: 492 | C15: =VLOOKUP(B15,داتا!$B$3:$D$42,2,FALSE) -> دبابة | D15: =VLOOKUP(B15,داتا!$B$3:$D$42,3,FALSE) -> 0.020833333 | E15: بورسعيد | F15: محمد احمد | G15: 0.25 | H15: 0.27777778 | I15: =H15-G15 -> 0.027777778 | J15: 0.27430556 | K15: 0.28472222 | L15: كريم سمير | M15: اسلام حمدان | N15: =K15-J15 -> 0.010416667 | O15: 0 | P15: 0.0069444444 | Q15: 0.29513889 | R15: =Q15-P15-K15 -> 0.0034722222 | S15: 0.29513889 | T15: =VLOOKUP(E15,'[1]22-1-2026'!$E$3:$T$13,16,FALSE) -> 0.0034722222 | U15: 0.29166667 | V15: 0 | W15: 0.03125 | X15: 0.34375 | Y15: 0.36111111 | Z15: =Y15-X15 -> 0.017361111 | AA15: 0 | AB15: 0.3625
A16: 1 | B16: 492 | C16: =VLOOKUP(B16,داتا!$B$3:$D$42,2,FALSE) -> دبابة | D16: =VLOOKUP(B16,داتا!$B$3:$D$42,3,FALSE) -> 0.020833333 | E16: الشروق | F16: محمد احمد | G16: 0.25 | H16: 0.25 | I16: =H16-G16 -> 0 | J16: 0.41666667 | K16: 0.45138889 | L16: عمرو محمد | M16: خالد عبدالسلام | N16: =K16-J16 -> 0.034722222 | O16: =N16-D16 -> 0.013888889 | P16: 0.0069444444 | Q16: 0.45138889 | R16: 0 | S16: 0.45138889 | T16: =VLOOKUP(E16,'[1]22-1-2026'!$E$3:$T$13,16,FALSE) -> 0.034722222 | U16: 0.49305556 | V16: =U16-T16-S16 -> 0.0069444444 | W16: 0.020833333 | X16: 0.49444444 | Y16: 0.50833333 | Z16: =Y16-X16 -> 0.013888889 | AA16: 0 | AB16: 0.51041667 | AD16: رحلة ثانية ( شرقى وغربى ومخبوزات )
A17: 2 | B17: 492 | C17: =VLOOKUP(B17,داتا!$B$3:$D$42,2,FALSE) -> دبابة | D17: =VLOOKUP(B17,داتا!$B$3:$D$42,3,FALSE) -> 0.020833333 | E17: بدر | F17: محمد احمد | G17: 0.25 | H17: 0.25 | I17: =H17-G17 -> 0 | J17: 0.41666667 | K17: 0.45138889 | L17: عمرو محمد | M17: خالد عبدالسلام | N17: =K17-J17 -> 0.034722222 | O17: =N17-D17 -> 0.013888889 | P17: 0.0069444444 | Q17: 0.45138889 | R17: 0 | S17: 0.45138889 | T17: 0.020833333 | U17: 0.52430556 | V17: 0 | W17: 0.03125 | X17: 0.52777778 | Y17: 0.55 | Z17: =Y17-X17 -> 0.022222222 | AA17: 0 | AB17: 0.55208333
A18: 3 | B18: 249 | C18: =VLOOKUP(B18,داتا!$B$3:$D$42,2,FALSE) -> دبابة | D18: =VLOOKUP(B18,داتا!$B$3:$D$42,3,FALSE) -> 0.020833333 | E18: اللبيني | F18: حسن علي | G18: 0.25 | H18: 0.24305556 | I18: 0 | J18: 0.41666667 | K18: 0.45138889 | L18: عبدالمنعم | M18: محمد هشام | N18: =K18-J18 -> 0.034722222 | O18: =N18-D18 -> 0.013888889 | P18: 0.0069444444 | Q18: 0.45486111 | R18: 0 | S18: 0.45486111 | T18: =VLOOKUP(E18,'[1]22-1-2026'!$E$3:$T$13,16,FALSE) -> 0.041666667 | U18: 0.49444444 | V18: 0 | W18: 0.020833333 | X18: 0.49583333 | Y18: 0.50347222 | Z18: =Y18-X18 -> 0.0076388889 | AA18: 0 | AB18: 0.50694444
A19: 4 | B19: 249 | C19: =VLOOKUP(B19,داتا!$B$3:$D$42,2,FALSE) -> دبابة | D19: =VLOOKUP(B19,داتا!$B$3:$D$42,3,FALSE) -> 0.020833333 | E19: ترسا | F19: حسن علي | G19: 0.25 | H19: 0.24305556 | I19: 0 | J19: 0.41666667 | K19: 0.45138889 | L19: عبدالمنعم | M19: محمد هشام | N19: =K19-J19 -> 0.034722222 | O19: =N19-D19 -> 0.013888889 | P19: 0.0069444444 | Q19: 0.45486111 | R19: 0 | S19: 0.45486111 | T19: =VLOOKUP(E19,'[1]22-1-2026'!$E$3:$T$13,16,FALSE) -> 0.0069444444 | U19: 0.51388889 | V19: 0 | W19: 0.03125 | X19: 0.51736111 | Y19: 0.53333333 | Z19: =Y19-X19 -> 0.015972222 | AA19: 0 | AB19: 0.53819444
A20: 5 | B20: 876 | C20: =VLOOKUP(B20,داتا!$B$3:$D$42,2,FALSE) -> دبابة | D20: =VLOOKUP(B20,داتا!$B$3:$D$42,3,FALSE) -> 0.020833333 | E20: العباسية | F20: احمد السعيد | G20: 0.25 | H20: =VLOOKUP(F20,$F$3:$H$12,3,FALSE) -> 0.25 | I20: =H20-G20 -> 0 | J20: 0.45138889 | K20: 0.47222222 | L20: عبدالمنعم | M20: محمد هشام | N20: =K20-J20 -> 0.020833333 | O20: =N20-D20 -> 3.8163916e-17 | P20: 0.0069444444 | Q20: 0.47569444 | R20: 0 | S20: 0.47569444 | T20: =VLOOKUP(E20,'[1]22-1-2026'!$E$3:$T$13,16,FALSE) -> 0.013888889 | U20: 0.49513889 | V20: =U20-T20-S20 -> 0.0055555556 | W20: 0.020833333 | X20: 0.49583333 | Y20: 0.51041667 | Z20: =Y20-X20 -> 0.014583333 | AA20: 0 | AB20: 0.51111111
A21: 6 | B21: 876 | C21: =VLOOKUP(B21,داتا!$B$3:$D$42,2,FALSE) -> دبابة | D21: =VLOOKUP(B21,داتا!$B$3:$D$42,3,FALSE) -> 0.020833333 | E21: مسرة | F21: احمد السعيد | G21: 0.25 | H21: =VLOOKUP(F21,$F$3:$H$12,3,FALSE) -> 0.25 | I21: =H21-G21 -> 0 | J21: 0.45138889 | K21: 0.47222222 | L21: عبدالمنعم | M21: محمد هشام | N21: =K21-J21 -> 0.020833333 | O21: =N21-D21 -> 3.8163916e-17 | P21: 0.0069444444 | Q21: 0.47569444 | R21: 0 | S21: 0.47569444 | T21: =VLOOKUP(E21,'[1]22-1-2026'!$E$3:$T$13,16,FALSE) -> 0.013888889 | U21: 0.52777778 | V21: 0 | W21: 0.03125 | X21: 0.53125 | Y21: 0.54791667 | Z21: =Y21-X21 -> 0.016666667 | AA21: 0 | AB21: 0.54861111
A22: 7 | B22: 7435 | C22: =VLOOKUP(B22,داتا!$B$3:$D$42,2,FALSE) -> تلتين | D22: =VLOOKUP(B22,داتا!$B$3:$D$42,3,FALSE) -> 0.03125 | E22: السلام | F22: مصطفى عادل | G22: 0.25 | H22: =VLOOKUP(F22,$F$3:$H$12,3,FALSE) -> 0.25347222 | I22: =H22-G22 -> 0.0034722222 | J22: 0.45486111 | K22: 0.47569444 | L22: عمرو محمد | M22: خالد عبدالسلام | N22: =K22-J22 -> 0.020833333 | O22: 0 | P22: 0.0069444444 | Q22: 0.47916667 | R22: 0 | S22: 0.47916667 | T22: =VLOOKUP(E22,'[1]22-1-2026'!$E$3:$T$13,16,FALSE) -> 0.027777778 | U22: 0.50347222 | V22: 0 | W22: 0.03125 | X22: 0.50694444 | Y22: 0.52291667 | Z22: =Y22-X22 -> 0.015972222 | AA22: 0 | AB22: 0.52430556
A23: 8 | B23: 7435 | C23: =VLOOKUP(B23,داتا!$B$3:$D$42,2,FALSE) -> تلتين | D23: =VLOOKUP(B23,داتا!$B$3:$D$42,3,FALSE) -> 0.03125 | E23: العبور | F23: مصطفى عادل | G23: 0.25 | H23: =VLOOKUP(F23,$F$3:$H$12,3,FALSE) -> 0.25347222 | I23: =H23-G23 -> 0.0034722222 | J23: 0.45486111 | K23: 0.47569444 | L23: عمرو محمد | M23: خالد عبدالسلام | N23: =K23-J23 -> 0.020833333 | O23: 0 | P23: 0.0069444444 | Q23: 0.47916667 | R23: 0 | S23: 0.47916667 | T23: =VLOOKUP(E23,'[1]22-1-2026'!$E$3:$T$13,16,FALSE) -> 0.017361111 | U23: 0.57986111 | V23: 0 | W23: 0.041666667 | X23: 0.58333333 | Y23: 0.59027778 | Z23: =Y23-X23 -> 0.0069444444 | AA23: 0 | AB23: 0.59375
A24: 9 | B24: 529 | C24: =VLOOKUP(B24,داتا!$B$3:$D$42,2,FALSE) -> دبابة | D24: =VLOOKUP(B24,داتا!$B$3:$D$42,3,FALSE) -> 0.020833333 | E24: اول جمال | F24: اسلام سلطان | G24: 0.25 | H24: =VLOOKUP(F24,$F$3:$H$12,3,FALSE) -> 0.25 | I24: =H24-G24 -> 0 | J24: 0.47222222 | K24: 0.48611111 | L24: عبدالمنعم | M24: محمد هشام | N24: =K24-J24 -> 0.013888889 | O24: 0 | P24: 0.0069444444 | Q24: 0.49305556 | R24: =Q24-P24-K24 -> 0 | S24: 0.49305556 | T24: =VLOOKUP(E24,'[1]22-1-2026'!$E$3:$T$13,16,FALSE) -> 0.024305556 | U24: 0.51041667 | V24: 0 | W24: 0.020833333 | X24: 0.51388889 | Y24: 0.53472222 | Z24: =Y24-X24 -> 0.020833333 | AA24: 0 | AB24: 0.53819444
A25: 10 | B25: 529 | C25: =VLOOKUP(B25,داتا!$B$3:$D$42,2,FALSE) -> دبابة | D25: =VLOOKUP(B25,داتا!$B$3:$D$42,3,FALSE) -> 0.020833333 | E25: النزهة | F25: اسلام سلطان | G25: 0.25 | H25: =VLOOKUP(F25,$F$3:$H$12,3,FALSE) -> 0.25 | I25: =H25-G25 -> 0 | J25: 0.47222222 | K25: 0.48611111 | L25: عبدالمنعم | M25: محمد هشام | N25: =K25-J25 -> 0.013888889 | O25: 0 | P25: 0.0069444444 | Q25: 0.49305556 | R25: =Q25-P25-K25 -> 0 | S25: 0.49305556 | T25: 0.010416667 | U25: 0.55555556 | V25: 0 | W25: 0.03125 | X25: 0.55902778 | Y25: 0.56944444 | Z25: =Y25-X25 -> 0.010416667 | AA25: 0 | AB25: 0.56944444
A26: 11 | B26: 892 | C26: =VLOOKUP(B26,داتا!$B$3:$D$42,2,FALSE) -> تلتين | D26: =VLOOKUP(B26,داتا!$B$3:$D$42,3,FALSE) -> 0.03125 | E26: التعاون | F26: احمد جمعة | G26: 0.25 | H26: =VLOOKUP(F26,$F$3:$H$12,3,FALSE) -> 0.26388889 | I26: =H26-G26 -> 0.013888889 | J26: 0.47916667 | K26: 0.49652778 | L26: عمرو محمد | M26: خالد عبدالسلام | N26: =K26-J26 -> 0.017361111 | O26: 0 | P26: 0.0069444444 | Q26: 0.5 | R26: 0 | S26: 0.5 | T26: =VLOOKUP(E26,'[1]22-1-2026'!$E$3:$T$13,16,FALSE) -> 0.013888889 | U26: 0.51041667 | V26: 0 | W26: 0.03125 | X26: 0.51388889 | Y26: 0.54166667 | Z26: =Y26-X26 -> 0.027777778 | AA26: 0 | AB26: 0.54791667
A27: 12 | B27: 892 | C27: =VLOOKUP(B27,داتا!$B$3:$D$42,2,FALSE) -> تلتين | D27: =VLOOKUP(B27,داتا!$B$3:$D$42,3,FALSE) -> 0.03125 | E27: الشارع | F27: احمد جمعة | G27: 0.25 | H27: =VLOOKUP(F27,$F$3:$H$12,3,FALSE) -> 0.26388889 | I27: =H27-G27 -> 0.013888889 | J27: 0.47916667 | K27: 0.49652778 | L27: عمرو محمد | M27: خالد عبدالسلام | N27: =K27-J27 -> 0.017361111 | O27: 0 | P27: 0.0069444444 | Q27: 0.5 | R27: 0 | S27: 0.5 | T27: =VLOOKUP(E27,'[1]22-1-2026'!$E$3:$T$13,16,FALSE) -> 0.013888889 | U27: 0.56041667 | V27: 0 | W27: 0.041666667 | X27: 0.5625 | Y27: 0.57638889 | Z27: =Y27-X27 -> 0.013888889 | AA27: 0 | AB27: 0.57986111
A28: 13 | B28: 539 | C28: =VLOOKUP(B28,داتا!$B$3:$D$42,2,FALSE) -> دبابة | D28: =VLOOKUP(B28,داتا!$B$3:$D$42,3,FALSE) -> 0.020833333 | E28: بورسعيد | F28: احمد اشرف | G28: 0.25 | H28: =VLOOKUP(F28,$F$3:$H$12,3,FALSE) -> 0.26388889 | I28: =H28-G28 -> 0.013888889 | J28: 0.48263889 | K28: 0.49305556 | L28: عبدالمنعم | M28: محمد هشام | N28: =K28-J28 -> 0.010416667 | O28: 0 | P28: 0.0069444444 | Q28: 0.5 | R28: =Q28-P28-K28 -> 0 | S28: 0.5 | T28: =VLOOKUP(E28,'[1]22-1-2026'!$E$3:$T$13,16,FALSE) -> 0.0034722222 | U28: 0.5 | V28: 0 | W28: 0.03125 | X28: 0.50138889 | Y28: 0.51944444 | Z28: =Y28-X28 -> 0.018055556 | AA28: 0 | AB28: 0.52430556

Sheet 22-4-2026
A1: شيت دخول وخروج السيارات أبو محرم
A2: م | B2: رقم السيارة | C2: نوع السيارة | D2: الزمن المعيارى للتحميل | E2: اسم الفرع | F2: اسم السائق | G2: وقت الحضور المقرر | H2: الحضور فعلى | I2: مدة التأخير | J2: دخول الكيدج | K2: نزول من الكيدج | L2: أخصائى الدفترى | M2: أخصائى السيستم | N2: مدة التحميل | O2: مدة انحراف التحميل | P2: الزمن المعيارى لنزول الاذن | Q2: وقت نزول الاذن | R2: مدة انحراف نزول الاذن | S2: خروج من المصنع | T2: الزمن المعيارى لدخول الفرع | U2: دخول الفرع | V2: مدة انحراف دخول الفرع | W2: الزمن المعيارى لنزول المنتجات | X2: فتح السياره | Y2: غلق السياره | Z2: الوقت المستغرق | AA2: مدة انحراف نزول المنتجات فى الفرع | AB2: خروج من الفرع | AC2: ملاحظات
A3: 1 | B3: 762 | C3: =VLOOKUP(B3,داتا!$B$3:$D$42,2,FALSE) -> دبابة | D3: =VLOOKUP(B3,داتا!$B$3:$D$42,3,FALSE) -> 0.020833333 | E3: الشروق | F3: ممدوح عبدالعال | G3: 0.25 | H3: 0.18055556 | I3: 0 | J3: 0.22222222 | K3: 0.23958333 | L3: ايمن عبدالقادر | M3: اسلام حمدان | N3: =K3-J3 -> 0.017361111 | O3: 0 | P3: 0.0069444444 | Q3: 0.24652778 | R3: =Q3-P3-K3 -> 0 | S3: 0.24652778 | T3: =VLOOKUP(E3,'[1]22-1-2026'!$E$3:$T$13,16,FALSE) -> 0.034722222 | U3: 0.28194444 | V3: =U3-T3-S3 -> 0.00069444444 | W3: 0.020833333 | X3: 0.33055556 | Y3: 0.35763889 | Z3: =Y3-X3 -> 0.027083333 | AA3: =Z3-W3 -> 0.00625 | AB3: 0.35972222 | AD3: رحلة اولى ( شرقى ومخبوزات وغربى )
A4: 2 | B4: 762 | C4: =VLOOKUP(B4,داتا!$B$3:$D$42,2,FALSE) -> دبابة | D4: =VLOOKUP(B4,داتا!$B$3:$D$42,3,FALSE) -> 0.020833333 | E4: بدر | F4: ممدوح عبدالعال | G4: 0.25 | H4: 0.18055556 | I4: 0 | J4: 0.22222222 | K4: 0.23958333 | L4: ايمن عبدالقادر | M4: اسلام حمدان | N4: =K4-J4 -> 0.017361111 | O4: 0 | P4: 0.0069444444 | Q4: 0.24652778 | R4: =Q4-P4-K4 -> 0 | S4: 0.24652778 | T4: 0.013888889 | U4: 0.375 | V4: 0 | W4: 0.03125 | X4: 0.37847222 | Y4: 0.43472222 | Z4: =Y4-X4 -> 0.05625 | AA4: =Z4-W4 -> 0.025 | AB4: 0.4375
A5: 3 | B5: 7435 | C5: =VLOOKUP(B5,داتا!$B$3:$D$42,2,FALSE) -> تلتين | D5: =VLOOKUP(B5,داتا!$B$3:$D$42,3,FALSE) -> 0.03125 | E5: اول جمال | F5: مصطفى عادل | G5: 0.25 | H5: 0.25694444 | I5: =H5-G5 -> 0.0069444444 | J5: 0.22222222 | K5: 0.23958333 | L5: ايمن عبدالقادر | M5: اسلام حمدان | N5: =K5-J5 -> 0.017361111 | O5: 0 | P5: 0.0069444444 | Q5: 0.25 | R5: =Q5-P5-K5 -> 0.0034722222 | S5: 0.25 | T5: =VLOOKUP(E5,'[1]22-1-2026'!$E$3:$T$13,16,FALSE) -> 0.024305556 | U5: 0.28819444 | V5: =U5-T5-S5 -> 0.013888889 | W5: 0.03125 | X5: 0.31944444 | Y5: 0.35416667 | Z5: =Y5-X5 -> 0.034722222 | AA5: =Z5-W5 -> 0.0034722222 | AB5: 0.35763889
A6: 4 | B6: 7435 | C6: =VLOOKUP(B6,داتا!$B$3:$D$42,2,FALSE) -> تلتين | D6: =VLOOKUP(B6,داتا!$B$3:$D$42,3,FALSE) -> 0.03125 | E6: السلام | F6: مصطفى عادل | G6: 0.25 | H6: 0.25694444 | I6: =H6-G6 -> 0.0069444444 | J6: 0.22222222 | K6: 0.23958333 | L6: ايمن عبدالقادر | M6: اسلام حمدان | N6: =K6-J6 -> 0.017361111 | O6: 0 | P6: 0.0069444444 | Q6: 0.25 | R6: =Q6-P6-K6 -> 0.0034722222 | S6: 0.25 | T6: =VLOOKUP(E6,'[1]22-1-2026'!$E$3:$T$13,16,FALSE) -> 0.027777778 | U6: 0.36805556 | V6: 0 | W6: 0.041666667 | X6: 0.37152778 | Y6: 0.39583333 | Z6: =Y6-X6 -> 0.024305556 | AA6: 0 | AB6: 0.39930556
A7: 5 | B7: 876 | C7: =VLOOKUP(B7,داتا!$B$3:$D$42,2,FALSE) -> دبابة | D7: =VLOOKUP(B7,داتا!$B$3:$D$42,3,FALSE) -> 0.020833333 | E7: اللبيني | F7: احمد سعيد | G7: 0.25 | H7: 0.24305556 | I7: 0 | J7: 0.24652778 | K7: 0.25347222 | L7: ايمن عبدالقادر | M7: اسلام حمدان | N7: =K7-J7 -> 0.0069444444 | O7: 0 | P7: 0.0069444444 | Q7: 0.25694444 | R7: 0 | S7: 0.25694444 | T7: =VLOOKUP(E7,'[1]22-1-2026'!$E$3:$T$13,16,FALSE) -> 0.041666667 | U7: 0.27777778 | V7: 0 | W7: 0.020833333 | X7: 0.33472222 | Y7: 0.35625 | Z7: =Y7-X7 -> 0.021527778 | AA7: =Z7-W7 -> 0.00069444444 | AB7: 0.35763889
A8: 6 | B8: 876 | C8: =VLOOKUP(B8,داتا!$B$3:$D$42,2,FALSE) -> دبابة | D8: =VLOOKUP(B8,داتا!$B$3:$D$42,3,FALSE) -> 0.020833333 | E8: ترسا | F8: احمد سعيد | G8: 0.25 | H8: 0.24305556 | I8: 0 | J8: 0.24652778 | K8: 0.25347222 | L8: ايمن عبدالقادر | M8: اسلام حمدان | N8: =K8-J8 -> 0.0069444444 | O8: 0 | P8: 0.0069444444 | Q8: 0.25694444 | R8: 0 | S8: 0.25694444 | T8: =VLOOKUP(E8,'[1]22-1-2026'!$E$3:$T$13,16,FALSE) -> 0.0069444444 | U8: 0.36805556 | V8: 0 | W8: 0.03125 | X8: 0.37013889 | Y8: 0.38888889 | Z8: =Y8-X8 -> 0.01875 | AA8: 0 | AB8: 0.39236111
A9: 7 | B9: 539 | C9: =VLOOKUP(B9,داتا!$B$3:$D$42,2,FALSE) -> دبابة | D9: =VLOOKUP(B9,داتا!$B$3:$D$42,3,FALSE) -> 0.020833333 | E9: العبور | F9: احمد اشرف | G9: 0.25 | H9: 0.26388889 | I9: =H9-G9 -> 0.013888889 | J9: 0.25347222 | K9: 0.26041667 | L9: ايمن عبدالقادر | M9: اسلام حمدان | N9: =K9-J9 -> 0.0069444444 | O9: 0 | P9: 0.0069444444 | Q9: 0.26736111 | R9: =Q9-P9-K9 -> 0 | S9: 0.26736111 | T9: =VLOOKUP(E9,'[1]22-1-2026'!$E$3:$T$13,16,FALSE) -> 0.017361111 | U9: 0.30902778 | V9: =U9-T9-S9 -> 0.024305556 | W9: 0.03125 | X9: 0.34027778 | Y9: 0.37013889 | Z9: =Y9-X9 -> 0.029861111 | AA9: 0 | AB9: 0.37152778
A10: 8 | B10: 249 | C10: =VLOOKUP(B10,داتا!$B$3:$D$42,2,FALSE) -> دبابة | D10: =VLOOKUP(B10,داتا!$B$3:$D$42,3,FALSE) -> 0.020833333 | E10: العباسية | F10: محمد صديق | G10: 0.25 | H10: 0.25694444 | I10: =H10-G10 -> 0.0069444444 | J10: 0.24305556 | K10: 0.25 | L10: ايمن عبدالقادر | M10: اسلام حمدان | N10: =K10-J10 -> 0.0069444444 | O10: 0 | P10: 0.0069444444 | Q10: 0.25347222 | R10: 0 | S10: 0.25347222 | T10: =VLOOKUP(E10,'[1]22-1-2026'!$E$3:$T$13,16,FALSE) -> 0.013888889 | U10: 0.28472222 | V10: =U10-T10-S10 -> 0.017361111 | W10: 0.03125 | X10: 0.32638889 | Y10: 0.35208333 | Z10: =Y10-X10 -> 0.025694444 | AA10: 0 | AB10: 0.35416667
A11: 9 | B11: 492 | C11: =VLOOKUP(B11,داتا!$B$3:$D$42,2,FALSE) -> دبابة | D11: =VLOOKUP(B11,داتا!$B$3:$D$42,3,FALSE) -> 0.020833333 | E11: مسرة | F11: مجدي صبحي | G11: 0.25 | H11: 0.25 | I11: =H11-G11 -> 0 | J11: 0.26041667 | K11: 0.26736111 | L11: ايمن عبدالقادر | M11: اسلام حمدان | N11: =K11-J11 -> 0.0069444444 | O11: 0 | P11: 0.0069444444 | Q11: 0.27083333 | R11: 0 | S11: 0.27083333 | T11: =VLOOKUP(E11,'[1]22-1-2026'!$E$3:$T$13,16,FALSE) -> 0.013888889 | U11: 0.28472222 | V11: =U11-T11-S11 -> 0 | W11: 0.03125 | X11: 0.30347222 | Y11: 0.33333333 | Z11: =Y11-X11 -> 0.029861111 | AA11: 0 | AB11: 0.33541667
A12: 10 | B12: 529 | C12: =VLOOKUP(B12,داتا!$B$3:$D$42,2,FALSE) -> دبابة | D12: =VLOOKUP(B12,داتا!$B$3:$D$42,3,FALSE) -> 0.020833333 | E12: النزهة | F12: احمد صادق | G12: 0.25 | H12: 0.25347222 | I12: =H12-G12 -> 0.0034722222 | J12: 0.25347222 | K12: 0.27083333 | L12: ايمن عبدالقادر | M12: اسلام حمدان | N12: =K12-J12 -> 0.017361111 | O12: 0 | P12: 0.0069444444 | Q12: 0.27430556 | R12: 0 | S12: 0.27430556 | T12: 0.013888889 | U12: 0.30555556 | V12: =U12-T12-S12 -> 0.017361111 | W12: 0.03125 | X12: 0.34027778 | Y12: 0.375 | Z12: =Y12-X12 -> 0.034722222 | AA12: =Z12-W12 -> 0.0034722222 | AB12: 0.37847222
A13: 11 | B13: 892 | C13: =VLOOKUP(B13,داتا!$B$3:$D$42,2,FALSE) -> تلتين | D13: =VLOOKUP(B13,داتا!$B$3:$D$42,3,FALSE) -> 0.03125 | E13: الشارع | F13: احمد جمعة | G13: 0.25 | H13: 0.27083333 | I13: =H13-G13 -> 0.020833333 | J13: 0.27430556 | K13: 0.29166667 | L13: ايمن عبدالقادر | M13: اسلام حمدان | N13: =K13-J13 -> 0.017361111 | O13: 0 | P13: 0.0069444444 | Q13: 0.29166667 | R13: 0 | S13: 0.29166667 | T13: =VLOOKUP(E13,'[1]22-1-2026'!$E$3:$T$13,16,FALSE) -> 0.013888889 | U13: 0.29930556 | V13: 0 | W13: 0.03125 | X13: 0.33333333 | Y13: 0.36458333 | Z13: =Y13-X13 -> 0.03125 | AA13: =Z13-W13 -> 0 | AB13: 0.37152778
A14: 12 | B14: 892 | C14: =VLOOKUP(B14,داتا!$B$3:$D$42,2,FALSE) -> تلتين | D14: =VLOOKUP(B14,داتا!$B$3:$D$42,3,FALSE) -> 0.03125 | E14: التعاون | F14: احمد جمعة | G14: 0.25 | H14: 0.27083333 | I14: =H14-G14 -> 0.020833333 | J14: 0.27430556 | K14: 0.29166667 | L14: ايمن عبدالقادر | M14: اسلام حمدان | N14: =K14-J14 -> 0.017361111 | O14: 0 | P14: 0.0069444444 | Q14: 0.29166667 | R14: 0 | S14: 0.29166667 | T14: =VLOOKUP(E14,'[1]22-1-2026'!$E$3:$T$13,16,FALSE) -> 0.013888889 | U14: 0.38680556 | V14: 0 | W14: 0.041666667 | X14: 0.38888889 | Y14: 0.40972222 | Z14: =Y14-X14 -> 0.020833333 | AA14: 0 | AB14: 0.41180556
A15: 13 | B15: 529 | C15: =VLOOKUP(B15,داتا!$B$3:$D$42,2,FALSE) -> دبابة | D15: =VLOOKUP(B15,داتا!$B$3:$D$42,3,FALSE) -> 0.020833333 | E15: بورسعيد | F15: محمد احمد | G15: 0.29166667 | H15: 0.28819444 | I15: 0 | J15: 0.27083333 | K15: 0.27777778 | L15: ايمن عبدالقادر | M15: اسلام حمدان | N15: =K15-J15 -> 0.0069444444 | O15: 0 | P15: 0.0069444444 | Q15: 0.27777778 | R15: 0 | S15: 0.27777778 | T15: =VLOOKUP(E15,'[1]22-1-2026'!$E$3:$T$13,16,FALSE) -> 0.0034722222 | U15: 0.30208333 | V15: =U15-T15-S15 -> 0.020833333 | W15: 0.03125 | X15: 0.33680556 | Y15: 0.35763889 | Z15: =Y15-X15 -> 0.020833333 | AA15: 0 | AB15: 0.36111111
A16: 1 | B16: 529 | C16: =VLOOKUP(B16,داتا!$B$3:$D$42,2,FALSE) -> دبابة | D16: =VLOOKUP(B16,داتا!$B$3:$D$42,3,FALSE) -> 0.020833333 | E16: الشروق | F16: محمد احمد | G16: 0.29166667 | H16: 0.28819444 | I16: 0 | J16: 0.41319444 | K16: 0.44444444 | L16: عمرو محمد | M16: علي ممدوح | N16: =K16-J16 -> 0.03125 | O16: =N16-D16 -> 0.010416667 | P16: 0.0069444444 | Q16: 0.44791667 | R16: 0 | S16: 0.44791667 | T16: =VLOOKUP(E16,'[1]22-1-2026'!$E$3:$T$13,16,FALSE) -> 0.034722222 | U16: 0.49652778 | V16: =U16-T16-S16 -> 0.013888889 | W16: 0.020833333 | X16: 0.5 | Y16: 0.51388889 | Z16: =Y16-X16 -> 0.013888889 | AA16: 0 | AB16: 0.51736111 | AD16: رحلة ثانية ( شرقى وغربى ومخبوزات )
A17: 2 | B17: 529 | C17: =VLOOKUP(B17,داتا!$B$3:$D$42,2,FALSE) -> دبابة | D17: =VLOOKUP(B17,داتا!$B$3:$D$42,3,FALSE) -> 0.020833333 | E17: بدر | F17: محمد احمد | G17: 0.29166667 | H17: 0.28819444 | I17: 0 | J17: 0.41319444 | K17: 0.44444444 | L17: عمرو محمد | M17: علي ممدوح | N17: =K17-J17 -> 0.03125 | O17: =N17-D17 -> 0.010416667 | P17: 0.0069444444 | Q17: 0.44791667 | R17: 0 | S17: 0.44791667 | T17: 0.020833333 | U17: 0.53125 | V17: 0 | W17: 0.03125 | X17: 0.53472222 | Y17: 0.54652778 | Z17: =Y17-X17 -> 0.011805556 | AA17: 0 | AB17: 0.54861111
A18: 3 | B18: 492 | C18: =VLOOKUP(B18,داتا!$B$3:$D$42,2,FALSE) -> دبابة | D18: =VLOOKUP(B18,داتا!$B$3:$D$42,3,FALSE) -> 0.020833333 | E18: اللبيني | F18: مجدي صبحي | G18: 0.25 | H18: =VLOOKUP(F18,$F$3:$H$12,3,FALSE) -> 0.25 | I18: =H18-G18 -> 0 | J18: 0.41319444 | K18: 0.44444444 | L18: محمد هشام | M18: خالد عبدالسلام | N18: =K18-J18 -> 0.03125 | O18: =N18-D18 -> 0.010416667 | P18: 0.0069444444 | Q18: 0.44791667 | R18: 0 | S18: 0.44791667 | T18: =VLOOKUP(E18,'[1]22-1-2026'!$E$3:$T$13,16,FALSE) -> 0.041666667 | U18: 0.47916667 | V18: 0 | W18: 0.020833333 | X18: 0.48055556 | Y18: 0.48819444 | Z18: =Y18-X18 -> 0.0076388889 | AA18: 0 | AB18: 0.48958333
A19: 4 | B19: 492 | C19: =VLOOKUP(B19,داتا!$B$3:$D$42,2,FALSE) -> دبابة | D19: =VLOOKUP(B19,داتا!$B$3:$D$42,3,FALSE) -> 0.020833333 | E19: ترسا | F19: مجدي صبحي | G19: 0.25 | H19: =VLOOKUP(F19,$F$3:$H$12,3,FALSE) -> 0.25 | I19: =H19-G19 -> 0 | J19: 0.41319444 | K19: 0.44444444 | L19: محمد هشام | M19: خالد عبدالسلام | N19: =K19-J19 -> 0.03125 | O19: =N19-D19 -> 0.010416667 | P19: 0.0069444444 | Q19: 0.44791667 | R19: 0 | S19: 0.44791667 | T19: =VLOOKUP(E19,'[1]22-1-2026'!$E$3:$T$13,16,FALSE) -> 0.0069444444 | U19: 0.49305556 | V19: 0 | W19: 0.03125 | X19: 0.49861111 | Y19: 0.50347222 | Z19: =Y19-X19 -> 0.0048611111 | AA19: 0 | AB19: 0.50694444
A20: 5 | B20: 539 | C20: =VLOOKUP(B20,داتا!$B$3:$D$42,2,FALSE) -> دبابة | D20: =VLOOKUP(B20,داتا!$B$3:$D$42,3,FALSE) -> 0.020833333 | E20: اول جمال | F20: احمد اشرف | G20: 0.25 | H20: =VLOOKUP(F20,$F$3:$H$12,3,FALSE) -> 0.26388889 | I20: =H20-G20 -> 0.013888889 | J20: 0.44791667 | K20: 0.46875 | L20: محمد هشام | M20: خالد عبدالسلام | N20: =K20-J20 -> 0.020833333 | O20: =N20-D20 -> 0 | P20: 0.0069444444 | Q20: 0.47222222 | R20: 0 | S20: 0.47222222 | T20: =VLOOKUP(E20,'[1]22-1-2026'!$E$3:$T$13,16,FALSE) -> 0.024305556 | U20: 0.47569444 | V20: 0 | W20: 0.020833333 | X20: 0.49722222 | Y20: 0.50208333 | Z20: =Y20-X20 -> 0.0048611111 | AA20: 0 | AB20: 0.50347222
A21: 6 | B21: 539 | C21: =VLOOKUP(B21,داتا!$B$3:$D$42,2,FALSE) -> دبابة | D21: =VLOOKUP(B21,داتا!$B$3:$D$42,3,FALSE) -> 0.020833333 | E21: النزهة | F21: احمد اشرف | G21: 0.25 | H21: =VLOOKUP(F21,$F$3:$H$12,3,FALSE) -> 0.26388889 | I21: =H21-G21 -> 0.013888889 | J21: 0.44791667 | K21: 0.46875 | L21: محمد هشام | M21: خالد عبدالسلام | N21: =K21-J21 -> 0.020833333 | O21: =N21-D21 -> 0 | P21: 0.0069444444 | Q21: 0.47222222 | R21: 0 | S21: 0.47222222 | T21: 0.010416667 | U21: 0.51736111 | V21: 0 | W21: 0.03125 | X21: 0.52083333 | Y21: 0.54166667 | Z21: =Y21-X21 -> 0.020833333 | AA21: 0 | AB21: 0.54513889
A22: 7 | B22: 892 | C22: =VLOOKUP(B22,داتا!$B$3:$D$42,2,FALSE) -> تلتين | D22: =VLOOKUP(B22,داتا!$B$3:$D$42,3,FALSE) -> 0.03125 | E22: السلام | F22: احمد جمعة | G22: 0.25 | H22: 0.27083333 | I22: =H22-G22 -> 0.020833333 | J22: 0.44791667 | K22: 0.46875 | L22: عمرو محمد | M22: علي ممدوح | N22: =K22-J22 -> 0.020833333 | O22: 0 | P22: 0.0069444444 | Q22: 0.47222222 | R22: 0 | S22: 0.47222222 | T22: =VLOOKUP(E22,'[1]22-1-2026'!$E$3:$T$13,16,FALSE) -> 0.027777778 | U22: 0.50347222 | V22: =U22-T22-S22 -> 0.0034722222 | W22: 0.03125 | X22: 0.50694444 | Y22: 0.52430556 | Z22: =Y22-X22 -> 0.017361111 | AA22: 0 | AB22: 0.52777778
A23: 8 | B23: 892 | C23: =VLOOKUP(B23,داتا!$B$3:$D$42,2,FALSE) -> تلتين | D23: =VLOOKUP(B23,داتا!$B$3:$D$42,3,FALSE) -> 0.03125 | E23: العبور | F23: احمد جمعة | G23: 0.25 | H23: 0.27083333 | I23: =H23-G23 -> 0.020833333 | J23: 0.44791667 | K23: 0.46875 | L23: عمرو محمد | M23: علي ممدوح | N23: =K23-J23 -> 0.020833333 | O23: 0 | P23: 0.0069444444 | Q23: 0.47222222 | R23: 0 | S23: 0.47222222 | T23: =VLOOKUP(E23,'[1]22-1-2026'!$E$3:$T$13,16,FALSE) -> 0.017361111 | U23: 0.54861111 | V23: 0 | W23: 0.041666667 | X23: 0.55347222 | Y23: 0.57291667 | Z23: =Y23-X23 -> 0.019444444 | AA23: 0 | AB23: 0.57638889
A24: 9 | B24: 7435 | C24: =VLOOKUP(B24,داتا!$B$3:$D$42,2,FALSE) -> تلتين | D24: =VLOOKUP(B24,داتا!$B$3:$D$42,3,FALSE) -> 0.03125 | E24: الشارع | F24: مصطفى عادل | G24: 0.25 | H24: =VLOOKUP(F24,$F$3:$H$12,3,FALSE) -> 0.25694444 | I24: =H24-G24 -> 0.0069444444 | J24: 0.46875 | K24: 0.48958333 | L24: محمد هشام | M24: خالد عبدالسلام | N24: =K24-J24 -> 0.020833333 | O24: 0 | P24: 0.0069444444 | Q24: 0.48958333 | R24: 0 | S24: 0.48958333 | T24: =VLOOKUP(E24,'[1]22-1-2026'!$E$3:$T$13,16,FALSE) -> 0.013888889 | U24: 0.50347222 | V24: =U24-T24-S24 -> 0 | W24: 0.03125 | X24: 0.50694444 | Y24: 0.52083333 | Z24: =Y24-X24 -> 0.013888889 | AA24: 0 | AB24: 0.52430556
A25: 10 | B25: 7435 | C25: =VLOOKUP(B25,داتا!$B$3:$D$42,2,FALSE) -> تلتين | D25: =VLOOKUP(B25,داتا!$B$3:$D$42,3,FALSE) -> 0.03125 | E25: التعاون | F25: مصطفى عادل | G25: 0.25 | H25: =VLOOKUP(F25,$F$3:$H$12,3,FALSE) -> 0.25694444 | I25: =H25-G25 -> 0.0069444444 | J25: 0.46875 | K25: 0.48958333 | L25: محمد هشام | M25: خالد عبدالسلام | N25: =K25-J25 -> 0.020833333 | O25: 0 | P25: 0.0069444444 | Q25: 0.48958333 | R25: 0 | S25: 0.48958333 | T25: =VLOOKUP(E25,'[1]22-1-2026'!$E$3:$T$13,16,FALSE) -> 0.013888889 | U25: 0.53819444 | V25: 0 | W25: 0.041666667 | X25: 0.54027778 | Y25: 0.56458333 | Z25: =Y25-X25 -> 0.024305556 | AA25: 0 | AB25: 0.56597222
A26: 11 | B26: 249 | C26: =VLOOKUP(B26,داتا!$B$3:$D$42,2,FALSE) -> دبابة | D26: =VLOOKUP(B26,داتا!$B$3:$D$42,3,FALSE) -> 0.020833333 | E26: العباسية | F26: محمد صديق | G26: 0.25 | H26: =VLOOKUP(F26,$F$3:$H$12,3,FALSE) -> 0.25694444 | I26: =H26-G26 -> 0.0069444444 | J26: 0.46875 | K26: 0.48958333 | L26: عمرو محمد | M26: علي ممدوح | N26: =K26-J26 -> 0.020833333 | O26: =N26-D26 -> 0 | P26: 0.0069444444 | Q26: 0.48958333 | R26: 0 | S26: 0.48958333 | T26: =VLOOKUP(E26,'[1]22-1-2026'!$E$3:$T$13,16,FALSE) -> 0.013888889 | U26: 0.51527778 | V26: =U26-T26-S26 -> 0.011805556 | W26: 0.03125 | X26: 0.51597222 | Y26: 0.54027778 | Z26: =Y26-X26 -> 0.024305556 | AA26: 0 | AB26: 0.54236111
A27: 12 | B27: 876 | C27: =VLOOKUP(B27,داتا!$B$3:$D$42,2,FALSE) -> دبابة | D27: =VLOOKUP(B27,داتا!$B$3:$D$42,3,FALSE) -> 0.020833333 | E27: مسرة | F27: احمد سعيد | G27: 0.25 | H27: =VLOOKUP(F27,$F$3:$H$12,3,FALSE) -> 0.24305556 | I27: 0 | J27: 0.46875 | K27: 0.48958333 | L27: عمرو محمد | M27: علي ممدوح | N27: =K27-J27 -> 0.020833333 | O27: =N27-D27 -> 0 | P27: 0.0069444444 | Q27: 0.52777778 | R27: =Q27-P27-K27 -> 0.03125 | S27: 0.52777778 | T27: =VLOOKUP(E27,'[1]22-1-2026'!$E$3:$T$13,16,FALSE) -> 0.013888889 | U27: 0.54305556 | V27: =U27-T27-S27 -> 0.0013888889 | W27: 0.03125 | X27: 0.54513889 | Y27: 0.5625 | Z27: =Y27-X27 -> 0.017361111 | AA27: 0 | AB27: 0.56597222
A28: 13 | B28: 762 | C28: =VLOOKUP(B28,داتا!$B$3:$D$42,2,FALSE) -> دبابة | D28: =VLOOKUP(B28,داتا!$B$3:$D$42,3,FALSE) -> 0.020833333 | E28: بورسعيد | F28: ممدوح عبدالعال | G28: 0.25 | H28: =VLOOKUP(F28,$F$3:$H$12,3,FALSE) -> 0.18055556 | I28: 0 | J28: 0.48958333 | K28: 0.5 | L28: محمد هشام | M28: خالد عبدالسلام | N28: =K28-J28 -> 0.010416667 | O28: 0 | P28: 0.0069444444 | Q28: 0.50347222 | R28: 0 | S28: 0.50347222 | T28: =VLOOKUP(E28,'[1]22-1-2026'!$E$3:$T$13,16,FALSE) -> 0.0034722222 | U28: 0.50694444 | V28: =U28-T28-S28 -> 0 | W28: 0.03125 | X28: 0.50902778 | Y28: 0.52916667 | Z28: =Y28-X28 -> 0.020138889 | AA28: 0 | AB28: 0.53125

Sheet 23-4-2026
A1: شيت دخول وخروج السيارات أبو محرم
A2: م | B2: رقم السيارة | C2: نوع السيارة | D2: الزمن المعيارى للتحميل | E2: اسم الفرع | F2: اسم السائق | G2: وقت الحضور المقرر | H2: الحضور فعلى | I2: مدة التأخير | J2: دخول الكيدج | K2: نزول من الكيدج | L2: أخصائى الدفترى | M2: أخصائى السيستم | N2: مدة التحميل | O2: مدة انحراف التحميل | P2: الزمن المعيارى لنزول الاذن | Q2: وقت نزول الاذن | R2: مدة انحراف نزول الاذن | S2: خروج من المصنع | T2: الزمن المعيارى لدخول الفرع | U2: دخول الفرع | V2: مدة انحراف دخول الفرع | W2: الزمن المعيارى لنزول المنتجات | X2: فتح السياره | Y2: غلق السياره | Z2: الوقت المستغرق | AA2: مدة انحراف نزول المنتجات فى الفرع | AB2: خروج من الفرع | AC2: ملاحظات
A3: 1 | B3: 762 | C3: =VLOOKUP(B3,داتا!$B$3:$D$42,2,FALSE) -> دبابة | D3: =VLOOKUP(B3,داتا!$B$3:$D$42,3,FALSE) -> 0.020833333 | E3: الشروق | F3: مجدي صبحي | G3: 0.25 | H3: 0.25347222 | I3: =H3-G3 -> 0.0034722222 | J3: 0.25 | K3: 0.27083333 | L3: ايمن عبدالقادر | M3: اسلام حمدان | N3: =K3-J3 -> 0.020833333 | O3: =N3-D3 -> 0 | P3: 0.0069444444 | Q3: 0.30902778 | R3: =Q3-P3-K3 -> 0.03125 | S3: 0.30902778 | T3: =VLOOKUP(E3,'[1]22-1-2026'!$E$3:$T$13,16,FALSE) -> 0.034722222 | U3: 0.36041667 | V3: =U3-T3-S3 -> 0.016666667 | W3: 0.020833333 | X3: 0.36111111 | Y3: 0.38541667 | Z3: =Y3-X3 -> 0.024305556 | AA3: =Z3-W3 -> 0.0034722222 | AB3: 0.38888889 | AD3: رحلة اولى ( شرقى ومخبوزات وغربى )
A4: 2 | B4: 762 | C4: =VLOOKUP(B4,داتا!$B$3:$D$42,2,FALSE) -> دبابة | D4: =VLOOKUP(B4,داتا!$B$3:$D$42,3,FALSE) -> 0.020833333 | E4: بدر | F4: مجدي صبحي | G4: 0.25 | H4: 0.25347222 | I4: =H4-G4 -> 0.0034722222 | J4: 0.25 | K4: 0.27083333 | L4: ايمن عبدالقادر | M4: اسلام حمدان | N4: =K4-J4 -> 0.020833333 | O4: =N4-D4 -> 0 | P4: 0.0069444444 | Q4: 0.30902778 | R4: =Q4-P4-K4 -> 0.03125 | S4: 0.27430556 | T4: 0.020833333 | U4: 0.41111111 | V4: 0 | W4: 0.03125 | X4: 0.41319444 | Y4: 0.45833333 | Z4: =Y4-X4 -> 0.045138889 | AA4: =Z4-W4 -> 0.013888889 | AB4: 0.46180556
A5: 3 | B5: 892 | C5: =VLOOKUP(B5,داتا!$B$3:$D$42,2,FALSE) -> تلتين | D5: =VLOOKUP(B5,داتا!$B$3:$D$42,3,FALSE) -> 0.03125 | E5: اول جمال | F5: احمد جمعة | G5: 0.25 | H5: 0.26041667 | I5: =H5-G5 -> 0.010416667 | J5: 0.25 | K5: 0.27430556 | L5: ايمن عبدالقادر | M5: اسلام حمدان | N5: =K5-J5 -> 0.024305556 | O5: 0 | P5: 0.0069444444 | Q5: 0.27430556 | R5: 0 | S5: 0.27430556 | T5: =VLOOKUP(E5,'[1]22-1-2026'!$E$3:$T$13,16,FALSE) -> 0.024305556 | U5: 0.29861111 | V5: =U5-T5-S5 -> 0 | W5: 0.03125 | X5: 0.32291667 | Y5: 0.35416667 | Z5: =Y5-X5 -> 0.03125 | AA5: =Z5-W5 -> 0 | AB5: 0.35763889
